INFO:root:Document created successfully at Sun Feb  5 10:48:49 2023
INFO:root:Document created successfully at Sun Feb  5 10:48:49 2023
ERROR:django.request:Internal Server Error: /employees
Traceback (most recent call last):
  File "C:\django-mongo\django-mongo\venv\lib\site-packages\django\core\handlers\exception.py", line 47, in inner
    response = get_response(request)
  File "C:\django-mongo\django-mongo\venv\lib\site-packages\django\core\handlers\base.py", line 181, in _get_response
    response = wrapped_callback(request, *callback_args, **callback_kwargs)
  File "C:\django-mongo\django-mongo\venv\lib\site-packages\django\views\decorators\csrf.py", line 54, in wrapped_view
    return view_func(*args, **kwargs)
  File "C:\django-mongo\django-mongo\venv\lib\site-packages\django\views\generic\base.py", line 70, in view
    return self.dispatch(request, *args, **kwargs)
  File "C:\django-mongo\django-mongo\venv\lib\site-packages\rest_framework\views.py", line 509, in dispatch
    response = self.handle_exception(exc)
  File "C:\django-mongo\django-mongo\venv\lib\site-packages\rest_framework\views.py", line 469, in handle_exception
    self.raise_uncaught_exception(exc)
  File "C:\django-mongo\django-mongo\venv\lib\site-packages\rest_framework\views.py", line 480, in raise_uncaught_exception
    raise exc
  File "C:\django-mongo\django-mongo\venv\lib\site-packages\rest_framework\views.py", line 497, in dispatch
    self.initial(request, *args, **kwargs)
  File "C:\django-mongo\django-mongo\venv\lib\site-packages\rest_framework\views.py", line 414, in initial
    self.perform_authentication(request)
  File "C:\django-mongo\django-mongo\venv\lib\site-packages\rest_framework\views.py", line 324, in perform_authentication
    request.user
  File "C:\django-mongo\django-mongo\venv\lib\site-packages\rest_framework\request.py", line 227, in user
    self._authenticate()
  File "C:\django-mongo\django-mongo\venv\lib\site-packages\rest_framework\request.py", line 380, in _authenticate
    user_auth_tuple = authenticator.authenticate(self)
  File "C:\django-mongo\django-mongo\EmployeeApp\middleware.py", line 10, in authenticate
    if request.path("PATH_INFO") in EXCLUDED_URLS:
TypeError: 'str' object is not callable
INFO:django.utils.autoreload:C:\django-mongo\django-mongo\EmployeeApp\middleware.py changed, reloading.
INFO:root:Document created successfully at Sun Feb  5 10:49:52 2023
INFO:root:Document created successfully at Sun Feb  5 10:49:52 2023
WARNING:django.request:Forbidden: /employees
ERROR:django.request:Internal Server Error: /employee/28
Traceback (most recent call last):
  File "C:\django-mongo\django-mongo\venv\lib\site-packages\rest_framework\fields.py", line 446, in get_attribute
    return get_attribute(instance, self.source_attrs)
  File "C:\django-mongo\django-mongo\venv\lib\site-packages\rest_framework\fields.py", line 96, in get_attribute
    instance = getattr(instance, attr)
AttributeError: 'Response' object has no attribute 'name'

During handling of the above exception, another exception occurred:

Traceback (most recent call last):
  File "C:\django-mongo\django-mongo\venv\lib\site-packages\django\core\handlers\exception.py", line 47, in inner
    response = get_response(request)
  File "C:\django-mongo\django-mongo\venv\lib\site-packages\django\core\handlers\base.py", line 181, in _get_response
    response = wrapped_callback(request, *callback_args, **callback_kwargs)
  File "C:\django-mongo\django-mongo\venv\lib\site-packages\django\views\decorators\csrf.py", line 54, in wrapped_view
    return view_func(*args, **kwargs)
  File "C:\django-mongo\django-mongo\venv\lib\site-packages\django\views\generic\base.py", line 70, in view
    return self.dispatch(request, *args, **kwargs)
  File "C:\django-mongo\django-mongo\venv\lib\site-packages\rest_framework\views.py", line 509, in dispatch
    response = self.handle_exception(exc)
  File "C:\django-mongo\django-mongo\venv\lib\site-packages\rest_framework\views.py", line 469, in handle_exception
    self.raise_uncaught_exception(exc)
  File "C:\django-mongo\django-mongo\venv\lib\site-packages\rest_framework\views.py", line 480, in raise_uncaught_exception
    raise exc
  File "C:\django-mongo\django-mongo\venv\lib\site-packages\rest_framework\views.py", line 506, in dispatch
    response = handler(request, *args, **kwargs)
  File "C:\django-mongo\django-mongo\venv\lib\site-packages\rest_framework_mongoengine\generics.py", line 124, in get
    return self.retrieve(request, *args, **kwargs)
  File "C:\django-mongo\django-mongo\venv\lib\site-packages\rest_framework\mixins.py", line 56, in retrieve
    return Response(serializer.data)
  File "C:\django-mongo\django-mongo\venv\lib\site-packages\rest_framework\serializers.py", line 555, in data
    ret = super().data
  File "C:\django-mongo\django-mongo\venv\lib\site-packages\rest_framework\serializers.py", line 253, in data
    self._data = self.to_representation(self.instance)
  File "C:\django-mongo\django-mongo\venv\lib\site-packages\rest_framework\serializers.py", line 509, in to_representation
    attribute = field.get_attribute(instance)
  File "C:\django-mongo\django-mongo\venv\lib\site-packages\rest_framework\fields.py", line 479, in get_attribute
    raise type(exc)(msg)
AttributeError: Got AttributeError when attempting to get a value for field `name` on serializer `EmployeeSerializer`.
The serializer field might be named incorrectly and not match any attribute or key on the `Response` instance.
Original exception text was: 'Response' object has no attribute 'name'.
INFO:django.utils.autoreload:C:\django-mongo\django-mongo\EmployeeApp\views.py changed, reloading.
INFO:root:Document created successfully at Sun Feb  5 10:50:43 2023
INFO:root:Document created successfully at Sun Feb  5 10:50:43 2023
INFO:django.utils.autoreload:C:\django-mongo\django-mongo\EmployeeApp\views.py changed, reloading.
INFO:root:Document created successfully at Sun Feb  5 10:50:52 2023
INFO:root:Document created successfully at Sun Feb  5 10:50:52 2023
ERROR:django.request:Internal Server Error: /employee/28
Traceback (most recent call last):
  File "C:\django-mongo\django-mongo\venv\lib\site-packages\rest_framework\fields.py", line 446, in get_attribute
    return get_attribute(instance, self.source_attrs)
  File "C:\django-mongo\django-mongo\venv\lib\site-packages\rest_framework\fields.py", line 96, in get_attribute
    instance = getattr(instance, attr)
AttributeError: 'Response' object has no attribute 'name'

During handling of the above exception, another exception occurred:

Traceback (most recent call last):
  File "C:\django-mongo\django-mongo\venv\lib\site-packages\django\core\handlers\exception.py", line 47, in inner
    response = get_response(request)
  File "C:\django-mongo\django-mongo\venv\lib\site-packages\django\core\handlers\base.py", line 181, in _get_response
    response = wrapped_callback(request, *callback_args, **callback_kwargs)
  File "C:\django-mongo\django-mongo\venv\lib\site-packages\django\views\decorators\csrf.py", line 54, in wrapped_view
    return view_func(*args, **kwargs)
  File "C:\django-mongo\django-mongo\venv\lib\site-packages\django\views\generic\base.py", line 70, in view
    return self.dispatch(request, *args, **kwargs)
  File "C:\django-mongo\django-mongo\venv\lib\site-packages\rest_framework\views.py", line 509, in dispatch
    response = self.handle_exception(exc)
  File "C:\django-mongo\django-mongo\venv\lib\site-packages\rest_framework\views.py", line 469, in handle_exception
    self.raise_uncaught_exception(exc)
  File "C:\django-mongo\django-mongo\venv\lib\site-packages\rest_framework\views.py", line 480, in raise_uncaught_exception
    raise exc
  File "C:\django-mongo\django-mongo\venv\lib\site-packages\rest_framework\views.py", line 506, in dispatch
    response = handler(request, *args, **kwargs)
  File "C:\django-mongo\django-mongo\venv\lib\site-packages\rest_framework_mongoengine\generics.py", line 124, in get
    return self.retrieve(request, *args, **kwargs)
  File "C:\django-mongo\django-mongo\venv\lib\site-packages\rest_framework\mixins.py", line 56, in retrieve
    return Response(serializer.data)
  File "C:\django-mongo\django-mongo\venv\lib\site-packages\rest_framework\serializers.py", line 555, in data
    ret = super().data
  File "C:\django-mongo\django-mongo\venv\lib\site-packages\rest_framework\serializers.py", line 253, in data
    self._data = self.to_representation(self.instance)
  File "C:\django-mongo\django-mongo\venv\lib\site-packages\rest_framework\serializers.py", line 509, in to_representation
    attribute = field.get_attribute(instance)
  File "C:\django-mongo\django-mongo\venv\lib\site-packages\rest_framework\fields.py", line 479, in get_attribute
    raise type(exc)(msg)
AttributeError: Got AttributeError when attempting to get a value for field `name` on serializer `EmployeeSerializer`.
The serializer field might be named incorrectly and not match any attribute or key on the `Response` instance.
Original exception text was: 'Response' object has no attribute 'name'.
ERROR:root:Failed to update document with ID 28 due to validation error: {'name': [ErrorDetail(string='This field is required.', code='required')], 'age': [ErrorDetail(string='This field is required.', code='required')], 'company': [ErrorDetail(string='This field is required.', code='required')], 'email': [ErrorDetail(string='This field is required.', code='required')], 'password': [ErrorDetail(string='This field is required.', code='required')]}
WARNING:django.request:Bad Request: /employee/28
INFO:root:Document created successfully at Sun Feb  5 10:53:03 2023
INFO:root:Document created successfully at Sun Feb  5 10:53:03 2023
ERROR:django.request:Internal Server Error: /employee/28
Traceback (most recent call last):
  File "C:\django-mongo\django-mongo\venv\lib\site-packages\rest_framework\fields.py", line 446, in get_attribute
    return get_attribute(instance, self.source_attrs)
  File "C:\django-mongo\django-mongo\venv\lib\site-packages\rest_framework\fields.py", line 96, in get_attribute
    instance = getattr(instance, attr)
AttributeError: 'Response' object has no attribute 'name'

During handling of the above exception, another exception occurred:

Traceback (most recent call last):
  File "C:\django-mongo\django-mongo\venv\lib\site-packages\django\core\handlers\exception.py", line 47, in inner
    response = get_response(request)
  File "C:\django-mongo\django-mongo\venv\lib\site-packages\django\core\handlers\base.py", line 181, in _get_response
    response = wrapped_callback(request, *callback_args, **callback_kwargs)
  File "C:\django-mongo\django-mongo\venv\lib\site-packages\django\views\decorators\csrf.py", line 54, in wrapped_view
    return view_func(*args, **kwargs)
  File "C:\django-mongo\django-mongo\venv\lib\site-packages\django\views\generic\base.py", line 70, in view
    return self.dispatch(request, *args, **kwargs)
  File "C:\django-mongo\django-mongo\venv\lib\site-packages\rest_framework\views.py", line 509, in dispatch
    response = self.handle_exception(exc)
  File "C:\django-mongo\django-mongo\venv\lib\site-packages\rest_framework\views.py", line 469, in handle_exception
    self.raise_uncaught_exception(exc)
  File "C:\django-mongo\django-mongo\venv\lib\site-packages\rest_framework\views.py", line 480, in raise_uncaught_exception
    raise exc
  File "C:\django-mongo\django-mongo\venv\lib\site-packages\rest_framework\views.py", line 506, in dispatch
    response = handler(request, *args, **kwargs)
  File "C:\django-mongo\django-mongo\venv\lib\site-packages\rest_framework_mongoengine\generics.py", line 124, in get
    return self.retrieve(request, *args, **kwargs)
  File "C:\django-mongo\django-mongo\venv\lib\site-packages\rest_framework\mixins.py", line 56, in retrieve
    return Response(serializer.data)
  File "C:\django-mongo\django-mongo\venv\lib\site-packages\rest_framework\serializers.py", line 555, in data
    ret = super().data
  File "C:\django-mongo\django-mongo\venv\lib\site-packages\rest_framework\serializers.py", line 253, in data
    self._data = self.to_representation(self.instance)
  File "C:\django-mongo\django-mongo\venv\lib\site-packages\rest_framework\serializers.py", line 509, in to_representation
    attribute = field.get_attribute(instance)
  File "C:\django-mongo\django-mongo\venv\lib\site-packages\rest_framework\fields.py", line 479, in get_attribute
    raise type(exc)(msg)
AttributeError: Got AttributeError when attempting to get a value for field `name` on serializer `EmployeeSerializer`.
The serializer field might be named incorrectly and not match any attribute or key on the `Response` instance.
Original exception text was: 'Response' object has no attribute 'name'.
INFO:root:Document created successfully at Sun Feb  5 10:55:09 2023
INFO:root:Document created successfully at Sun Feb  5 10:55:09 2023
ERROR:django.request:Internal Server Error: /employee/28
Traceback (most recent call last):
  File "C:\django-mongo\django-mongo\venv\lib\site-packages\rest_framework\fields.py", line 446, in get_attribute
    return get_attribute(instance, self.source_attrs)
  File "C:\django-mongo\django-mongo\venv\lib\site-packages\rest_framework\fields.py", line 96, in get_attribute
    instance = getattr(instance, attr)
AttributeError: 'Response' object has no attribute 'name'

During handling of the above exception, another exception occurred:

Traceback (most recent call last):
  File "C:\django-mongo\django-mongo\venv\lib\site-packages\django\core\handlers\exception.py", line 47, in inner
    response = get_response(request)
  File "C:\django-mongo\django-mongo\venv\lib\site-packages\django\core\handlers\base.py", line 181, in _get_response
    response = wrapped_callback(request, *callback_args, **callback_kwargs)
  File "C:\django-mongo\django-mongo\venv\lib\site-packages\django\views\decorators\csrf.py", line 54, in wrapped_view
    return view_func(*args, **kwargs)
  File "C:\django-mongo\django-mongo\venv\lib\site-packages\django\views\generic\base.py", line 70, in view
    return self.dispatch(request, *args, **kwargs)
  File "C:\django-mongo\django-mongo\venv\lib\site-packages\rest_framework\views.py", line 509, in dispatch
    response = self.handle_exception(exc)
  File "C:\django-mongo\django-mongo\venv\lib\site-packages\rest_framework\views.py", line 469, in handle_exception
    self.raise_uncaught_exception(exc)
  File "C:\django-mongo\django-mongo\venv\lib\site-packages\rest_framework\views.py", line 480, in raise_uncaught_exception
    raise exc
  File "C:\django-mongo\django-mongo\venv\lib\site-packages\rest_framework\views.py", line 506, in dispatch
    response = handler(request, *args, **kwargs)
  File "C:\django-mongo\django-mongo\venv\lib\site-packages\rest_framework_mongoengine\generics.py", line 124, in get
    return self.retrieve(request, *args, **kwargs)
  File "C:\django-mongo\django-mongo\venv\lib\site-packages\rest_framework\mixins.py", line 56, in retrieve
    return Response(serializer.data)
  File "C:\django-mongo\django-mongo\venv\lib\site-packages\rest_framework\serializers.py", line 555, in data
    ret = super().data
  File "C:\django-mongo\django-mongo\venv\lib\site-packages\rest_framework\serializers.py", line 253, in data
    self._data = self.to_representation(self.instance)
  File "C:\django-mongo\django-mongo\venv\lib\site-packages\rest_framework\serializers.py", line 509, in to_representation
    attribute = field.get_attribute(instance)
  File "C:\django-mongo\django-mongo\venv\lib\site-packages\rest_framework\fields.py", line 479, in get_attribute
    raise type(exc)(msg)
AttributeError: Got AttributeError when attempting to get a value for field `name` on serializer `EmployeeSerializer`.
The serializer field might be named incorrectly and not match any attribute or key on the `Response` instance.
Original exception text was: 'Response' object has no attribute 'name'.
INFO:django.utils.autoreload:C:\django-mongo\django-mongo\EmployeeApp\views.py changed, reloading.
INFO:root:Document created successfully at Sun Feb  5 10:56:11 2023
INFO:root:Document created successfully at Sun Feb  5 10:56:11 2023
INFO:django.utils.autoreload:C:\django-mongo\django-mongo\EmployeeApp\views.py changed, reloading.
INFO:root:Document created successfully at Sun Feb  5 10:56:23 2023
INFO:root:Document created successfully at Sun Feb  5 10:56:23 2023
INFO:django.utils.autoreload:C:\django-mongo\django-mongo\EmployeeApp\views.py changed, reloading.
INFO:root:Document created successfully at Sun Feb  5 10:56:32 2023
INFO:root:Document created successfully at Sun Feb  5 10:56:33 2023
INFO:django.utils.autoreload:C:\django-mongo\django-mongo\EmployeeApp\views.py changed, reloading.
INFO:root:Document created successfully at Sun Feb  5 10:56:46 2023
INFO:root:Document created successfully at Sun Feb  5 10:56:46 2023
INFO:django.utils.autoreload:C:\django-mongo\django-mongo\EmployeeApp\views.py changed, reloading.
INFO:root:Document created successfully at Sun Feb  5 10:56:56 2023
INFO:root:Document created successfully at Sun Feb  5 10:56:56 2023
INFO:django.utils.autoreload:C:\django-mongo\django-mongo\EmployeeApp\views.py changed, reloading.
INFO:root:Document created successfully at Sun Feb  5 10:57:01 2023
INFO:root:Document created successfully at Sun Feb  5 10:57:01 2023
INFO:django.utils.autoreload:C:\django-mongo\django-mongo\EmployeeApp\views.py changed, reloading.
INFO:root:Document created successfully at Sun Feb  5 10:57:09 2023
INFO:root:Document created successfully at Sun Feb  5 10:57:09 2023
ERROR:django.request:Internal Server Error: /employee/28
Traceback (most recent call last):
  File "C:\django-mongo\django-mongo\venv\lib\site-packages\rest_framework\fields.py", line 446, in get_attribute
    return get_attribute(instance, self.source_attrs)
  File "C:\django-mongo\django-mongo\venv\lib\site-packages\rest_framework\fields.py", line 96, in get_attribute
    instance = getattr(instance, attr)
AttributeError: 'NotFound' object has no attribute 'name'

During handling of the above exception, another exception occurred:

Traceback (most recent call last):
  File "C:\django-mongo\django-mongo\venv\lib\site-packages\django\core\handlers\exception.py", line 47, in inner
    response = get_response(request)
  File "C:\django-mongo\django-mongo\venv\lib\site-packages\django\core\handlers\base.py", line 181, in _get_response
    response = wrapped_callback(request, *callback_args, **callback_kwargs)
  File "C:\django-mongo\django-mongo\venv\lib\site-packages\django\views\decorators\csrf.py", line 54, in wrapped_view
    return view_func(*args, **kwargs)
  File "C:\django-mongo\django-mongo\venv\lib\site-packages\django\views\generic\base.py", line 70, in view
    return self.dispatch(request, *args, **kwargs)
  File "C:\django-mongo\django-mongo\venv\lib\site-packages\rest_framework\views.py", line 509, in dispatch
    response = self.handle_exception(exc)
  File "C:\django-mongo\django-mongo\venv\lib\site-packages\rest_framework\views.py", line 469, in handle_exception
    self.raise_uncaught_exception(exc)
  File "C:\django-mongo\django-mongo\venv\lib\site-packages\rest_framework\views.py", line 480, in raise_uncaught_exception
    raise exc
  File "C:\django-mongo\django-mongo\venv\lib\site-packages\rest_framework\views.py", line 506, in dispatch
    response = handler(request, *args, **kwargs)
  File "C:\django-mongo\django-mongo\venv\lib\site-packages\rest_framework_mongoengine\generics.py", line 124, in get
    return self.retrieve(request, *args, **kwargs)
  File "C:\django-mongo\django-mongo\venv\lib\site-packages\rest_framework\mixins.py", line 56, in retrieve
    return Response(serializer.data)
  File "C:\django-mongo\django-mongo\venv\lib\site-packages\rest_framework\serializers.py", line 555, in data
    ret = super().data
  File "C:\django-mongo\django-mongo\venv\lib\site-packages\rest_framework\serializers.py", line 253, in data
    self._data = self.to_representation(self.instance)
  File "C:\django-mongo\django-mongo\venv\lib\site-packages\rest_framework\serializers.py", line 509, in to_representation
    attribute = field.get_attribute(instance)
  File "C:\django-mongo\django-mongo\venv\lib\site-packages\rest_framework\fields.py", line 479, in get_attribute
    raise type(exc)(msg)
AttributeError: Got AttributeError when attempting to get a value for field `name` on serializer `EmployeeSerializer`.
The serializer field might be named incorrectly and not match any attribute or key on the `NotFound` instance.
Original exception text was: 'NotFound' object has no attribute 'name'.
INFO:django.utils.autoreload:C:\django-mongo\django-mongo\EmployeeApp\views.py changed, reloading.
INFO:root:Document created successfully at Sun Feb  5 11:00:48 2023
INFO:root:Document created successfully at Sun Feb  5 11:00:48 2023
INFO:django.utils.autoreload:C:\django-mongo\django-mongo\EmployeeApp\views.py changed, reloading.
INFO:root:Document created successfully at Sun Feb  5 11:00:52 2023
INFO:root:Document created successfully at Sun Feb  5 11:00:52 2023
ERROR:django.request:Internal Server Error: /employee/28
Traceback (most recent call last):
  File "C:\django-mongo\django-mongo\venv\lib\site-packages\rest_framework\fields.py", line 446, in get_attribute
    return get_attribute(instance, self.source_attrs)
  File "C:\django-mongo\django-mongo\venv\lib\site-packages\rest_framework\fields.py", line 96, in get_attribute
    instance = getattr(instance, attr)
AttributeError: 'Response' object has no attribute 'name'

During handling of the above exception, another exception occurred:

Traceback (most recent call last):
  File "C:\django-mongo\django-mongo\venv\lib\site-packages\django\core\handlers\exception.py", line 47, in inner
    response = get_response(request)
  File "C:\django-mongo\django-mongo\venv\lib\site-packages\django\core\handlers\base.py", line 181, in _get_response
    response = wrapped_callback(request, *callback_args, **callback_kwargs)
  File "C:\django-mongo\django-mongo\venv\lib\site-packages\django\views\decorators\csrf.py", line 54, in wrapped_view
    return view_func(*args, **kwargs)
  File "C:\django-mongo\django-mongo\venv\lib\site-packages\django\views\generic\base.py", line 70, in view
    return self.dispatch(request, *args, **kwargs)
  File "C:\django-mongo\django-mongo\venv\lib\site-packages\rest_framework\views.py", line 509, in dispatch
    response = self.handle_exception(exc)
  File "C:\django-mongo\django-mongo\venv\lib\site-packages\rest_framework\views.py", line 469, in handle_exception
    self.raise_uncaught_exception(exc)
  File "C:\django-mongo\django-mongo\venv\lib\site-packages\rest_framework\views.py", line 480, in raise_uncaught_exception
    raise exc
  File "C:\django-mongo\django-mongo\venv\lib\site-packages\rest_framework\views.py", line 506, in dispatch
    response = handler(request, *args, **kwargs)
  File "C:\django-mongo\django-mongo\venv\lib\site-packages\rest_framework_mongoengine\generics.py", line 124, in get
    return self.retrieve(request, *args, **kwargs)
  File "C:\django-mongo\django-mongo\venv\lib\site-packages\rest_framework\mixins.py", line 56, in retrieve
    return Response(serializer.data)
  File "C:\django-mongo\django-mongo\venv\lib\site-packages\rest_framework\serializers.py", line 555, in data
    ret = super().data
  File "C:\django-mongo\django-mongo\venv\lib\site-packages\rest_framework\serializers.py", line 253, in data
    self._data = self.to_representation(self.instance)
  File "C:\django-mongo\django-mongo\venv\lib\site-packages\rest_framework\serializers.py", line 509, in to_representation
    attribute = field.get_attribute(instance)
  File "C:\django-mongo\django-mongo\venv\lib\site-packages\rest_framework\fields.py", line 479, in get_attribute
    raise type(exc)(msg)
AttributeError: Got AttributeError when attempting to get a value for field `name` on serializer `EmployeeSerializer`.
The serializer field might be named incorrectly and not match any attribute or key on the `Response` instance.
Original exception text was: 'Response' object has no attribute 'name'.
WARNING:django.request:Bad Request: /employee/29
INFO:django.utils.autoreload:C:\django-mongo\django-mongo\EmployeeApp\views.py changed, reloading.
INFO:root:Document created successfully at Sun Feb  5 11:01:52 2023
INFO:root:Document created successfully at Sun Feb  5 11:01:52 2023
ERROR:root:Failed to update document with ID 29 due to validation error: {'company': [ErrorDetail(string='This field is required.', code='required')], 'email': [ErrorDetail(string='This field is required.', code='required')], 'password': [ErrorDetail(string='This field is required.', code='required')]}
WARNING:django.request:Bad Request: /employee/29
WARNING:django.request:Forbidden: /employee/29
INFO:django.utils.autoreload:C:\django-mongo\django-mongo\EmployeeApp\middleware.py changed, reloading.
INFO:root:Document created successfully at Sun Feb  5 11:07:58 2023
INFO:root:Document created successfully at Sun Feb  5 11:07:58 2023
INFO:django.utils.autoreload:C:\django-mongo\django-mongo\EmployeeApp\middleware.py changed, reloading.
INFO:root:Document created successfully at Sun Feb  5 11:52:53 2023
INFO:root:Document created successfully at Sun Feb  5 11:52:53 2023
INFO:django.utils.autoreload:C:\django-mongo\django-mongo\EmployeeApp\middleware.py changed, reloading.
INFO:root:Document created successfully at Sun Feb  5 11:59:42 2023
INFO:root:Document created successfully at Sun Feb  5 11:59:42 2023
WARNING:django.request:Forbidden: /employee/29
INFO:django.utils.autoreload:C:\django-mongo\django-mongo\new_project\settings.py changed, reloading.
INFO:root:Document created successfully at Sun Feb  5 12:01:03 2023
INFO:root:Document created successfully at Sun Feb  5 12:01:03 2023
ERROR:django.request:Internal Server Error: /employee/29
Traceback (most recent call last):
  File "C:\django-mongo\django-mongo\venv\lib\site-packages\django\core\handlers\exception.py", line 47, in inner
    response = get_response(request)
  File "C:\django-mongo\django-mongo\venv\lib\site-packages\django\core\handlers\base.py", line 181, in _get_response
    response = wrapped_callback(request, *callback_args, **callback_kwargs)
  File "C:\django-mongo\django-mongo\venv\lib\site-packages\django\views\decorators\csrf.py", line 54, in wrapped_view
    return view_func(*args, **kwargs)
  File "C:\django-mongo\django-mongo\venv\lib\site-packages\django\views\generic\base.py", line 70, in view
    return self.dispatch(request, *args, **kwargs)
  File "C:\django-mongo\django-mongo\venv\lib\site-packages\rest_framework\views.py", line 509, in dispatch
    response = self.handle_exception(exc)
  File "C:\django-mongo\django-mongo\venv\lib\site-packages\rest_framework\views.py", line 469, in handle_exception
    self.raise_uncaught_exception(exc)
  File "C:\django-mongo\django-mongo\venv\lib\site-packages\rest_framework\views.py", line 480, in raise_uncaught_exception
    raise exc
  File "C:\django-mongo\django-mongo\venv\lib\site-packages\rest_framework\views.py", line 497, in dispatch
    self.initial(request, *args, **kwargs)
  File "C:\django-mongo\django-mongo\venv\lib\site-packages\rest_framework\views.py", line 415, in initial
    self.check_permissions(request)
  File "C:\django-mongo\django-mongo\venv\lib\site-packages\rest_framework\views.py", line 332, in check_permissions
    if not permission.has_permission(request, self):
  File "C:\django-mongo\django-mongo\EmployeeApp\middleware.py", line 34, in has_permission
    return user['_id'] == view.kwargs.get('pk')
TypeError: 'NoneType' object is not subscriptable
INFO:django.utils.autoreload:C:\django-mongo\django-mongo\EmployeeApp\middleware.py changed, reloading.
INFO:root:Document created successfully at Sun Feb  5 12:02:01 2023
INFO:root:Document created successfully at Sun Feb  5 12:02:01 2023
ERROR:django.request:Internal Server Error: /employee/29
Traceback (most recent call last):
  File "C:\django-mongo\django-mongo\venv\lib\site-packages\django\core\handlers\exception.py", line 47, in inner
    response = get_response(request)
  File "C:\django-mongo\django-mongo\venv\lib\site-packages\django\core\handlers\base.py", line 181, in _get_response
    response = wrapped_callback(request, *callback_args, **callback_kwargs)
  File "C:\django-mongo\django-mongo\venv\lib\site-packages\django\views\decorators\csrf.py", line 54, in wrapped_view
    return view_func(*args, **kwargs)
  File "C:\django-mongo\django-mongo\venv\lib\site-packages\django\views\generic\base.py", line 70, in view
    return self.dispatch(request, *args, **kwargs)
  File "C:\django-mongo\django-mongo\venv\lib\site-packages\rest_framework\views.py", line 509, in dispatch
    response = self.handle_exception(exc)
  File "C:\django-mongo\django-mongo\venv\lib\site-packages\rest_framework\views.py", line 469, in handle_exception
    self.raise_uncaught_exception(exc)
  File "C:\django-mongo\django-mongo\venv\lib\site-packages\rest_framework\views.py", line 480, in raise_uncaught_exception
    raise exc
  File "C:\django-mongo\django-mongo\venv\lib\site-packages\rest_framework\views.py", line 497, in dispatch
    self.initial(request, *args, **kwargs)
  File "C:\django-mongo\django-mongo\venv\lib\site-packages\rest_framework\views.py", line 415, in initial
    self.check_permissions(request)
  File "C:\django-mongo\django-mongo\venv\lib\site-packages\rest_framework\views.py", line 332, in check_permissions
    if not permission.has_permission(request, self):
  File "C:\django-mongo\django-mongo\EmployeeApp\middleware.py", line 35, in has_permission
    return user['_id'] == view.kwargs.get('pk')
TypeError: 'NoneType' object is not subscriptable
INFO:root:Document created successfully at Sun Feb  5 12:04:48 2023
INFO:root:Document created successfully at Sun Feb  5 12:04:48 2023
ERROR:django.request:Internal Server Error: /employee/29
Traceback (most recent call last):
  File "C:\django-mongo\django-mongo\venv\lib\site-packages\django\core\handlers\exception.py", line 47, in inner
    response = get_response(request)
  File "C:\django-mongo\django-mongo\venv\lib\site-packages\django\core\handlers\base.py", line 181, in _get_response
    response = wrapped_callback(request, *callback_args, **callback_kwargs)
  File "C:\django-mongo\django-mongo\venv\lib\site-packages\django\views\decorators\csrf.py", line 54, in wrapped_view
    return view_func(*args, **kwargs)
  File "C:\django-mongo\django-mongo\venv\lib\site-packages\django\views\generic\base.py", line 70, in view
    return self.dispatch(request, *args, **kwargs)
  File "C:\django-mongo\django-mongo\venv\lib\site-packages\rest_framework\views.py", line 509, in dispatch
    response = self.handle_exception(exc)
  File "C:\django-mongo\django-mongo\venv\lib\site-packages\rest_framework\views.py", line 469, in handle_exception
    self.raise_uncaught_exception(exc)
  File "C:\django-mongo\django-mongo\venv\lib\site-packages\rest_framework\views.py", line 480, in raise_uncaught_exception
    raise exc
  File "C:\django-mongo\django-mongo\venv\lib\site-packages\rest_framework\views.py", line 497, in dispatch
    self.initial(request, *args, **kwargs)
  File "C:\django-mongo\django-mongo\venv\lib\site-packages\rest_framework\views.py", line 414, in initial
    self.perform_authentication(request)
  File "C:\django-mongo\django-mongo\venv\lib\site-packages\rest_framework\views.py", line 324, in perform_authentication
    request.user
  File "C:\django-mongo\django-mongo\venv\lib\site-packages\rest_framework\request.py", line 227, in user
    self._authenticate()
  File "C:\django-mongo\django-mongo\venv\lib\site-packages\rest_framework\request.py", line 380, in _authenticate
    user_auth_tuple = authenticator.authenticate(self)
TypeError: authenticate() missing 1 required positional argument: 'view'
INFO:root:Document created successfully at Sun Feb  5 12:06:06 2023
INFO:root:Document created successfully at Sun Feb  5 12:06:06 2023
INFO:django.utils.autoreload:C:\django-mongo\django-mongo\new_project\settings.py changed, reloading.
INFO:root:Document created successfully at Sun Feb  5 12:06:20 2023
INFO:root:Document created successfully at Sun Feb  5 12:06:21 2023
WARNING:django.request:Forbidden: /employee/29
WARNING:django.request:Forbidden: /employee/28
INFO:django.utils.autoreload:C:\django-mongo\django-mongo\EmployeeApp\middleware.py changed, reloading.
INFO:root:Document created successfully at Sun Feb  5 12:07:16 2023
INFO:root:Document created successfully at Sun Feb  5 12:07:16 2023
WARNING:django.request:Forbidden: /employee/28
INFO:django.utils.autoreload:C:\django-mongo\django-mongo\EmployeeApp\middleware.py changed, reloading.
INFO:root:Document created successfully at Sun Feb  5 12:07:34 2023
INFO:root:Document created successfully at Sun Feb  5 12:07:34 2023
INFO:django.utils.autoreload:C:\django-mongo\django-mongo\EmployeeApp\middleware.py changed, reloading.
INFO:root:Document created successfully at Sun Feb  5 12:07:40 2023
INFO:root:Document created successfully at Sun Feb  5 12:07:41 2023
WARNING:django.request:Forbidden: /employee/28
INFO:django.utils.autoreload:C:\django-mongo\django-mongo\EmployeeApp\middleware.py changed, reloading.
INFO:root:Document created successfully at Sun Feb  5 12:07:57 2023
INFO:root:Document created successfully at Sun Feb  5 12:07:58 2023
INFO:django.utils.autoreload:C:\django-mongo\django-mongo\EmployeeApp\middleware.py changed, reloading.
INFO:root:Document created successfully at Sun Feb  5 12:08:03 2023
INFO:root:Document created successfully at Sun Feb  5 12:08:03 2023
INFO:django.utils.autoreload:C:\django-mongo\django-mongo\EmployeeApp\middleware.py changed, reloading.
INFO:root:Document created successfully at Sun Feb  5 12:16:05 2023
INFO:root:Document created successfully at Sun Feb  5 12:16:05 2023
ERROR:django.request:Internal Server Error: /employee/28
Traceback (most recent call last):
  File "C:\django-mongo\django-mongo\venv\lib\site-packages\django\core\handlers\exception.py", line 47, in inner
    response = get_response(request)
  File "C:\django-mongo\django-mongo\venv\lib\site-packages\django\core\handlers\base.py", line 181, in _get_response
    response = wrapped_callback(request, *callback_args, **callback_kwargs)
  File "C:\django-mongo\django-mongo\venv\lib\site-packages\django\views\decorators\csrf.py", line 54, in wrapped_view
    return view_func(*args, **kwargs)
  File "C:\django-mongo\django-mongo\venv\lib\site-packages\django\views\generic\base.py", line 70, in view
    return self.dispatch(request, *args, **kwargs)
  File "C:\django-mongo\django-mongo\venv\lib\site-packages\rest_framework\views.py", line 509, in dispatch
    response = self.handle_exception(exc)
  File "C:\django-mongo\django-mongo\venv\lib\site-packages\rest_framework\views.py", line 469, in handle_exception
    self.raise_uncaught_exception(exc)
  File "C:\django-mongo\django-mongo\venv\lib\site-packages\rest_framework\views.py", line 480, in raise_uncaught_exception
    raise exc
  File "C:\django-mongo\django-mongo\venv\lib\site-packages\rest_framework\views.py", line 497, in dispatch
    self.initial(request, *args, **kwargs)
  File "C:\django-mongo\django-mongo\venv\lib\site-packages\rest_framework\views.py", line 415, in initial
    self.check_permissions(request)
  File "C:\django-mongo\django-mongo\venv\lib\site-packages\rest_framework\views.py", line 332, in check_permissions
    if not permission.has_permission(request, self):
  File "C:\django-mongo\django-mongo\EmployeeApp\middleware.py", line 36, in has_permission
    return user["_id"] == view.kwargs.get("pk")
  File "C:\django-mongo\django-mongo\venv\lib\site-packages\mongoengine\base\document.py", line 257, in __getitem__
    raise KeyError(name)
KeyError: '_id'
INFO:django.utils.autoreload:C:\django-mongo\django-mongo\EmployeeApp\middleware.py changed, reloading.
INFO:root:Document created successfully at Sun Feb  5 12:16:38 2023
INFO:root:Document created successfully at Sun Feb  5 12:16:38 2023
INFO:django.utils.autoreload:C:\django-mongo\django-mongo\EmployeeApp\middleware.py changed, reloading.
INFO:root:Document created successfully at Sun Feb  5 12:16:44 2023
INFO:root:Document created successfully at Sun Feb  5 12:16:44 2023
ERROR:django.request:Internal Server Error: /employee/28
Traceback (most recent call last):
  File "C:\django-mongo\django-mongo\venv\lib\site-packages\django\core\handlers\exception.py", line 47, in inner
    response = get_response(request)
  File "C:\django-mongo\django-mongo\venv\lib\site-packages\django\core\handlers\base.py", line 181, in _get_response
    response = wrapped_callback(request, *callback_args, **callback_kwargs)
  File "C:\django-mongo\django-mongo\venv\lib\site-packages\django\views\decorators\csrf.py", line 54, in wrapped_view
    return view_func(*args, **kwargs)
  File "C:\django-mongo\django-mongo\venv\lib\site-packages\django\views\generic\base.py", line 70, in view
    return self.dispatch(request, *args, **kwargs)
  File "C:\django-mongo\django-mongo\venv\lib\site-packages\rest_framework\views.py", line 509, in dispatch
    response = self.handle_exception(exc)
  File "C:\django-mongo\django-mongo\venv\lib\site-packages\rest_framework\views.py", line 469, in handle_exception
    self.raise_uncaught_exception(exc)
  File "C:\django-mongo\django-mongo\venv\lib\site-packages\rest_framework\views.py", line 480, in raise_uncaught_exception
    raise exc
  File "C:\django-mongo\django-mongo\venv\lib\site-packages\rest_framework\views.py", line 497, in dispatch
    self.initial(request, *args, **kwargs)
  File "C:\django-mongo\django-mongo\venv\lib\site-packages\rest_framework\views.py", line 415, in initial
    self.check_permissions(request)
  File "C:\django-mongo\django-mongo\venv\lib\site-packages\rest_framework\views.py", line 332, in check_permissions
    if not permission.has_permission(request, self):
  File "C:\django-mongo\django-mongo\EmployeeApp\middleware.py", line 36, in has_permission
    return user["_id"] == view.kwargs.get("pk")
  File "C:\django-mongo\django-mongo\venv\lib\site-packages\mongoengine\base\document.py", line 257, in __getitem__
    raise KeyError(name)
KeyError: '_id'
INFO:django.utils.autoreload:C:\django-mongo\django-mongo\EmployeeApp\middleware.py changed, reloading.
INFO:root:Document created successfully at Sun Feb  5 12:17:12 2023
INFO:root:Document created successfully at Sun Feb  5 12:17:12 2023
ERROR:django.request:Internal Server Error: /employee/28
Traceback (most recent call last):
  File "C:\django-mongo\django-mongo\venv\lib\site-packages\django\core\handlers\exception.py", line 47, in inner
    response = get_response(request)
  File "C:\django-mongo\django-mongo\venv\lib\site-packages\django\core\handlers\base.py", line 181, in _get_response
    response = wrapped_callback(request, *callback_args, **callback_kwargs)
  File "C:\django-mongo\django-mongo\venv\lib\site-packages\django\views\decorators\csrf.py", line 54, in wrapped_view
    return view_func(*args, **kwargs)
  File "C:\django-mongo\django-mongo\venv\lib\site-packages\django\views\generic\base.py", line 70, in view
    return self.dispatch(request, *args, **kwargs)
  File "C:\django-mongo\django-mongo\venv\lib\site-packages\rest_framework\views.py", line 509, in dispatch
    response = self.handle_exception(exc)
  File "C:\django-mongo\django-mongo\venv\lib\site-packages\rest_framework\views.py", line 469, in handle_exception
    self.raise_uncaught_exception(exc)
  File "C:\django-mongo\django-mongo\venv\lib\site-packages\rest_framework\views.py", line 480, in raise_uncaught_exception
    raise exc
  File "C:\django-mongo\django-mongo\venv\lib\site-packages\rest_framework\views.py", line 497, in dispatch
    self.initial(request, *args, **kwargs)
  File "C:\django-mongo\django-mongo\venv\lib\site-packages\rest_framework\views.py", line 415, in initial
    self.check_permissions(request)
  File "C:\django-mongo\django-mongo\venv\lib\site-packages\rest_framework\views.py", line 332, in check_permissions
    if not permission.has_permission(request, self):
  File "C:\django-mongo\django-mongo\EmployeeApp\middleware.py", line 35, in has_permission
    print(user.get('name'))
AttributeError: 'Employee' object has no attribute 'get'
INFO:django.utils.autoreload:C:\django-mongo\django-mongo\EmployeeApp\middleware.py changed, reloading.
INFO:root:Document created successfully at Sun Feb  5 12:17:42 2023
INFO:root:Document created successfully at Sun Feb  5 12:17:42 2023
INFO:django.utils.autoreload:C:\django-mongo\django-mongo\EmployeeApp\middleware.py changed, reloading.
INFO:root:Document created successfully at Sun Feb  5 12:17:58 2023
INFO:root:Document created successfully at Sun Feb  5 12:17:58 2023
INFO:django.utils.autoreload:C:\django-mongo\django-mongo\EmployeeApp\middleware.py changed, reloading.
INFO:root:Document created successfully at Sun Feb  5 12:18:03 2023
INFO:root:Document created successfully at Sun Feb  5 12:18:03 2023
INFO:django.utils.autoreload:C:\django-mongo\django-mongo\EmployeeApp\middleware.py changed, reloading.
INFO:root:Document created successfully at Sun Feb  5 12:18:12 2023
INFO:root:Document created successfully at Sun Feb  5 12:18:12 2023
ERROR:django.request:Internal Server Error: /employee/28
Traceback (most recent call last):
  File "C:\django-mongo\django-mongo\venv\lib\site-packages\django\core\handlers\exception.py", line 47, in inner
    response = get_response(request)
  File "C:\django-mongo\django-mongo\venv\lib\site-packages\django\core\handlers\base.py", line 181, in _get_response
    response = wrapped_callback(request, *callback_args, **callback_kwargs)
  File "C:\django-mongo\django-mongo\venv\lib\site-packages\django\views\decorators\csrf.py", line 54, in wrapped_view
    return view_func(*args, **kwargs)
  File "C:\django-mongo\django-mongo\venv\lib\site-packages\django\views\generic\base.py", line 70, in view
    return self.dispatch(request, *args, **kwargs)
  File "C:\django-mongo\django-mongo\venv\lib\site-packages\rest_framework\views.py", line 509, in dispatch
    response = self.handle_exception(exc)
  File "C:\django-mongo\django-mongo\venv\lib\site-packages\rest_framework\views.py", line 469, in handle_exception
    self.raise_uncaught_exception(exc)
  File "C:\django-mongo\django-mongo\venv\lib\site-packages\rest_framework\views.py", line 480, in raise_uncaught_exception
    raise exc
  File "C:\django-mongo\django-mongo\venv\lib\site-packages\rest_framework\views.py", line 497, in dispatch
    self.initial(request, *args, **kwargs)
  File "C:\django-mongo\django-mongo\venv\lib\site-packages\rest_framework\views.py", line 415, in initial
    self.check_permissions(request)
  File "C:\django-mongo\django-mongo\venv\lib\site-packages\rest_framework\views.py", line 332, in check_permissions
    if not permission.has_permission(request, self):
  File "C:\django-mongo\django-mongo\EmployeeApp\middleware.py", line 36, in has_permission
    return employee["_id"] == view.kwargs.get("pk")
  File "C:\django-mongo\django-mongo\venv\lib\site-packages\mongoengine\base\document.py", line 257, in __getitem__
    raise KeyError(name)
KeyError: '_id'
INFO:django.utils.autoreload:C:\django-mongo\django-mongo\EmployeeApp\middleware.py changed, reloading.
INFO:root:Document created successfully at Sun Feb  5 12:18:32 2023
INFO:root:Document created successfully at Sun Feb  5 12:18:32 2023
INFO:django.utils.autoreload:C:\django-mongo\django-mongo\EmployeeApp\middleware.py changed, reloading.
INFO:root:Document created successfully at Sun Feb  5 12:18:49 2023
INFO:root:Document created successfully at Sun Feb  5 12:18:49 2023
INFO:django.utils.autoreload:C:\django-mongo\django-mongo\EmployeeApp\middleware.py changed, reloading.
INFO:root:Document created successfully at Sun Feb  5 12:18:56 2023
INFO:root:Document created successfully at Sun Feb  5 12:18:56 2023
ERROR:django.request:Internal Server Error: /employee/28
Traceback (most recent call last):
  File "C:\django-mongo\django-mongo\venv\lib\site-packages\mongoengine\queryset\transform.py", line 95, in query
    fields = _doc_cls._lookup_field(parts)
  File "C:\django-mongo\django-mongo\venv\lib\site-packages\mongoengine\base\document.py", line 1135, in _lookup_field
    raise LookUpError('Cannot resolve field "%s"' % field_name)
mongoengine.errors.LookUpError: Cannot resolve field "_id"

During handling of the above exception, another exception occurred:

Traceback (most recent call last):
  File "C:\django-mongo\django-mongo\venv\lib\site-packages\django\core\handlers\exception.py", line 47, in inner
    response = get_response(request)
  File "C:\django-mongo\django-mongo\venv\lib\site-packages\django\core\handlers\base.py", line 181, in _get_response
    response = wrapped_callback(request, *callback_args, **callback_kwargs)
  File "C:\django-mongo\django-mongo\venv\lib\site-packages\django\views\decorators\csrf.py", line 54, in wrapped_view
    return view_func(*args, **kwargs)
  File "C:\django-mongo\django-mongo\venv\lib\site-packages\django\views\generic\base.py", line 70, in view
    return self.dispatch(request, *args, **kwargs)
  File "C:\django-mongo\django-mongo\venv\lib\site-packages\rest_framework\views.py", line 509, in dispatch
    response = self.handle_exception(exc)
  File "C:\django-mongo\django-mongo\venv\lib\site-packages\rest_framework\views.py", line 469, in handle_exception
    self.raise_uncaught_exception(exc)
  File "C:\django-mongo\django-mongo\venv\lib\site-packages\rest_framework\views.py", line 480, in raise_uncaught_exception
    raise exc
  File "C:\django-mongo\django-mongo\venv\lib\site-packages\rest_framework\views.py", line 497, in dispatch
    self.initial(request, *args, **kwargs)
  File "C:\django-mongo\django-mongo\venv\lib\site-packages\rest_framework\views.py", line 415, in initial
    self.check_permissions(request)
  File "C:\django-mongo\django-mongo\venv\lib\site-packages\rest_framework\views.py", line 332, in check_permissions
    if not permission.has_permission(request, self):
  File "C:\django-mongo\django-mongo\EmployeeApp\middleware.py", line 35, in has_permission
    email=email, password=password, _id=view.kwargs.get("pk")
  File "C:\django-mongo\django-mongo\venv\lib\site-packages\mongoengine\queryset\base.py", line 269, in get
    result = next(queryset)
  File "C:\django-mongo\django-mongo\venv\lib\site-packages\mongoengine\queryset\base.py", line 1596, in __next__
    raw_doc = next(self._cursor)
  File "C:\django-mongo\django-mongo\venv\lib\site-packages\mongoengine\queryset\base.py", line 1669, in _cursor
    self._cursor_obj = self._collection.find(self._query, **self._cursor_args)
  File "C:\django-mongo\django-mongo\venv\lib\site-packages\mongoengine\queryset\base.py", line 1718, in _query
    self._mongo_query = self._query_obj.to_query(self._document)
  File "C:\django-mongo\django-mongo\venv\lib\site-packages\mongoengine\queryset\visitor.py", line 91, in to_query
    query = query.accept(QueryCompilerVisitor(document))
  File "C:\django-mongo\django-mongo\venv\lib\site-packages\mongoengine\queryset\visitor.py", line 184, in accept
    return visitor.visit_query(self)
  File "C:\django-mongo\django-mongo\venv\lib\site-packages\mongoengine\queryset\visitor.py", line 80, in visit_query
    return transform.query(self.document, **query.query)
  File "C:\django-mongo\django-mongo\venv\lib\site-packages\mongoengine\queryset\transform.py", line 97, in query
    raise InvalidQueryError(e)
mongoengine.errors.InvalidQueryError: Cannot resolve field "_id"
INFO:django.utils.autoreload:C:\django-mongo\django-mongo\EmployeeApp\middleware.py changed, reloading.
INFO:root:Document created successfully at Sun Feb  5 12:19:10 2023
INFO:root:Document created successfully at Sun Feb  5 12:19:10 2023
ERROR:django.request:Internal Server Error: /employee/28
Traceback (most recent call last):
  File "C:\django-mongo\django-mongo\venv\lib\site-packages\mongoengine\queryset\base.py", line 269, in get
    result = next(queryset)
  File "C:\django-mongo\django-mongo\venv\lib\site-packages\mongoengine\queryset\base.py", line 1596, in __next__
    raw_doc = next(self._cursor)
  File "C:\django-mongo\django-mongo\venv\lib\site-packages\pymongo\cursor.py", line 1251, in next
    raise StopIteration
StopIteration

During handling of the above exception, another exception occurred:

Traceback (most recent call last):
  File "C:\django-mongo\django-mongo\venv\lib\site-packages\django\core\handlers\exception.py", line 47, in inner
    response = get_response(request)
  File "C:\django-mongo\django-mongo\venv\lib\site-packages\django\core\handlers\base.py", line 181, in _get_response
    response = wrapped_callback(request, *callback_args, **callback_kwargs)
  File "C:\django-mongo\django-mongo\venv\lib\site-packages\django\views\decorators\csrf.py", line 54, in wrapped_view
    return view_func(*args, **kwargs)
  File "C:\django-mongo\django-mongo\venv\lib\site-packages\django\views\generic\base.py", line 70, in view
    return self.dispatch(request, *args, **kwargs)
  File "C:\django-mongo\django-mongo\venv\lib\site-packages\rest_framework\views.py", line 509, in dispatch
    response = self.handle_exception(exc)
  File "C:\django-mongo\django-mongo\venv\lib\site-packages\rest_framework\views.py", line 469, in handle_exception
    self.raise_uncaught_exception(exc)
  File "C:\django-mongo\django-mongo\venv\lib\site-packages\rest_framework\views.py", line 480, in raise_uncaught_exception
    raise exc
  File "C:\django-mongo\django-mongo\venv\lib\site-packages\rest_framework\views.py", line 497, in dispatch
    self.initial(request, *args, **kwargs)
  File "C:\django-mongo\django-mongo\venv\lib\site-packages\rest_framework\views.py", line 415, in initial
    self.check_permissions(request)
  File "C:\django-mongo\django-mongo\venv\lib\site-packages\rest_framework\views.py", line 332, in check_permissions
    if not permission.has_permission(request, self):
  File "C:\django-mongo\django-mongo\EmployeeApp\middleware.py", line 35, in has_permission
    email=email, password=password, pk=view.kwargs.get("pk")
  File "C:\django-mongo\django-mongo\venv\lib\site-packages\mongoengine\queryset\base.py", line 272, in get
    raise queryset._document.DoesNotExist(msg)
EmployeeApp.models.DoesNotExist: Employee matching query does not exist.
WARNING:django.request:Forbidden: /employee/29
INFO:django.utils.autoreload:C:\django-mongo\django-mongo\EmployeeApp\middleware.py changed, reloading.
INFO:root:Document created successfully at Sun Feb  5 12:19:36 2023
INFO:root:Document created successfully at Sun Feb  5 12:19:36 2023
WARNING:django.request:Forbidden: /employee/29
INFO:django.utils.autoreload:C:\django-mongo\django-mongo\EmployeeApp\middleware.py changed, reloading.
INFO:root:Document created successfully at Sun Feb  5 12:19:48 2023
INFO:root:Document created successfully at Sun Feb  5 12:19:48 2023
INFO:django.utils.autoreload:C:\django-mongo\django-mongo\EmployeeApp\middleware.py changed, reloading.
INFO:root:Document created successfully at Sun Feb  5 12:19:54 2023
INFO:root:Document created successfully at Sun Feb  5 12:19:55 2023
INFO:django.utils.autoreload:C:\django-mongo\django-mongo\EmployeeApp\middleware.py changed, reloading.
INFO:root:Document created successfully at Sun Feb  5 12:20:06 2023
INFO:root:Document created successfully at Sun Feb  5 12:20:06 2023
INFO:django.utils.autoreload:C:\django-mongo\django-mongo\EmployeeApp\middleware.py changed, reloading.
INFO:root:Document created successfully at Sun Feb  5 12:20:37 2023
INFO:root:Document created successfully at Sun Feb  5 12:20:37 2023
INFO:django.utils.autoreload:C:\django-mongo\django-mongo\EmployeeApp\middleware.py changed, reloading.
INFO:root:Document created successfully at Sun Feb  5 12:20:47 2023
INFO:root:Document created successfully at Sun Feb  5 12:20:47 2023
INFO:django.utils.autoreload:C:\django-mongo\django-mongo\EmployeeApp\middleware.py changed, reloading.
INFO:root:Document created successfully at Sun Feb  5 12:20:53 2023
INFO:root:Document created successfully at Sun Feb  5 12:20:53 2023
INFO:django.utils.autoreload:C:\django-mongo\django-mongo\EmployeeApp\middleware.py changed, reloading.
INFO:root:Document created successfully at Sun Feb  5 12:20:57 2023
INFO:root:Document created successfully at Sun Feb  5 12:20:57 2023
INFO:django.utils.autoreload:C:\django-mongo\django-mongo\EmployeeApp\middleware.py changed, reloading.
INFO:root:Document created successfully at Sun Feb  5 12:21:03 2023
INFO:root:Document created successfully at Sun Feb  5 12:21:03 2023
WARNING:django.request:Forbidden: /employee/29
INFO:django.utils.autoreload:C:\django-mongo\django-mongo\EmployeeApp\middleware.py changed, reloading.
INFO:root:Document created successfully at Sun Feb  5 12:21:28 2023
INFO:root:Document created successfully at Sun Feb  5 12:21:28 2023
WARNING:django.request:Forbidden: /employee/30
