INFO:root:Document created successfully at Fri Feb  3 10:25:09 2023
INFO:root:Document created successfully at Fri Feb  3 10:25:40 2023
WARNING:django.request:Method Not Allowed: /employees
ERROR:django.request:Internal Server Error: /employees
Traceback (most recent call last):
  File "C:\django-mongo\django-mongo\venv\lib\site-packages\django\core\handlers\exception.py", line 47, in inner
    response = get_response(request)
  File "C:\django-mongo\django-mongo\venv\lib\site-packages\django\core\handlers\base.py", line 181, in _get_response
    response = wrapped_callback(request, *callback_args, **callback_kwargs)
  File "C:\django-mongo\django-mongo\venv\lib\site-packages\django\views\decorators\csrf.py", line 54, in wrapped_view
    return view_func(*args, **kwargs)
  File "C:\django-mongo\django-mongo\venv\lib\site-packages\django\views\generic\base.py", line 70, in view
    return self.dispatch(request, *args, **kwargs)
  File "C:\django-mongo\django-mongo\venv\lib\site-packages\rest_framework\views.py", line 509, in dispatch
    response = self.handle_exception(exc)
  File "C:\django-mongo\django-mongo\venv\lib\site-packages\rest_framework\views.py", line 469, in handle_exception
    self.raise_uncaught_exception(exc)
  File "C:\django-mongo\django-mongo\venv\lib\site-packages\rest_framework\views.py", line 480, in raise_uncaught_exception
    raise exc
  File "C:\django-mongo\django-mongo\venv\lib\site-packages\rest_framework\views.py", line 506, in dispatch
    response = handler(request, *args, **kwargs)
  File "C:\django-mongo\django-mongo\venv\lib\site-packages\rest_framework\generics.py", line 199, in get
    return self.list(request, *args, **kwargs)
  File "C:\django-mongo\django-mongo\venv\lib\site-packages\rest_framework\mixins.py", line 46, in list
    return Response(serializer.data)
  File "C:\django-mongo\django-mongo\venv\lib\site-packages\rest_framework\serializers.py", line 768, in data
    ret = super().data
  File "C:\django-mongo\django-mongo\venv\lib\site-packages\rest_framework\serializers.py", line 253, in data
    self._data = self.to_representation(self.instance)
  File "C:\django-mongo\django-mongo\venv\lib\site-packages\rest_framework\serializers.py", line 687, in to_representation
    self.child.to_representation(item) for item in iterable
  File "C:\django-mongo\django-mongo\venv\lib\site-packages\rest_framework\serializers.py", line 687, in <listcomp>
    self.child.to_representation(item) for item in iterable
  File "C:\django-mongo\django-mongo\venv\lib\site-packages\mongoengine\queryset\queryset.py", line 110, in _iter_results
    self._populate_cache()
  File "C:\django-mongo\django-mongo\venv\lib\site-packages\mongoengine\queryset\queryset.py", line 129, in _populate_cache
    self._result_cache.append(next(self))
  File "C:\django-mongo\django-mongo\venv\lib\site-packages\mongoengine\queryset\base.py", line 1596, in __next__
    raw_doc = next(self._cursor)
  File "C:\django-mongo\django-mongo\venv\lib\site-packages\pymongo\cursor.py", line 1248, in next
    if len(self.__data) or self._refresh():
  File "C:\django-mongo\django-mongo\venv\lib\site-packages\pymongo\cursor.py", line 1139, in _refresh
    self.__session = self.__collection.database.client._ensure_session()
  File "C:\django-mongo\django-mongo\venv\lib\site-packages\pymongo\mongo_client.py", line 1740, in _ensure_session
    return self.__start_session(True, causal_consistency=False)
  File "C:\django-mongo\django-mongo\venv\lib\site-packages\pymongo\mongo_client.py", line 1685, in __start_session
    self._topology._check_implicit_session_support()
  File "C:\django-mongo\django-mongo\venv\lib\site-packages\pymongo\topology.py", line 538, in _check_implicit_session_support
    self._check_session_support()
  File "C:\django-mongo\django-mongo\venv\lib\site-packages\pymongo\topology.py", line 555, in _check_session_support
    readable_server_selector, self.get_server_selection_timeout(), None
  File "C:\django-mongo\django-mongo\venv\lib\site-packages\pymongo\topology.py", line 240, in _select_servers_loop
    % (self._error_message(selector), timeout, self.description)
pymongo.errors.ServerSelectionTimeoutError: ac-rrztoow-shard-00-00.fnt89sj.mongodb.net:27017: timed out,ac-rrztoow-shard-00-02.fnt89sj.mongodb.net:27017: timed out,ac-rrztoow-shard-00-01.fnt89sj.mongodb.net:27017: timed out, Timeout: 30s, Topology Description: <TopologyDescription id: 63dc93ac09f618727ba19d95, topology_type: ReplicaSetNoPrimary, servers: [<ServerDescription ('ac-rrztoow-shard-00-00.fnt89sj.mongodb.net', 27017) server_type: Unknown, rtt: None, error=NetworkTimeout('ac-rrztoow-shard-00-00.fnt89sj.mongodb.net:27017: timed out')>, <ServerDescription ('ac-rrztoow-shard-00-01.fnt89sj.mongodb.net', 27017) server_type: Unknown, rtt: None, error=NetworkTimeout('ac-rrztoow-shard-00-01.fnt89sj.mongodb.net:27017: timed out')>, <ServerDescription ('ac-rrztoow-shard-00-02.fnt89sj.mongodb.net', 27017) server_type: Unknown, rtt: None, error=NetworkTimeout('ac-rrztoow-shard-00-02.fnt89sj.mongodb.net:27017: timed out')>]>
INFO:root:Document created successfully at Fri Feb  3 10:41:48 2023
INFO:root:Document created successfully at Fri Feb  3 10:42:19 2023
ERROR:django.request:Internal Server Error: /employees
Traceback (most recent call last):
  File "C:\django-mongo\django-mongo\venv\lib\site-packages\django\core\handlers\exception.py", line 47, in inner
    response = get_response(request)
  File "C:\django-mongo\django-mongo\venv\lib\site-packages\django\core\handlers\base.py", line 181, in _get_response
    response = wrapped_callback(request, *callback_args, **callback_kwargs)
  File "C:\django-mongo\django-mongo\venv\lib\site-packages\django\views\decorators\csrf.py", line 54, in wrapped_view
    return view_func(*args, **kwargs)
  File "C:\django-mongo\django-mongo\venv\lib\site-packages\django\views\generic\base.py", line 70, in view
    return self.dispatch(request, *args, **kwargs)
  File "C:\django-mongo\django-mongo\venv\lib\site-packages\rest_framework\views.py", line 509, in dispatch
    response = self.handle_exception(exc)
  File "C:\django-mongo\django-mongo\venv\lib\site-packages\rest_framework\views.py", line 469, in handle_exception
    self.raise_uncaught_exception(exc)
  File "C:\django-mongo\django-mongo\venv\lib\site-packages\rest_framework\views.py", line 480, in raise_uncaught_exception
    raise exc
  File "C:\django-mongo\django-mongo\venv\lib\site-packages\rest_framework\views.py", line 506, in dispatch
    response = handler(request, *args, **kwargs)
  File "C:\django-mongo\django-mongo\venv\lib\site-packages\rest_framework_mongoengine\generics.py", line 71, in get
    return self.list(request, *args, **kwargs)
  File "C:\django-mongo\django-mongo\venv\lib\site-packages\rest_framework\mixins.py", line 38, in list
    queryset = self.filter_queryset(self.get_queryset())
  File "C:\django-mongo\django-mongo\EmployeeApp\views.py", line 48, in get_queryset
    queryset = Employee.objects.filter(**filtering_kwargs)
TypeError: filter() keywords must be strings
INFO:django.utils.autoreload:C:\django-mongo\django-mongo\EmployeeApp\views.py changed, reloading.
INFO:root:Document created successfully at Fri Feb  3 10:44:21 2023
INFO:root:Document created successfully at Fri Feb  3 10:44:52 2023
ERROR:django.request:Internal Server Error: /employees
Traceback (most recent call last):
  File "C:\django-mongo\django-mongo\venv\lib\site-packages\django\core\handlers\exception.py", line 47, in inner
    response = get_response(request)
  File "C:\django-mongo\django-mongo\venv\lib\site-packages\django\core\handlers\base.py", line 181, in _get_response
    response = wrapped_callback(request, *callback_args, **callback_kwargs)
  File "C:\django-mongo\django-mongo\venv\lib\site-packages\django\views\decorators\csrf.py", line 54, in wrapped_view
    return view_func(*args, **kwargs)
  File "C:\django-mongo\django-mongo\venv\lib\site-packages\django\views\generic\base.py", line 70, in view
    return self.dispatch(request, *args, **kwargs)
  File "C:\django-mongo\django-mongo\venv\lib\site-packages\rest_framework\views.py", line 509, in dispatch
    response = self.handle_exception(exc)
  File "C:\django-mongo\django-mongo\venv\lib\site-packages\rest_framework\views.py", line 469, in handle_exception
    self.raise_uncaught_exception(exc)
  File "C:\django-mongo\django-mongo\venv\lib\site-packages\rest_framework\views.py", line 480, in raise_uncaught_exception
    raise exc
  File "C:\django-mongo\django-mongo\venv\lib\site-packages\rest_framework\views.py", line 506, in dispatch
    response = handler(request, *args, **kwargs)
  File "C:\django-mongo\django-mongo\venv\lib\site-packages\rest_framework_mongoengine\generics.py", line 71, in get
    return self.list(request, *args, **kwargs)
  File "C:\django-mongo\django-mongo\venv\lib\site-packages\rest_framework\mixins.py", line 46, in list
    return Response(serializer.data)
  File "C:\django-mongo\django-mongo\venv\lib\site-packages\rest_framework\serializers.py", line 768, in data
    ret = super().data
  File "C:\django-mongo\django-mongo\venv\lib\site-packages\rest_framework\serializers.py", line 253, in data
    self._data = self.to_representation(self.instance)
  File "C:\django-mongo\django-mongo\venv\lib\site-packages\rest_framework\serializers.py", line 687, in to_representation
    self.child.to_representation(item) for item in iterable
  File "C:\django-mongo\django-mongo\venv\lib\site-packages\rest_framework\serializers.py", line 687, in <listcomp>
    self.child.to_representation(item) for item in iterable
  File "C:\django-mongo\django-mongo\venv\lib\site-packages\mongoengine\queryset\queryset.py", line 110, in _iter_results
    self._populate_cache()
  File "C:\django-mongo\django-mongo\venv\lib\site-packages\mongoengine\queryset\queryset.py", line 129, in _populate_cache
    self._result_cache.append(next(self))
  File "C:\django-mongo\django-mongo\venv\lib\site-packages\mongoengine\queryset\base.py", line 1596, in __next__
    raw_doc = next(self._cursor)
  File "C:\django-mongo\django-mongo\venv\lib\site-packages\pymongo\cursor.py", line 1248, in next
    if len(self.__data) or self._refresh():
  File "C:\django-mongo\django-mongo\venv\lib\site-packages\pymongo\cursor.py", line 1139, in _refresh
    self.__session = self.__collection.database.client._ensure_session()
  File "C:\django-mongo\django-mongo\venv\lib\site-packages\pymongo\mongo_client.py", line 1740, in _ensure_session
    return self.__start_session(True, causal_consistency=False)
  File "C:\django-mongo\django-mongo\venv\lib\site-packages\pymongo\mongo_client.py", line 1685, in __start_session
    self._topology._check_implicit_session_support()
  File "C:\django-mongo\django-mongo\venv\lib\site-packages\pymongo\topology.py", line 538, in _check_implicit_session_support
    self._check_session_support()
  File "C:\django-mongo\django-mongo\venv\lib\site-packages\pymongo\topology.py", line 555, in _check_session_support
    readable_server_selector, self.get_server_selection_timeout(), None
  File "C:\django-mongo\django-mongo\venv\lib\site-packages\pymongo\topology.py", line 240, in _select_servers_loop
    % (self._error_message(selector), timeout, self.description)
pymongo.errors.ServerSelectionTimeoutError: ac-rrztoow-shard-00-01.fnt89sj.mongodb.net:27017: timed out,ac-rrztoow-shard-00-02.fnt89sj.mongodb.net:27017: timed out,ac-rrztoow-shard-00-00.fnt89sj.mongodb.net:27017: timed out, Timeout: 30s, Topology Description: <TopologyDescription id: 63dc982b4fa8f3e6e1cb26b1, topology_type: ReplicaSetNoPrimary, servers: [<ServerDescription ('ac-rrztoow-shard-00-00.fnt89sj.mongodb.net', 27017) server_type: Unknown, rtt: None, error=NetworkTimeout('ac-rrztoow-shard-00-00.fnt89sj.mongodb.net:27017: timed out')>, <ServerDescription ('ac-rrztoow-shard-00-01.fnt89sj.mongodb.net', 27017) server_type: Unknown, rtt: None, error=NetworkTimeout('ac-rrztoow-shard-00-01.fnt89sj.mongodb.net:27017: timed out')>, <ServerDescription ('ac-rrztoow-shard-00-02.fnt89sj.mongodb.net', 27017) server_type: Unknown, rtt: None, error=NetworkTimeout('ac-rrztoow-shard-00-02.fnt89sj.mongodb.net:27017: timed out')>]>
INFO:django.utils.autoreload:C:\django-mongo\django-mongo\EmployeeApp\models.py changed, reloading.
INFO:root:Document created successfully at Fri Feb  3 10:49:26 2023
INFO:root:Document created successfully at Fri Feb  3 10:49:56 2023
WARNING:django.request:Not Found: /employee/register
ERROR:django.request:Internal Server Error: /register
Traceback (most recent call last):
  File "C:\django-mongo\django-mongo\venv\lib\site-packages\django\core\handlers\exception.py", line 47, in inner
    response = get_response(request)
  File "C:\django-mongo\django-mongo\venv\lib\site-packages\django\core\handlers\base.py", line 181, in _get_response
    response = wrapped_callback(request, *callback_args, **callback_kwargs)
  File "C:\django-mongo\django-mongo\venv\lib\site-packages\django\views\decorators\csrf.py", line 54, in wrapped_view
    return view_func(*args, **kwargs)
  File "C:\django-mongo\django-mongo\venv\lib\site-packages\django\views\generic\base.py", line 70, in view
    return self.dispatch(request, *args, **kwargs)
  File "C:\django-mongo\django-mongo\venv\lib\site-packages\rest_framework\views.py", line 509, in dispatch
    response = self.handle_exception(exc)
  File "C:\django-mongo\django-mongo\venv\lib\site-packages\rest_framework\views.py", line 469, in handle_exception
    self.raise_uncaught_exception(exc)
  File "C:\django-mongo\django-mongo\venv\lib\site-packages\rest_framework\views.py", line 480, in raise_uncaught_exception
    raise exc
  File "C:\django-mongo\django-mongo\venv\lib\site-packages\rest_framework\views.py", line 506, in dispatch
    response = handler(request, *args, **kwargs)
  File "C:\django-mongo\django-mongo\venv\lib\site-packages\rest_framework_mongoengine\generics.py", line 56, in post
    return self.create(request, *args, **kwargs)
  File "C:\django-mongo\django-mongo\venv\lib\site-packages\rest_framework\mixins.py", line 19, in create
    self.perform_create(serializer)
  File "C:\django-mongo\django-mongo\venv\lib\site-packages\rest_framework\mixins.py", line 24, in perform_create
    serializer.save()
  File "C:\django-mongo\django-mongo\venv\lib\site-packages\rest_framework\serializers.py", line 212, in save
    self.instance = self.create(validated_data)
  File "C:\django-mongo\django-mongo\venv\lib\site-packages\rest_framework_mongoengine\serializers.py", line 162, in create
    instance = self.recursive_save(validated_data)
  File "C:\django-mongo\django-mongo\venv\lib\site-packages\rest_framework_mongoengine\serializers.py", line 262, in recursive_save
    instance.save()
  File "C:\django-mongo\django-mongo\venv\lib\site-packages\mongoengine\document.py", line 411, in save
    doc = self.to_mongo()
  File "C:\django-mongo\django-mongo\venv\lib\site-packages\mongoengine\document.py", line 275, in to_mongo
    data = super().to_mongo(*args, **kwargs)
  File "C:\django-mongo\django-mongo\venv\lib\site-packages\mongoengine\base\document.py", line 372, in to_mongo
    value = field.generate()
  File "C:\django-mongo\django-mongo\venv\lib\site-packages\mongoengine\fields.py", line 2163, in generate
    upsert=True,
  File "C:\django-mongo\django-mongo\venv\lib\site-packages\pymongo\collection.py", line 3193, in find_one_and_update
    **kwargs,
  File "C:\django-mongo\django-mongo\venv\lib\site-packages\pymongo\collection.py", line 2845, in __find_and_modify
    write_concern.acknowledged, _find_and_modify, session
  File "C:\django-mongo\django-mongo\venv\lib\site-packages\pymongo\mongo_client.py", line 1475, in _retryable_write
    with self._tmp_session(session) as s:
  File "C:\Program Files\WindowsApps\PythonSoftwareFoundation.Python.3.7_3.7.2544.0_x64__qbz5n2kfra8p0\lib\contextlib.py", line 112, in __enter__
    return next(self.gen)
  File "C:\django-mongo\django-mongo\venv\lib\site-packages\pymongo\mongo_client.py", line 1757, in _tmp_session
    s = self._ensure_session(session)
  File "C:\django-mongo\django-mongo\venv\lib\site-packages\pymongo\mongo_client.py", line 1740, in _ensure_session
    return self.__start_session(True, causal_consistency=False)
  File "C:\django-mongo\django-mongo\venv\lib\site-packages\pymongo\mongo_client.py", line 1685, in __start_session
    self._topology._check_implicit_session_support()
  File "C:\django-mongo\django-mongo\venv\lib\site-packages\pymongo\topology.py", line 538, in _check_implicit_session_support
    self._check_session_support()
  File "C:\django-mongo\django-mongo\venv\lib\site-packages\pymongo\topology.py", line 555, in _check_session_support
    readable_server_selector, self.get_server_selection_timeout(), None
  File "C:\django-mongo\django-mongo\venv\lib\site-packages\pymongo\topology.py", line 240, in _select_servers_loop
    % (self._error_message(selector), timeout, self.description)
pymongo.errors.ServerSelectionTimeoutError: ac-rrztoow-shard-00-00.fnt89sj.mongodb.net:27017: timed out,ac-rrztoow-shard-00-02.fnt89sj.mongodb.net:27017: timed out,ac-rrztoow-shard-00-01.fnt89sj.mongodb.net:27017: timed out, Timeout: 30s, Topology Description: <TopologyDescription id: 63dc995d47212513f8547da3, topology_type: ReplicaSetNoPrimary, servers: [<ServerDescription ('ac-rrztoow-shard-00-00.fnt89sj.mongodb.net', 27017) server_type: Unknown, rtt: None, error=NetworkTimeout('ac-rrztoow-shard-00-00.fnt89sj.mongodb.net:27017: timed out')>, <ServerDescription ('ac-rrztoow-shard-00-01.fnt89sj.mongodb.net', 27017) server_type: Unknown, rtt: None, error=NetworkTimeout('ac-rrztoow-shard-00-01.fnt89sj.mongodb.net:27017: timed out')>, <ServerDescription ('ac-rrztoow-shard-00-02.fnt89sj.mongodb.net', 27017) server_type: Unknown, rtt: None, error=NetworkTimeout('ac-rrztoow-shard-00-02.fnt89sj.mongodb.net:27017: timed out')>]>
INFO:root:Document created successfully at Fri Feb  3 12:03:58 2023
ERROR:django.request:Internal Server Error: /register
Traceback (most recent call last):
  File "C:\django-mongo\django-mongo\venv\lib\site-packages\django\core\handlers\exception.py", line 47, in inner
    response = get_response(request)
  File "C:\django-mongo\django-mongo\venv\lib\site-packages\django\core\handlers\base.py", line 204, in _get_response
    response = response.render()
  File "C:\django-mongo\django-mongo\venv\lib\site-packages\django\template\response.py", line 105, in render
    self.content = self.rendered_content
  File "C:\django-mongo\django-mongo\venv\lib\site-packages\rest_framework\response.py", line 70, in rendered_content
    ret = renderer.render(self.data, accepted_media_type, context)
  File "C:\django-mongo\django-mongo\venv\lib\site-packages\rest_framework\renderers.py", line 102, in render
    allow_nan=not self.strict, separators=separators
  File "C:\django-mongo\django-mongo\venv\lib\site-packages\rest_framework\utils\json.py", line 25, in dumps
    return json.dumps(*args, **kwargs)
  File "C:\Program Files\WindowsApps\PythonSoftwareFoundation.Python.3.7_3.7.2544.0_x64__qbz5n2kfra8p0\lib\json\__init__.py", line 238, in dumps
    **kw).encode(obj)
  File "C:\Program Files\WindowsApps\PythonSoftwareFoundation.Python.3.7_3.7.2544.0_x64__qbz5n2kfra8p0\lib\json\encoder.py", line 199, in encode
    chunks = self.iterencode(o, _one_shot=True)
  File "C:\Program Files\WindowsApps\PythonSoftwareFoundation.Python.3.7_3.7.2544.0_x64__qbz5n2kfra8p0\lib\json\encoder.py", line 257, in iterencode
    return _iterencode(o, 0)
  File "C:\django-mongo\django-mongo\venv\lib\site-packages\rest_framework\utils\encoders.py", line 67, in default
    return super().default(obj)
  File "C:\Program Files\WindowsApps\PythonSoftwareFoundation.Python.3.7_3.7.2544.0_x64__qbz5n2kfra8p0\lib\json\encoder.py", line 179, in default
    raise TypeError(f'Object of type {o.__class__.__name__} '
TypeError: Object of type GenderEnums is not JSON serializable
INFO:django.utils.autoreload:C:\django-mongo\django-mongo\EmployeeApp\models.py changed, reloading.
INFO:root:Document created successfully at Fri Feb  3 12:05:31 2023
WARNING:django.request:Bad Request: /register
WARNING:django.request:Bad Request: /register
INFO:django.utils.autoreload:C:\django-mongo\django-mongo\EmployeeApp\models.py changed, reloading.
INFO:root:Document created successfully at Fri Feb  3 12:07:28 2023
INFO:django.utils.autoreload:C:\django-mongo\django-mongo\EmployeeApp\models.py changed, reloading.
INFO:root:Document created successfully at Fri Feb  3 12:07:40 2023
WARNING:django.request:Bad Request: /register
WARNING:django.request:Bad Request: /register
INFO:django.utils.autoreload:C:\django-mongo\django-mongo\EmployeeApp\models.py changed, reloading.
INFO:root:Document created successfully at Fri Feb  3 12:09:23 2023
INFO:django.utils.autoreload:C:\django-mongo\django-mongo\EmployeeApp\models.py changed, reloading.
INFO:root:Document created successfully at Fri Feb  3 12:10:20 2023
INFO:django.utils.autoreload:C:\django-mongo\django-mongo\EmployeeApp\models.py changed, reloading.
INFO:root:Document created successfully at Fri Feb  3 12:12:01 2023
INFO:django.utils.autoreload:C:\django-mongo\django-mongo\EmployeeApp\models.py changed, reloading.
INFO:root:Document created successfully at Fri Feb  3 12:12:30 2023
WARNING:django.request:Bad Request: /register
INFO:django.utils.autoreload:C:\django-mongo\django-mongo\EmployeeApp\models.py changed, reloading.
INFO:root:Document created successfully at Fri Feb  3 12:15:00 2023
INFO:django.utils.autoreload:C:\django-mongo\django-mongo\EmployeeApp\models.py changed, reloading.
INFO:root:Document created successfully at Fri Feb  3 12:15:54 2023
INFO:django.utils.autoreload:C:\django-mongo\django-mongo\EmployeeApp\models.py changed, reloading.
INFO:root:Document created successfully at Fri Feb  3 12:24:21 2023
WARNING:django.request:Bad Request: /register
WARNING:django.request:Bad Request: /register
INFO:django.utils.autoreload:C:\django-mongo\django-mongo\EmployeeApp\models.py changed, reloading.
INFO:root:Document created successfully at Fri Feb  3 12:38:27 2023
WARNING:django.request:Bad Request: /register
INFO:root:Document created successfully at Fri Feb  3 12:44:06 2023
INFO:django.utils.autoreload:C:\django-mongo\django-mongo\EmployeeApp\models.py changed, reloading.
INFO:root:Document created successfully at Fri Feb  3 12:44:26 2023
INFO:django.utils.autoreload:C:\django-mongo\django-mongo\EmployeeApp\models.py changed, reloading.
INFO:root:Document created successfully at Fri Feb  3 12:47:34 2023
ERROR:django.request:Internal Server Error: /register
Traceback (most recent call last):
  File "C:\django-mongo\django-mongo\venv\lib\site-packages\django\core\handlers\exception.py", line 47, in inner
    response = get_response(request)
  File "C:\django-mongo\django-mongo\venv\lib\site-packages\django\core\handlers\base.py", line 181, in _get_response
    response = wrapped_callback(request, *callback_args, **callback_kwargs)
  File "C:\django-mongo\django-mongo\venv\lib\site-packages\django\views\decorators\csrf.py", line 54, in wrapped_view
    return view_func(*args, **kwargs)
  File "C:\django-mongo\django-mongo\venv\lib\site-packages\django\views\generic\base.py", line 70, in view
    return self.dispatch(request, *args, **kwargs)
  File "C:\django-mongo\django-mongo\venv\lib\site-packages\rest_framework\views.py", line 509, in dispatch
    response = self.handle_exception(exc)
  File "C:\django-mongo\django-mongo\venv\lib\site-packages\rest_framework\views.py", line 469, in handle_exception
    self.raise_uncaught_exception(exc)
  File "C:\django-mongo\django-mongo\venv\lib\site-packages\rest_framework\views.py", line 480, in raise_uncaught_exception
    raise exc
  File "C:\django-mongo\django-mongo\venv\lib\site-packages\rest_framework\views.py", line 506, in dispatch
    response = handler(request, *args, **kwargs)
  File "C:\django-mongo\django-mongo\venv\lib\site-packages\rest_framework_mongoengine\generics.py", line 56, in post
    return self.create(request, *args, **kwargs)
  File "C:\django-mongo\django-mongo\venv\lib\site-packages\rest_framework\mixins.py", line 19, in create
    self.perform_create(serializer)
  File "C:\django-mongo\django-mongo\venv\lib\site-packages\rest_framework\mixins.py", line 24, in perform_create
    serializer.save()
  File "C:\django-mongo\django-mongo\venv\lib\site-packages\rest_framework\serializers.py", line 212, in save
    self.instance = self.create(validated_data)
  File "C:\django-mongo\django-mongo\venv\lib\site-packages\rest_framework_mongoengine\serializers.py", line 162, in create
    instance = self.recursive_save(validated_data)
  File "C:\django-mongo\django-mongo\venv\lib\site-packages\rest_framework_mongoengine\serializers.py", line 262, in recursive_save
    instance.save()
  File "C:\django-mongo\django-mongo\venv\lib\site-packages\mongoengine\document.py", line 399, in save
    self.validate(clean=clean)
  File "C:\django-mongo\django-mongo\venv\lib\site-packages\mongoengine\base\document.py", line 398, in validate
    self.clean()
  File "C:\django-mongo\django-mongo\EmployeeApp\models.py", line 29, in clean
    raise ValidationError("Age cannot be under 18")
django.core.exceptions.ValidationError: ['Age cannot be under 18']
INFO:django.utils.autoreload:C:\django-mongo\django-mongo\EmployeeApp\models.py changed, reloading.
INFO:root:Document created successfully at Fri Feb  3 12:49:04 2023
WARNING:django.request:Bad Request: /register
WARNING:django.request:Bad Request: /register
INFO:root:Document created successfully at Fri Feb  3 12:55:54 2023
ERROR:django.request:Internal Server Error: /register
Traceback (most recent call last):
  File "C:\django-mongo\django-mongo\venv\lib\site-packages\django\core\handlers\exception.py", line 47, in inner
    response = get_response(request)
  File "C:\django-mongo\django-mongo\venv\lib\site-packages\django\core\handlers\base.py", line 181, in _get_response
    response = wrapped_callback(request, *callback_args, **callback_kwargs)
  File "C:\django-mongo\django-mongo\venv\lib\site-packages\django\views\decorators\csrf.py", line 54, in wrapped_view
    return view_func(*args, **kwargs)
  File "C:\django-mongo\django-mongo\venv\lib\site-packages\django\views\generic\base.py", line 70, in view
    return self.dispatch(request, *args, **kwargs)
  File "C:\django-mongo\django-mongo\venv\lib\site-packages\rest_framework\views.py", line 509, in dispatch
    response = self.handle_exception(exc)
  File "C:\django-mongo\django-mongo\venv\lib\site-packages\rest_framework\views.py", line 469, in handle_exception
    self.raise_uncaught_exception(exc)
  File "C:\django-mongo\django-mongo\venv\lib\site-packages\rest_framework\views.py", line 480, in raise_uncaught_exception
    raise exc
  File "C:\django-mongo\django-mongo\venv\lib\site-packages\rest_framework\views.py", line 506, in dispatch
    response = handler(request, *args, **kwargs)
  File "C:\django-mongo\django-mongo\venv\lib\site-packages\rest_framework_mongoengine\generics.py", line 56, in post
    return self.create(request, *args, **kwargs)
  File "C:\django-mongo\django-mongo\venv\lib\site-packages\rest_framework\mixins.py", line 19, in create
    self.perform_create(serializer)
  File "C:\django-mongo\django-mongo\venv\lib\site-packages\rest_framework\mixins.py", line 24, in perform_create
    serializer.save()
  File "C:\django-mongo\django-mongo\venv\lib\site-packages\rest_framework\serializers.py", line 212, in save
    self.instance = self.create(validated_data)
  File "C:\django-mongo\django-mongo\venv\lib\site-packages\rest_framework_mongoengine\serializers.py", line 162, in create
    instance = self.recursive_save(validated_data)
  File "C:\django-mongo\django-mongo\venv\lib\site-packages\rest_framework_mongoengine\serializers.py", line 262, in recursive_save
    instance.save()
  File "C:\django-mongo\django-mongo\venv\lib\site-packages\mongoengine\document.py", line 399, in save
    self.validate(clean=clean)
  File "C:\django-mongo\django-mongo\venv\lib\site-packages\mongoengine\base\document.py", line 398, in validate
    self.clean()
  File "C:\django-mongo\django-mongo\EmployeeApp\models.py", line 25, in clean
    raise ValidationError("For male employees, age should be under 31")
django.core.exceptions.ValidationError: ['For male employees, age should be under 31']
INFO:root:Document created successfully at Fri Feb  3 13:03:52 2023
WARNING:django.request:Bad Request: /register
WARNING:django.request:Bad Request: /register
INFO:root:Document created successfully at Fri Feb  3 13:13:18 2023
WARNING:django.request:Bad Request: /register
INFO:root:Document created successfully at Fri Feb  3 13:26:46 2023
WARNING:django.request:Bad Request: /register
WARNING:django.request:Bad Request: /register
INFO:root:Document created successfully at Fri Feb  3 13:30:11 2023
INFO:django.utils.autoreload:C:\django-mongo\django-mongo\EmployeeApp\models.py changed, reloading.
INFO:root:Document created successfully at Fri Feb  3 13:30:58 2023
INFO:django.utils.autoreload:C:\django-mongo\django-mongo\EmployeeApp\models.py changed, reloading.
INFO:root:Document created successfully at Fri Feb  3 13:32:22 2023
WARNING:django.request:Bad Request: /register
INFO:root:Document created successfully at Fri Feb  3 13:33:03 2023
WARNING:django.request:Bad Request: /register
INFO:root:Document created successfully at Fri Feb  3 13:33:59 2023
INFO:django.utils.autoreload:C:\django-mongo\django-mongo\EmployeeApp\models.py changed, reloading.
INFO:root:Document created successfully at Fri Feb  3 13:34:05 2023
INFO:django.utils.autoreload:C:\django-mongo\django-mongo\EmployeeApp\models.py changed, reloading.
INFO:root:Document created successfully at Fri Feb  3 13:34:16 2023
INFO:django.utils.autoreload:C:\django-mongo\django-mongo\EmployeeApp\models.py changed, reloading.
INFO:root:Document created successfully at Fri Feb  3 13:34:25 2023
INFO:django.utils.autoreload:C:\django-mongo\django-mongo\EmployeeApp\models.py changed, reloading.
INFO:root:Document created successfully at Fri Feb  3 13:34:49 2023
INFO:django.utils.autoreload:C:\django-mongo\django-mongo\EmployeeApp\models.py changed, reloading.
INFO:root:Document created successfully at Fri Feb  3 13:35:24 2023
INFO:django.utils.autoreload:C:\django-mongo\django-mongo\EmployeeApp\models.py changed, reloading.
INFO:root:Document created successfully at Fri Feb  3 13:35:28 2023
ERROR:django.request:Internal Server Error: /register
Traceback (most recent call last):
  File "C:\django-mongo\django-mongo\venv\lib\site-packages\django\core\handlers\exception.py", line 47, in inner
    response = get_response(request)
  File "C:\django-mongo\django-mongo\venv\lib\site-packages\django\core\handlers\base.py", line 181, in _get_response
    response = wrapped_callback(request, *callback_args, **callback_kwargs)
  File "C:\django-mongo\django-mongo\venv\lib\site-packages\django\views\decorators\csrf.py", line 54, in wrapped_view
    return view_func(*args, **kwargs)
  File "C:\django-mongo\django-mongo\venv\lib\site-packages\django\views\generic\base.py", line 70, in view
    return self.dispatch(request, *args, **kwargs)
  File "C:\django-mongo\django-mongo\venv\lib\site-packages\rest_framework\views.py", line 509, in dispatch
    response = self.handle_exception(exc)
  File "C:\django-mongo\django-mongo\venv\lib\site-packages\rest_framework\views.py", line 469, in handle_exception
    self.raise_uncaught_exception(exc)
  File "C:\django-mongo\django-mongo\venv\lib\site-packages\rest_framework\views.py", line 480, in raise_uncaught_exception
    raise exc
  File "C:\django-mongo\django-mongo\venv\lib\site-packages\rest_framework\views.py", line 506, in dispatch
    response = handler(request, *args, **kwargs)
  File "C:\django-mongo\django-mongo\venv\lib\site-packages\rest_framework_mongoengine\generics.py", line 56, in post
    return self.create(request, *args, **kwargs)
  File "C:\django-mongo\django-mongo\venv\lib\site-packages\rest_framework\mixins.py", line 19, in create
    self.perform_create(serializer)
  File "C:\django-mongo\django-mongo\venv\lib\site-packages\rest_framework\mixins.py", line 24, in perform_create
    serializer.save()
  File "C:\django-mongo\django-mongo\venv\lib\site-packages\rest_framework\serializers.py", line 212, in save
    self.instance = self.create(validated_data)
  File "C:\django-mongo\django-mongo\venv\lib\site-packages\rest_framework_mongoengine\serializers.py", line 162, in create
    instance = self.recursive_save(validated_data)
  File "C:\django-mongo\django-mongo\venv\lib\site-packages\rest_framework_mongoengine\serializers.py", line 262, in recursive_save
    instance.save()
  File "C:\django-mongo\django-mongo\venv\lib\site-packages\mongoengine\document.py", line 399, in save
    self.validate(clean=clean)
  File "C:\django-mongo\django-mongo\venv\lib\site-packages\mongoengine\base\document.py", line 398, in validate
    self.clean()
  File "C:\django-mongo\django-mongo\EmployeeApp\models.py", line 24, in clean
    raise ValidationError("For male employees, age should be under 31")
django.core.exceptions.ValidationError: ['For male employees, age should be under 31']
INFO:root:Document created successfully at Fri Feb  3 14:29:04 2023
