INFO:root:Document created successfully at Sun Feb  5 12:26:33 2023
INFO:root:Document created successfully at Sun Feb  5 12:26:33 2023
INFO:django.utils.autoreload:C:\django-mongo\django-mongo\EmployeeApp\middleware.py changed, reloading.
INFO:root:Document created successfully at Sun Feb  5 12:28:27 2023
INFO:root:Document created successfully at Sun Feb  5 12:28:27 2023
INFO:django.utils.autoreload:C:\django-mongo\django-mongo\EmployeeApp\middleware.py changed, reloading.
INFO:root:Document created successfully at Sun Feb  5 12:28:34 2023
INFO:root:Document created successfully at Sun Feb  5 12:28:34 2023
INFO:root:Started request: GET /employee/30
INFO:root:Finished request: GET /employee/30 with status 403
WARNING:django.request:Forbidden: /employee/30
INFO:root:Started request: GET /employee/29
INFO:root:Finished request: GET /employee/29 with status 200
INFO:root:Document created successfully at Sun Feb  5 12:46:09 2023
INFO:root:Document created successfully at Sun Feb  5 12:46:09 2023
INFO:root:Started request: POST /register
INFO:root:Finished request: POST /register with status 400
WARNING:django.request:Bad Request: /register
INFO:root:Started request: POST /register
INFO:root:Finished request: POST /register with status 400
WARNING:django.request:Bad Request: /register
INFO:root:Started request: POST /register
INFO:root:Finished request: POST /register with status 400
WARNING:django.request:Bad Request: /register
INFO:root:Started request: POST /register
INFO:root:Finished request: POST /register with status 400
WARNING:django.request:Bad Request: /register
INFO:root:Started request: POST /register
INFO:root:Finished request: POST /register with status 400
WARNING:django.request:Bad Request: /register
INFO:root:Started request: POST /register
INFO:root:Finished request: POST /register with status 400
WARNING:django.request:Bad Request: /register
INFO:root:Started request: POST /register
INFO:root:Finished request: POST /register with status 400
WARNING:django.request:Bad Request: /register
INFO:root:Started request: POST /register
INFO:root:Finished request: POST /register with status 400
WARNING:django.request:Bad Request: /register
INFO:root:Started request: POST /register
INFO:root:Finished request: POST /register with status 400
WARNING:django.request:Bad Request: /register
INFO:root:Started request: POST /register
INFO:root:Finished request: POST /register with status 400
WARNING:django.request:Bad Request: /register
INFO:root:Started request: POST /register
INFO:root:Finished request: POST /register with status 400
WARNING:django.request:Bad Request: /register
INFO:root:Started request: POST /register
INFO:root:Finished request: POST /register with status 400
WARNING:django.request:Bad Request: /register
INFO:root:Started request: POST /register
INFO:root:Finished request: POST /register with status 400
WARNING:django.request:Bad Request: /register
INFO:root:Started request: POST /register
INFO:root:Finished request: POST /register with status 400
WARNING:django.request:Bad Request: /register
INFO:root:Started request: POST /register
INFO:root:Finished request: POST /register with status 400
WARNING:django.request:Bad Request: /register
INFO:root:Started request: POST /register
INFO:root:Finished request: POST /register with status 400
WARNING:django.request:Bad Request: /register
INFO:root:Started request: POST /register
INFO:root:Finished request: POST /register with status 400
WARNING:django.request:Bad Request: /register
INFO:root:Started request: POST /register
INFO:root:Finished request: POST /register with status 400
WARNING:django.request:Bad Request: /register
INFO:root:Started request: POST /register
INFO:root:Finished request: POST /register with status 400
WARNING:django.request:Bad Request: /register
INFO:root:Started request: POST /register
INFO:root:Finished request: POST /register with status 400
WARNING:django.request:Bad Request: /register
INFO:root:Started request: POST /register
INFO:root:Finished request: POST /register with status 400
WARNING:django.request:Bad Request: /register
INFO:root:Started request: POST /register
INFO:root:Finished request: POST /register with status 400
WARNING:django.request:Bad Request: /register
INFO:root:Started request: POST /register
INFO:root:Finished request: POST /register with status 201
INFO:root:Started request: POST /register
INFO:root:Finished request: POST /register with status 400
WARNING:django.request:Bad Request: /register
INFO:root:Started request: POST /register
INFO:root:Finished request: POST /register with status 400
WARNING:django.request:Bad Request: /register
INFO:root:Started request: POST /register
INFO:root:Finished request: POST /register with status 400
WARNING:django.request:Bad Request: /register
INFO:root:Started request: POST /register
INFO:root:Finished request: POST /register with status 400
WARNING:django.request:Bad Request: /register
INFO:root:Started request: POST /register
INFO:root:Finished request: POST /register with status 201
INFO:root:Started request: POST /register
INFO:root:Finished request: POST /register with status 400
WARNING:django.request:Bad Request: /register
INFO:root:Started request: GET /employees
INFO:root:Finished request: GET /employees with status 403
WARNING:django.request:Forbidden: /employees
INFO:django.utils.autoreload:C:\django-mongo\django-mongo\EmployeeApp\middleware.py changed, reloading.
INFO:root:Document created successfully at Sun Feb  5 19:15:56 2023
INFO:root:Document created successfully at Sun Feb  5 19:15:56 2023
INFO:django.utils.autoreload:C:\django-mongo\django-mongo\EmployeeApp\middleware.py changed, reloading.
INFO:root:Document created successfully at Sun Feb  5 19:18:20 2023
INFO:root:Document created successfully at Sun Feb  5 19:18:21 2023
INFO:django.utils.autoreload:C:\django-mongo\django-mongo\EmployeeApp\middleware.py changed, reloading.
INFO:root:Document created successfully at Sun Feb  5 19:18:58 2023
INFO:root:Document created successfully at Sun Feb  5 19:18:58 2023
INFO:root:Started request: POST /register
INFO:root:Finished request: POST /register with status 400
WARNING:django.request:Bad Request: /register
INFO:root:Started request: GET /employees
INFO:root:Finished request: GET /employees with status 200
INFO:root:Started request: POST /register
INFO:root:Finished request: POST /register with status 400
WARNING:django.request:Bad Request: /register
INFO:root:Started request: GET /employee/32
INFO:root:Finished request: GET /employee/32 with status 403
WARNING:django.request:Forbidden: /employee/32
INFO:root:Started request: POST /register
INFO:root:Finished request: POST /register with status 400
WARNING:django.request:Bad Request: /register
INFO:root:Started request: GET /employee/32
INFO:root:Finished request: GET /employee/32 with status 200
INFO:root:Started request: POST /register
INFO:root:Finished request: POST /register with status 400
WARNING:django.request:Bad Request: /register
INFO:root:Started request: GET /employee/32
INFO:root:Finished request: GET /employee/32 with status 403
WARNING:django.request:Forbidden: /employee/32
INFO:root:Started request: POST /register
INFO:root:Finished request: POST /register with status 400
WARNING:django.request:Bad Request: /register
INFO:root:Started request: GET /employee/32
INFO:root:Finished request: GET /employee/32 with status 200
INFO:root:Document created successfully at Mon Feb  6 10:24:28 2023
INFO:root:Document created successfully at Mon Feb  6 10:24:28 2023
INFO:root:Started request: GET /employees
INFO:root:Finished request: GET /employees with status 200
INFO:root:Started request: GET /employee/6
INFO:root:Finished request: GET /employee/6 with status 403
WARNING:django.request:Forbidden: /employee/6
INFO:django.utils.autoreload:C:\django-mongo\django-mongo\EmployeeApp\middleware.py changed, reloading.
INFO:root:Document created successfully at Mon Feb  6 10:26:31 2023
INFO:root:Document created successfully at Mon Feb  6 10:26:31 2023
INFO:root:Started request: GET /employee/6
INFO:root:Finished request: GET /employee/6 with status 403
WARNING:django.request:Forbidden: /employee/6
INFO:root:Document created successfully at Tue Feb  7 12:49:03 2023
INFO:root:Document created successfully at Tue Feb  7 12:49:03 2023
INFO:django.utils.autoreload:C:\django-mongo\django-mongo\new_project\settings.py changed, reloading.
INFO:root:Document created successfully at Tue Feb  7 16:54:00 2023
INFO:root:Document created successfully at Tue Feb  7 16:54:00 2023
INFO:django.utils.autoreload:C:\django-mongo\django-mongo\EmployeeApp\views.py changed, reloading.
INFO:root:Document created successfully at Tue Feb  7 16:54:35 2023
INFO:root:Document created successfully at Tue Feb  7 16:54:35 2023
INFO:root:Started request: GET /employee/31
INFO:root:Finished request: GET /employee/31 with status 403
WARNING:django.request:Forbidden: /employee/31
INFO:django.utils.autoreload:C:\django-mongo\django-mongo\new_project\settings.py changed, reloading.
INFO:root:Document created successfully at Wed Feb  8 12:20:50 2023
INFO:root:Document created successfully at Wed Feb  8 12:20:50 2023
INFO:root:Started request: POST /register
INFO:root:Finished request: POST /register with status 400
WARNING:django.request:Bad Request: /register
INFO:root:Started request: POST /register
INFO:root:Finished request: POST /register with status 201
INFO:django.utils.autoreload:C:\django-mongo\django-mongo\EmployeeApp\views.py changed, reloading.
INFO:django.utils.autoreload:C:\django-mongo\django-mongo\EmployeeApp\views.py changed, reloading.
INFO:root:Started request: POST /register
ERROR:django.request:Internal Server Error: /register
Traceback (most recent call last):
  File "C:\django-mongo\django-mongo\venv\lib\site-packages\django\core\handlers\exception.py", line 47, in inner
    response = get_response(request)
  File "C:\django-mongo\django-mongo\venv\lib\site-packages\django\core\handlers\base.py", line 181, in _get_response
    response = wrapped_callback(request, *callback_args, **callback_kwargs)
  File "C:\django-mongo\django-mongo\venv\lib\site-packages\django\views\decorators\csrf.py", line 54, in wrapped_view
    return view_func(*args, **kwargs)
  File "C:\django-mongo\django-mongo\venv\lib\site-packages\django\views\generic\base.py", line 70, in view
    return self.dispatch(request, *args, **kwargs)
  File "C:\django-mongo\django-mongo\venv\lib\site-packages\rest_framework\views.py", line 509, in dispatch
    response = self.handle_exception(exc)
  File "C:\django-mongo\django-mongo\venv\lib\site-packages\rest_framework\views.py", line 469, in handle_exception
    self.raise_uncaught_exception(exc)
  File "C:\django-mongo\django-mongo\venv\lib\site-packages\rest_framework\views.py", line 480, in raise_uncaught_exception
    raise exc
  File "C:\django-mongo\django-mongo\venv\lib\site-packages\rest_framework\views.py", line 506, in dispatch
    response = handler(request, *args, **kwargs)
  File "C:\django-mongo\django-mongo\EmployeeApp\views.py", line 24, in post
    return super().post(request, *args, **kwargs)
  File "C:\django-mongo\django-mongo\venv\lib\site-packages\rest_framework_mongoengine\generics.py", line 56, in post
    return self.create(request, *args, **kwargs)
  File "C:\django-mongo\django-mongo\venv\lib\site-packages\rest_framework\mixins.py", line 17, in create
    serializer = self.get_serializer(data=request.data)
  File "C:\django-mongo\django-mongo\venv\lib\site-packages\rest_framework\generics.py", line 108, in get_serializer
    serializer_class = self.get_serializer_class()
  File "C:\django-mongo\django-mongo\venv\lib\site-packages\rest_framework\generics.py", line 125, in get_serializer_class
    % self.__class__.__name__
AssertionError: 'EmployeeAdd' should either include a `serializer_class` attribute, or override the `get_serializer_class()` method.
INFO:root:Finished request: POST /register with status 500
INFO:django.utils.autoreload:C:\django-mongo\django-mongo\EmployeeApp\views.py changed, reloading.
INFO:root:Started request: POST /register
INFO:root:Finished request: POST /register with status 400
WARNING:django.request:Bad Request: /register
INFO:django.utils.autoreload:C:\django-mongo\django-mongo\EmployeeApp\views.py changed, reloading.
INFO:root:Started request: POST /register
INFO:root:Finished request: POST /register with status 400
WARNING:django.request:Bad Request: /register
INFO:django.utils.autoreload:C:\django-mongo\django-mongo\EmployeeApp\views.py changed, reloading.
INFO:django.utils.autoreload:C:\django-mongo\django-mongo\EmployeeApp\views.py changed, reloading.
INFO:root:Started request: POST /register
INFO:root:Finished request: POST /register with status 400
WARNING:django.request:Bad Request: /register
INFO:django.utils.autoreload:C:\django-mongo\django-mongo\EmployeeApp\views.py changed, reloading.
INFO:django.utils.autoreload:C:\django-mongo\django-mongo\EmployeeApp\views.py changed, reloading.
INFO:root:Started request: POST /register
ERROR:django.request:Internal Server Error: /register
Traceback (most recent call last):
  File "C:\django-mongo\django-mongo\venv\lib\site-packages\django\core\handlers\exception.py", line 47, in inner
    response = get_response(request)
  File "C:\django-mongo\django-mongo\venv\lib\site-packages\django\core\handlers\base.py", line 181, in _get_response
    response = wrapped_callback(request, *callback_args, **callback_kwargs)
  File "C:\django-mongo\django-mongo\venv\lib\site-packages\django\views\decorators\csrf.py", line 54, in wrapped_view
    return view_func(*args, **kwargs)
  File "C:\django-mongo\django-mongo\venv\lib\site-packages\django\views\generic\base.py", line 70, in view
    return self.dispatch(request, *args, **kwargs)
  File "C:\django-mongo\django-mongo\venv\lib\site-packages\rest_framework\views.py", line 509, in dispatch
    response = self.handle_exception(exc)
  File "C:\django-mongo\django-mongo\venv\lib\site-packages\rest_framework\views.py", line 469, in handle_exception
    self.raise_uncaught_exception(exc)
  File "C:\django-mongo\django-mongo\venv\lib\site-packages\rest_framework\views.py", line 480, in raise_uncaught_exception
    raise exc
  File "C:\django-mongo\django-mongo\venv\lib\site-packages\rest_framework\views.py", line 506, in dispatch
    response = handler(request, *args, **kwargs)
  File "C:\django-mongo\django-mongo\EmployeeApp\views.py", line 24, in post
    print(request.body.name)
AttributeError: 'bytes' object has no attribute 'name'
INFO:root:Finished request: POST /register with status 500
INFO:django.utils.autoreload:C:\django-mongo\django-mongo\EmployeeApp\views.py changed, reloading.
INFO:root:Started request: POST /register
INFO:root:Finished request: POST /register with status 201
INFO:django.utils.autoreload:C:\django-mongo\django-mongo\EmployeeApp\views.py changed, reloading.
INFO:root:Started request: POST /register
INFO:root:Finished request: POST /register with status 400
WARNING:django.request:Bad Request: /register
INFO:root:Started request: POST /register
INFO:root:Finished request: POST /register with status 400
WARNING:django.request:Bad Request: /register
INFO:django.utils.autoreload:C:\django-mongo\django-mongo\EmployeeApp\models.py changed, reloading.
INFO:django.utils.autoreload:C:\django-mongo\django-mongo\EmployeeApp\models.py changed, reloading.
INFO:root:Started request: POST /register
ERROR:django.request:Internal Server Error: /register
Traceback (most recent call last):
  File "C:\django-mongo\django-mongo\venv\lib\site-packages\django\core\handlers\exception.py", line 47, in inner
    response = get_response(request)
  File "C:\django-mongo\django-mongo\venv\lib\site-packages\django\core\handlers\base.py", line 181, in _get_response
    response = wrapped_callback(request, *callback_args, **callback_kwargs)
  File "C:\django-mongo\django-mongo\venv\lib\site-packages\django\views\decorators\csrf.py", line 54, in wrapped_view
    return view_func(*args, **kwargs)
  File "C:\django-mongo\django-mongo\venv\lib\site-packages\django\views\generic\base.py", line 70, in view
    return self.dispatch(request, *args, **kwargs)
  File "C:\django-mongo\django-mongo\venv\lib\site-packages\rest_framework\views.py", line 509, in dispatch
    response = self.handle_exception(exc)
  File "C:\django-mongo\django-mongo\venv\lib\site-packages\rest_framework\views.py", line 469, in handle_exception
    self.raise_uncaught_exception(exc)
  File "C:\django-mongo\django-mongo\venv\lib\site-packages\rest_framework\views.py", line 480, in raise_uncaught_exception
    raise exc
  File "C:\django-mongo\django-mongo\venv\lib\site-packages\rest_framework\views.py", line 506, in dispatch
    response = handler(request, *args, **kwargs)
  File "C:\django-mongo\django-mongo\EmployeeApp\views.py", line 25, in post
    return super().post(request, *args, **kwargs)
  File "C:\django-mongo\django-mongo\venv\lib\site-packages\rest_framework_mongoengine\generics.py", line 56, in post
    return self.create(request, *args, **kwargs)
  File "C:\django-mongo\django-mongo\venv\lib\site-packages\rest_framework\mixins.py", line 18, in create
    serializer.is_valid(raise_exception=True)
  File "C:\django-mongo\django-mongo\venv\lib\site-packages\rest_framework\serializers.py", line 227, in is_valid
    self._validated_data = self.run_validation(self.initial_data)
  File "C:\django-mongo\django-mongo\venv\lib\site-packages\rest_framework\serializers.py", line 426, in run_validation
    value = self.to_internal_value(data)
  File "C:\django-mongo\django-mongo\venv\lib\site-packages\rest_framework_mongoengine\serializers.py", line 283, in to_internal_value
    ret = super(DocumentSerializer, self).to_internal_value(data)
  File "C:\django-mongo\django-mongo\venv\lib\site-packages\rest_framework\serializers.py", line 483, in to_internal_value
    validated_value = field.run_validation(primitive_value)
  File "C:\django-mongo\django-mongo\venv\lib\site-packages\rest_framework\fields.py", line 751, in run_validation
    return super().run_validation(data)
  File "C:\django-mongo\django-mongo\venv\lib\site-packages\rest_framework\fields.py", line 548, in run_validation
    self.run_validators(value)
  File "C:\django-mongo\django-mongo\venv\lib\site-packages\rest_framework\fields.py", line 560, in run_validators
    validator(value, self)
  File "C:\django-mongo\django-mongo\venv\lib\site-packages\rest_framework_mongoengine\validators.py", line 42, in __call__
    if queryset.first():
  File "C:\django-mongo\django-mongo\venv\lib\site-packages\mongoengine\queryset\base.py", line 293, in first
    result = queryset[0]
  File "C:\django-mongo\django-mongo\venv\lib\site-packages\mongoengine\queryset\base.py", line 204, in __getitem__
    _auto_dereference=self._auto_dereference,
  File "C:\django-mongo\django-mongo\venv\lib\site-packages\mongoengine\base\document.py", line 836, in _from_son
    obj = cls(__auto_convert=False, _created=created, **data)
  File "C:\django-mongo\django-mongo\venv\lib\site-packages\mongoengine\base\document.py", line 99, in __init__
    raise FieldDoesNotExist(msg)
mongoengine.errors.FieldDoesNotExist: The fields "{'name'}" do not exist on the document "Employee"
INFO:root:Finished request: POST /register with status 500
INFO:root:Started request: POST /register
ERROR:django.request:Internal Server Error: /register
Traceback (most recent call last):
  File "C:\django-mongo\django-mongo\venv\lib\site-packages\django\core\handlers\exception.py", line 47, in inner
    response = get_response(request)
  File "C:\django-mongo\django-mongo\venv\lib\site-packages\django\core\handlers\base.py", line 181, in _get_response
    response = wrapped_callback(request, *callback_args, **callback_kwargs)
  File "C:\django-mongo\django-mongo\venv\lib\site-packages\django\views\decorators\csrf.py", line 54, in wrapped_view
    return view_func(*args, **kwargs)
  File "C:\django-mongo\django-mongo\venv\lib\site-packages\django\views\generic\base.py", line 70, in view
    return self.dispatch(request, *args, **kwargs)
  File "C:\django-mongo\django-mongo\venv\lib\site-packages\rest_framework\views.py", line 509, in dispatch
    response = self.handle_exception(exc)
  File "C:\django-mongo\django-mongo\venv\lib\site-packages\rest_framework\views.py", line 469, in handle_exception
    self.raise_uncaught_exception(exc)
  File "C:\django-mongo\django-mongo\venv\lib\site-packages\rest_framework\views.py", line 480, in raise_uncaught_exception
    raise exc
  File "C:\django-mongo\django-mongo\venv\lib\site-packages\rest_framework\views.py", line 506, in dispatch
    response = handler(request, *args, **kwargs)
  File "C:\django-mongo\django-mongo\EmployeeApp\views.py", line 25, in post
    return super().post(request, *args, **kwargs)
  File "C:\django-mongo\django-mongo\venv\lib\site-packages\rest_framework_mongoengine\generics.py", line 56, in post
    return self.create(request, *args, **kwargs)
  File "C:\django-mongo\django-mongo\venv\lib\site-packages\rest_framework\mixins.py", line 18, in create
    serializer.is_valid(raise_exception=True)
  File "C:\django-mongo\django-mongo\venv\lib\site-packages\rest_framework\serializers.py", line 227, in is_valid
    self._validated_data = self.run_validation(self.initial_data)
  File "C:\django-mongo\django-mongo\venv\lib\site-packages\rest_framework\serializers.py", line 426, in run_validation
    value = self.to_internal_value(data)
  File "C:\django-mongo\django-mongo\venv\lib\site-packages\rest_framework_mongoengine\serializers.py", line 283, in to_internal_value
    ret = super(DocumentSerializer, self).to_internal_value(data)
  File "C:\django-mongo\django-mongo\venv\lib\site-packages\rest_framework\serializers.py", line 483, in to_internal_value
    validated_value = field.run_validation(primitive_value)
  File "C:\django-mongo\django-mongo\venv\lib\site-packages\rest_framework\fields.py", line 751, in run_validation
    return super().run_validation(data)
  File "C:\django-mongo\django-mongo\venv\lib\site-packages\rest_framework\fields.py", line 548, in run_validation
    self.run_validators(value)
  File "C:\django-mongo\django-mongo\venv\lib\site-packages\rest_framework\fields.py", line 560, in run_validators
    validator(value, self)
  File "C:\django-mongo\django-mongo\venv\lib\site-packages\rest_framework_mongoengine\validators.py", line 42, in __call__
    if queryset.first():
  File "C:\django-mongo\django-mongo\venv\lib\site-packages\mongoengine\queryset\base.py", line 293, in first
    result = queryset[0]
  File "C:\django-mongo\django-mongo\venv\lib\site-packages\mongoengine\queryset\base.py", line 204, in __getitem__
    _auto_dereference=self._auto_dereference,
  File "C:\django-mongo\django-mongo\venv\lib\site-packages\mongoengine\base\document.py", line 836, in _from_son
    obj = cls(__auto_convert=False, _created=created, **data)
  File "C:\django-mongo\django-mongo\venv\lib\site-packages\mongoengine\base\document.py", line 99, in __init__
    raise FieldDoesNotExist(msg)
mongoengine.errors.FieldDoesNotExist: The fields "{'name'}" do not exist on the document "Employee"
INFO:root:Finished request: POST /register with status 500
INFO:django.utils.autoreload:C:\django-mongo\django-mongo\EmployeeApp\models.py changed, reloading.
INFO:root:Started request: POST /register
ERROR:django.request:Internal Server Error: /register
Traceback (most recent call last):
  File "C:\django-mongo\django-mongo\venv\lib\site-packages\django\core\handlers\exception.py", line 47, in inner
    response = get_response(request)
  File "C:\django-mongo\django-mongo\venv\lib\site-packages\django\core\handlers\base.py", line 181, in _get_response
    response = wrapped_callback(request, *callback_args, **callback_kwargs)
  File "C:\django-mongo\django-mongo\venv\lib\site-packages\django\views\decorators\csrf.py", line 54, in wrapped_view
    return view_func(*args, **kwargs)
  File "C:\django-mongo\django-mongo\venv\lib\site-packages\django\views\generic\base.py", line 70, in view
    return self.dispatch(request, *args, **kwargs)
  File "C:\django-mongo\django-mongo\venv\lib\site-packages\rest_framework\views.py", line 509, in dispatch
    response = self.handle_exception(exc)
  File "C:\django-mongo\django-mongo\venv\lib\site-packages\rest_framework\views.py", line 469, in handle_exception
    self.raise_uncaught_exception(exc)
  File "C:\django-mongo\django-mongo\venv\lib\site-packages\rest_framework\views.py", line 480, in raise_uncaught_exception
    raise exc
  File "C:\django-mongo\django-mongo\venv\lib\site-packages\rest_framework\views.py", line 506, in dispatch
    response = handler(request, *args, **kwargs)
  File "C:\django-mongo\django-mongo\EmployeeApp\views.py", line 25, in post
    return super().post(request, *args, **kwargs)
  File "C:\django-mongo\django-mongo\venv\lib\site-packages\rest_framework_mongoengine\generics.py", line 56, in post
    return self.create(request, *args, **kwargs)
  File "C:\django-mongo\django-mongo\venv\lib\site-packages\rest_framework\mixins.py", line 18, in create
    serializer.is_valid(raise_exception=True)
  File "C:\django-mongo\django-mongo\venv\lib\site-packages\rest_framework\serializers.py", line 227, in is_valid
    self._validated_data = self.run_validation(self.initial_data)
  File "C:\django-mongo\django-mongo\venv\lib\site-packages\rest_framework\serializers.py", line 426, in run_validation
    value = self.to_internal_value(data)
  File "C:\django-mongo\django-mongo\venv\lib\site-packages\rest_framework_mongoengine\serializers.py", line 283, in to_internal_value
    ret = super(DocumentSerializer, self).to_internal_value(data)
  File "C:\django-mongo\django-mongo\venv\lib\site-packages\rest_framework\serializers.py", line 483, in to_internal_value
    validated_value = field.run_validation(primitive_value)
  File "C:\django-mongo\django-mongo\venv\lib\site-packages\rest_framework\fields.py", line 751, in run_validation
    return super().run_validation(data)
  File "C:\django-mongo\django-mongo\venv\lib\site-packages\rest_framework\fields.py", line 548, in run_validation
    self.run_validators(value)
  File "C:\django-mongo\django-mongo\venv\lib\site-packages\rest_framework\fields.py", line 560, in run_validators
    validator(value, self)
  File "C:\django-mongo\django-mongo\venv\lib\site-packages\rest_framework_mongoengine\validators.py", line 42, in __call__
    if queryset.first():
  File "C:\django-mongo\django-mongo\venv\lib\site-packages\mongoengine\queryset\base.py", line 293, in first
    result = queryset[0]
  File "C:\django-mongo\django-mongo\venv\lib\site-packages\mongoengine\queryset\base.py", line 204, in __getitem__
    _auto_dereference=self._auto_dereference,
  File "C:\django-mongo\django-mongo\venv\lib\site-packages\mongoengine\base\document.py", line 836, in _from_son
    obj = cls(__auto_convert=False, _created=created, **data)
  File "C:\django-mongo\django-mongo\venv\lib\site-packages\mongoengine\base\document.py", line 99, in __init__
    raise FieldDoesNotExist(msg)
mongoengine.errors.FieldDoesNotExist: The fields "{'name'}" do not exist on the document "Employee"
INFO:root:Finished request: POST /register with status 500
INFO:django.utils.autoreload:C:\django-mongo\django-mongo\EmployeeApp\views.py changed, reloading.
INFO:django.utils.autoreload:C:\django-mongo\django-mongo\EmployeeApp\views.py changed, reloading.
INFO:root:Started request: POST /register
ERROR:django.request:Internal Server Error: /register
Traceback (most recent call last):
  File "C:\django-mongo\django-mongo\venv\lib\site-packages\django\core\handlers\exception.py", line 47, in inner
    response = get_response(request)
  File "C:\django-mongo\django-mongo\venv\lib\site-packages\django\core\handlers\base.py", line 181, in _get_response
    response = wrapped_callback(request, *callback_args, **callback_kwargs)
  File "C:\django-mongo\django-mongo\venv\lib\site-packages\django\views\decorators\csrf.py", line 54, in wrapped_view
    return view_func(*args, **kwargs)
  File "C:\django-mongo\django-mongo\venv\lib\site-packages\django\views\generic\base.py", line 70, in view
    return self.dispatch(request, *args, **kwargs)
  File "C:\django-mongo\django-mongo\venv\lib\site-packages\rest_framework\views.py", line 509, in dispatch
    response = self.handle_exception(exc)
  File "C:\django-mongo\django-mongo\venv\lib\site-packages\rest_framework\views.py", line 469, in handle_exception
    self.raise_uncaught_exception(exc)
  File "C:\django-mongo\django-mongo\venv\lib\site-packages\rest_framework\views.py", line 480, in raise_uncaught_exception
    raise exc
  File "C:\django-mongo\django-mongo\venv\lib\site-packages\rest_framework\views.py", line 506, in dispatch
    response = handler(request, *args, **kwargs)
  File "C:\django-mongo\django-mongo\EmployeeApp\views.py", line 21, in post
    return super().post(request, *args, **kwargs)
  File "C:\django-mongo\django-mongo\venv\lib\site-packages\rest_framework_mongoengine\generics.py", line 56, in post
    return self.create(request, *args, **kwargs)
  File "C:\django-mongo\django-mongo\venv\lib\site-packages\rest_framework\mixins.py", line 18, in create
    serializer.is_valid(raise_exception=True)
  File "C:\django-mongo\django-mongo\venv\lib\site-packages\rest_framework\serializers.py", line 227, in is_valid
    self._validated_data = self.run_validation(self.initial_data)
  File "C:\django-mongo\django-mongo\venv\lib\site-packages\rest_framework\serializers.py", line 426, in run_validation
    value = self.to_internal_value(data)
  File "C:\django-mongo\django-mongo\venv\lib\site-packages\rest_framework_mongoengine\serializers.py", line 283, in to_internal_value
    ret = super(DocumentSerializer, self).to_internal_value(data)
  File "C:\django-mongo\django-mongo\venv\lib\site-packages\rest_framework\serializers.py", line 483, in to_internal_value
    validated_value = field.run_validation(primitive_value)
  File "C:\django-mongo\django-mongo\venv\lib\site-packages\rest_framework\fields.py", line 751, in run_validation
    return super().run_validation(data)
  File "C:\django-mongo\django-mongo\venv\lib\site-packages\rest_framework\fields.py", line 548, in run_validation
    self.run_validators(value)
  File "C:\django-mongo\django-mongo\venv\lib\site-packages\rest_framework\fields.py", line 560, in run_validators
    validator(value, self)
  File "C:\django-mongo\django-mongo\venv\lib\site-packages\rest_framework_mongoengine\validators.py", line 42, in __call__
    if queryset.first():
  File "C:\django-mongo\django-mongo\venv\lib\site-packages\mongoengine\queryset\base.py", line 293, in first
    result = queryset[0]
  File "C:\django-mongo\django-mongo\venv\lib\site-packages\mongoengine\queryset\base.py", line 204, in __getitem__
    _auto_dereference=self._auto_dereference,
  File "C:\django-mongo\django-mongo\venv\lib\site-packages\mongoengine\base\document.py", line 836, in _from_son
    obj = cls(__auto_convert=False, _created=created, **data)
  File "C:\django-mongo\django-mongo\venv\lib\site-packages\mongoengine\base\document.py", line 99, in __init__
    raise FieldDoesNotExist(msg)
mongoengine.errors.FieldDoesNotExist: The fields "{'name'}" do not exist on the document "Employee"
INFO:root:Finished request: POST /register with status 500
INFO:root:Started request: POST /add-person
INFO:root:Finished request: POST /add-person with status 404
WARNING:django.request:Not Found: /add-person
INFO:django.utils.autoreload:C:\django-mongo\django-mongo\new_project\urls.py changed, reloading.
INFO:root:Started request: POST /add-person
INFO:root:Finished request: POST /add-person with status 403
WARNING:django.request:Forbidden: /add-person
INFO:django.utils.autoreload:C:\django-mongo\django-mongo\EmployeeApp\middleware.py changed, reloading.
INFO:django.utils.autoreload:C:\django-mongo\django-mongo\EmployeeApp\middleware.py changed, reloading.
INFO:root:Started request: POST /add-person
INFO:root:Finished request: POST /add-person with status 201
INFO:root:Started request: POST /add-person
ERROR:django.request:Internal Server Error: /add-person
Traceback (most recent call last):
  File "C:\django-mongo\django-mongo\venv\lib\site-packages\django\core\handlers\exception.py", line 47, in inner
    response = get_response(request)
  File "C:\django-mongo\django-mongo\venv\lib\site-packages\django\core\handlers\base.py", line 204, in _get_response
    response = response.render()
  File "C:\django-mongo\django-mongo\venv\lib\site-packages\django\template\response.py", line 105, in render
    self.content = self.rendered_content
  File "C:\django-mongo\django-mongo\venv\lib\site-packages\rest_framework\response.py", line 61, in rendered_content
    charset = renderer.charset
AttributeError: 'AnyCaseJSONParser' object has no attribute 'charset'
INFO:root:Finished request: POST /add-person with status 500
INFO:django.utils.autoreload:C:\django-mongo\django-mongo\new_project\settings.py changed, reloading.
INFO:root:Started request: POST /add-person
ERROR:django.request:Internal Server Error: /add-person
Traceback (most recent call last):
  File "C:\django-mongo\django-mongo\venv\lib\site-packages\django\core\handlers\exception.py", line 47, in inner
    response = get_response(request)
  File "C:\django-mongo\django-mongo\venv\lib\site-packages\django\core\handlers\base.py", line 204, in _get_response
    response = response.render()
  File "C:\django-mongo\django-mongo\venv\lib\site-packages\django\template\response.py", line 105, in render
    self.content = self.rendered_content
  File "C:\django-mongo\django-mongo\venv\lib\site-packages\rest_framework\response.py", line 61, in rendered_content
    charset = renderer.charset
AttributeError: 'AnyCaseJSONParser' object has no attribute 'charset'
INFO:root:Finished request: POST /add-person with status 500
INFO:django.utils.autoreload:C:\django-mongo\django-mongo\new_project\settings.py changed, reloading.
INFO:root:Started request: POST /add-person
INFO:root:Finished request: POST /add-person with status 201
INFO:root:Started request: POST /add-person
INFO:root:Finished request: POST /add-person with status 201
INFO:root:Started request: POST /add-person
INFO:root:Finished request: POST /add-person with status 201
INFO:root:Started request: POST /login
INFO:root:Finished request: POST /login with status 403
WARNING:django.request:Forbidden: /login
INFO:django.utils.autoreload:C:\django-mongo\django-mongo\EmployeeApp\middleware.py changed, reloading.
INFO:root:Started request: POST /login
INFO:root:Finished request: POST /login with status 200
INFO:root:Started request: POST /login
INFO:root:Finished request: POST /login with status 200
INFO:django.utils.autoreload:C:\django-mongo\django-mongo\EmployeeApp\views.py changed, reloading.
INFO:root:Started request: POST /login
INFO:root:Finished request: POST /login with status 200
INFO:django.utils.autoreload:C:\django-mongo\django-mongo\EmployeeApp\views.py changed, reloading.
INFO:django.utils.autoreload:C:\django-mongo\django-mongo\EmployeeApp\views.py changed, reloading.
INFO:root:Started request: POST /login
ERROR:django.request:Internal Server Error: /login
Traceback (most recent call last):
  File "C:\django-mongo\django-mongo\venv\lib\site-packages\django\core\handlers\exception.py", line 47, in inner
    response = get_response(request)
  File "C:\django-mongo\django-mongo\venv\lib\site-packages\django\core\handlers\base.py", line 181, in _get_response
    response = wrapped_callback(request, *callback_args, **callback_kwargs)
  File "C:\django-mongo\django-mongo\venv\lib\site-packages\django\views\decorators\csrf.py", line 54, in wrapped_view
    return view_func(*args, **kwargs)
  File "C:\django-mongo\django-mongo\venv\lib\site-packages\django\views\generic\base.py", line 70, in view
    return self.dispatch(request, *args, **kwargs)
  File "C:\django-mongo\django-mongo\venv\lib\site-packages\rest_framework\views.py", line 509, in dispatch
    response = self.handle_exception(exc)
  File "C:\django-mongo\django-mongo\venv\lib\site-packages\rest_framework\views.py", line 469, in handle_exception
    self.raise_uncaught_exception(exc)
  File "C:\django-mongo\django-mongo\venv\lib\site-packages\rest_framework\views.py", line 480, in raise_uncaught_exception
    raise exc
  File "C:\django-mongo\django-mongo\venv\lib\site-packages\rest_framework\views.py", line 506, in dispatch
    response = handler(request, *args, **kwargs)
  File "C:\django-mongo\django-mongo\EmployeeApp\views.py", line 109, in post
    user = self.get_object(email=email, password=password)
TypeError: get_object() got an unexpected keyword argument 'email'
INFO:root:Finished request: POST /login with status 500
INFO:django.utils.autoreload:C:\django-mongo\django-mongo\EmployeeApp\views.py changed, reloading.
INFO:django.utils.autoreload:C:\django-mongo\django-mongo\EmployeeApp\views.py changed, reloading.
INFO:django.utils.autoreload:C:\django-mongo\django-mongo\EmployeeApp\views.py changed, reloading.
INFO:django.utils.autoreload:C:\django-mongo\django-mongo\EmployeeApp\views.py changed, reloading.
INFO:root:Started request: POST /login
INFO:root:Finished request: POST /login with status 200
INFO:django.utils.autoreload:C:\django-mongo\django-mongo\EmployeeApp\views.py changed, reloading.
INFO:root:Started request: POST /login
ERROR:django.request:Internal Server Error: /login
Traceback (most recent call last):
  File "C:\django-mongo\django-mongo\venv\lib\site-packages\django\core\handlers\exception.py", line 47, in inner
    response = get_response(request)
  File "C:\django-mongo\django-mongo\venv\lib\site-packages\django\core\handlers\base.py", line 181, in _get_response
    response = wrapped_callback(request, *callback_args, **callback_kwargs)
  File "C:\django-mongo\django-mongo\venv\lib\site-packages\django\views\decorators\csrf.py", line 54, in wrapped_view
    return view_func(*args, **kwargs)
  File "C:\django-mongo\django-mongo\venv\lib\site-packages\django\views\generic\base.py", line 70, in view
    return self.dispatch(request, *args, **kwargs)
  File "C:\django-mongo\django-mongo\venv\lib\site-packages\rest_framework\views.py", line 509, in dispatch
    response = self.handle_exception(exc)
  File "C:\django-mongo\django-mongo\venv\lib\site-packages\rest_framework\views.py", line 469, in handle_exception
    self.raise_uncaught_exception(exc)
  File "C:\django-mongo\django-mongo\venv\lib\site-packages\rest_framework\views.py", line 480, in raise_uncaught_exception
    raise exc
  File "C:\django-mongo\django-mongo\venv\lib\site-packages\rest_framework\views.py", line 506, in dispatch
    response = handler(request, *args, **kwargs)
  File "C:\django-mongo\django-mongo\EmployeeApp\views.py", line 111, in post
    user = self.get(email=email, password=password)
AttributeError: 'EmployeeLogin' object has no attribute 'get'
INFO:root:Finished request: POST /login with status 500
INFO:django.utils.autoreload:C:\django-mongo\django-mongo\EmployeeApp\views.py changed, reloading.
INFO:root:Started request: POST /login
ERROR:django.request:Internal Server Error: /login
Traceback (most recent call last):
  File "C:\django-mongo\django-mongo\venv\lib\site-packages\django\core\handlers\exception.py", line 47, in inner
    response = get_response(request)
  File "C:\django-mongo\django-mongo\venv\lib\site-packages\django\core\handlers\base.py", line 181, in _get_response
    response = wrapped_callback(request, *callback_args, **callback_kwargs)
  File "C:\django-mongo\django-mongo\venv\lib\site-packages\django\views\decorators\csrf.py", line 54, in wrapped_view
    return view_func(*args, **kwargs)
  File "C:\django-mongo\django-mongo\venv\lib\site-packages\django\views\generic\base.py", line 70, in view
    return self.dispatch(request, *args, **kwargs)
  File "C:\django-mongo\django-mongo\venv\lib\site-packages\rest_framework\views.py", line 509, in dispatch
    response = self.handle_exception(exc)
  File "C:\django-mongo\django-mongo\venv\lib\site-packages\rest_framework\views.py", line 469, in handle_exception
    self.raise_uncaught_exception(exc)
  File "C:\django-mongo\django-mongo\venv\lib\site-packages\rest_framework\views.py", line 480, in raise_uncaught_exception
    raise exc
  File "C:\django-mongo\django-mongo\venv\lib\site-packages\rest_framework\views.py", line 506, in dispatch
    response = handler(request, *args, **kwargs)
  File "C:\django-mongo\django-mongo\EmployeeApp\views.py", line 112, in post
    user = Employee.objects.get(email=email, password=password)
  File "C:\django-mongo\django-mongo\venv\lib\site-packages\mongoengine\queryset\base.py", line 269, in get
    result = next(queryset)
  File "C:\django-mongo\django-mongo\venv\lib\site-packages\mongoengine\queryset\base.py", line 1603, in __next__
    _auto_dereference=self._auto_dereference,
  File "C:\django-mongo\django-mongo\venv\lib\site-packages\mongoengine\base\document.py", line 836, in _from_son
    obj = cls(__auto_convert=False, _created=created, **data)
  File "C:\django-mongo\django-mongo\venv\lib\site-packages\mongoengine\base\document.py", line 99, in __init__
    raise FieldDoesNotExist(msg)
mongoengine.errors.FieldDoesNotExist: The fields "{'name'}" do not exist on the document "Employee"
INFO:root:Finished request: POST /login with status 500
INFO:django.utils.autoreload:C:\django-mongo\django-mongo\EmployeeApp\models.py changed, reloading.
INFO:root:Started request: POST /login
ERROR:django.request:Internal Server Error: /login
Traceback (most recent call last):
  File "C:\django-mongo\django-mongo\venv\lib\site-packages\django\core\handlers\exception.py", line 47, in inner
    response = get_response(request)
  File "C:\django-mongo\django-mongo\venv\lib\site-packages\django\core\handlers\base.py", line 181, in _get_response
    response = wrapped_callback(request, *callback_args, **callback_kwargs)
  File "C:\django-mongo\django-mongo\venv\lib\site-packages\django\views\decorators\csrf.py", line 54, in wrapped_view
    return view_func(*args, **kwargs)
  File "C:\django-mongo\django-mongo\venv\lib\site-packages\django\views\generic\base.py", line 70, in view
    return self.dispatch(request, *args, **kwargs)
  File "C:\django-mongo\django-mongo\venv\lib\site-packages\rest_framework\views.py", line 509, in dispatch
    response = self.handle_exception(exc)
  File "C:\django-mongo\django-mongo\venv\lib\site-packages\rest_framework\views.py", line 469, in handle_exception
    self.raise_uncaught_exception(exc)
  File "C:\django-mongo\django-mongo\venv\lib\site-packages\rest_framework\views.py", line 480, in raise_uncaught_exception
    raise exc
  File "C:\django-mongo\django-mongo\venv\lib\site-packages\rest_framework\views.py", line 506, in dispatch
    response = handler(request, *args, **kwargs)
  File "C:\django-mongo\django-mongo\EmployeeApp\views.py", line 117, in post
    jwt_token = {"token": jwt.encode(jwt_payload, "SECRET KEY").decode("utf-8")}
AttributeError: module 'jwt' has no attribute 'encode'
INFO:root:Finished request: POST /login with status 500
INFO:django.utils.autoreload:C:\django-mongo\django-mongo\EmployeeApp\views.py changed, reloading.
INFO:django.utils.autoreload:C:\django-mongo\django-mongo\EmployeeApp\views.py changed, reloading.
INFO:root:Started request: POST /login
ERROR:django.request:Internal Server Error: /login
Traceback (most recent call last):
  File "C:\django-mongo\django-mongo\venv\lib\site-packages\django\core\handlers\exception.py", line 47, in inner
    response = get_response(request)
  File "C:\django-mongo\django-mongo\venv\lib\site-packages\django\core\handlers\base.py", line 181, in _get_response
    response = wrapped_callback(request, *callback_args, **callback_kwargs)
  File "C:\django-mongo\django-mongo\venv\lib\site-packages\django\views\decorators\csrf.py", line 54, in wrapped_view
    return view_func(*args, **kwargs)
  File "C:\django-mongo\django-mongo\venv\lib\site-packages\django\views\generic\base.py", line 70, in view
    return self.dispatch(request, *args, **kwargs)
  File "C:\django-mongo\django-mongo\venv\lib\site-packages\rest_framework\views.py", line 509, in dispatch
    response = self.handle_exception(exc)
  File "C:\django-mongo\django-mongo\venv\lib\site-packages\rest_framework\views.py", line 469, in handle_exception
    self.raise_uncaught_exception(exc)
  File "C:\django-mongo\django-mongo\venv\lib\site-packages\rest_framework\views.py", line 480, in raise_uncaught_exception
    raise exc
  File "C:\django-mongo\django-mongo\venv\lib\site-packages\rest_framework\views.py", line 506, in dispatch
    response = handler(request, *args, **kwargs)
  File "C:\django-mongo\django-mongo\EmployeeApp\views.py", line 117, in post
    jwt_token = {"token": jwt.encode(jwt_payload, "SECRET KEY").decode("utf-8")}
AttributeError: 'str' object has no attribute 'decode'
INFO:root:Finished request: POST /login with status 500
INFO:django.utils.autoreload:C:\django-mongo\django-mongo\EmployeeApp\views.py changed, reloading.
INFO:root:Started request: POST /login
INFO:root:Finished request: POST /login with status 200
INFO:root:Started request: POST /add-person
INFO:root:Finished request: POST /add-person with status 201
INFO:root:Started request: POST /login
INFO:root:Finished request: POST /login with status 200
INFO:root:Started request: GET /employees
INFO:root:Finished request: GET /employees with status 200
INFO:root:Started request: GET /employee/35
INFO:root:Finished request: GET /employee/35 with status 403
WARNING:django.request:Forbidden: /employee/35
INFO:root:Started request: GET /employees
INFO:root:Finished request: GET /employees with status 200
INFO:root:Started request: GET /employees
INFO:root:Finished request: GET /employees with status 200
INFO:root:Started request: GET /employees
INFO:root:Finished request: GET /employees with status 200
INFO:root:Started request: GET /employees
INFO:root:Finished request: GET /employees with status 200
INFO:django.utils.autoreload:C:\django-mongo\django-mongo\EmployeeApp\views.py changed, reloading.
INFO:root:Started request: GET /employees
INFO:root:Finished request: GET /employees with status 200
INFO:django.utils.autoreload:C:\django-mongo\django-mongo\EmployeeApp\views.py changed, reloading.
INFO:django.utils.autoreload:C:\django-mongo\django-mongo\EmployeeApp\views.py changed, reloading.
INFO:django.utils.autoreload:C:\django-mongo\django-mongo\EmployeeApp\views.py changed, reloading.
INFO:django.utils.autoreload:C:\django-mongo\django-mongo\EmployeeApp\views.py changed, reloading.
INFO:django.utils.autoreload:C:\django-mongo\django-mongo\EmployeeApp\views.py changed, reloading.
INFO:django.utils.autoreload:C:\django-mongo\django-mongo\EmployeeApp\views.py changed, reloading.
INFO:django.utils.autoreload:C:\django-mongo\django-mongo\EmployeeApp\views.py changed, reloading.
INFO:django.utils.autoreload:C:\django-mongo\django-mongo\EmployeeApp\views.py changed, reloading.
INFO:django.utils.autoreload:C:\django-mongo\django-mongo\EmployeeApp\views.py changed, reloading.
INFO:django.utils.autoreload:C:\django-mongo\django-mongo\EmployeeApp\views.py changed, reloading.
INFO:django.utils.autoreload:C:\django-mongo\django-mongo\EmployeeApp\views.py changed, reloading.
INFO:django.utils.autoreload:C:\django-mongo\django-mongo\EmployeeApp\views.py changed, reloading.
INFO:root:Started request: GET /employees
INFO:root:Finished request: GET /employees with status 200
INFO:django.utils.autoreload:C:\django-mongo\django-mongo\EmployeeApp\views.py changed, reloading.
INFO:root:Started request: GET /employees
INFO:root:Finished request: GET /employees with status 200
INFO:django.utils.autoreload:C:\django-mongo\django-mongo\EmployeeApp\views.py changed, reloading.
INFO:django.utils.autoreload:C:\django-mongo\django-mongo\EmployeeApp\views.py changed, reloading.
INFO:django.utils.autoreload:C:\django-mongo\django-mongo\EmployeeApp\views.py changed, reloading.
INFO:root:Started request: GET /employees
ERROR:django.request:Internal Server Error: /employees
Traceback (most recent call last):
  File "C:\django-mongo\django-mongo\venv\lib\site-packages\django\core\handlers\exception.py", line 47, in inner
    response = get_response(request)
  File "C:\django-mongo\django-mongo\venv\lib\site-packages\django\core\handlers\base.py", line 181, in _get_response
    response = wrapped_callback(request, *callback_args, **callback_kwargs)
  File "C:\django-mongo\django-mongo\venv\lib\site-packages\django\views\decorators\csrf.py", line 54, in wrapped_view
    return view_func(*args, **kwargs)
  File "C:\django-mongo\django-mongo\venv\lib\site-packages\django\views\generic\base.py", line 70, in view
    return self.dispatch(request, *args, **kwargs)
  File "C:\django-mongo\django-mongo\venv\lib\site-packages\rest_framework\views.py", line 509, in dispatch
    response = self.handle_exception(exc)
  File "C:\django-mongo\django-mongo\venv\lib\site-packages\rest_framework\views.py", line 469, in handle_exception
    self.raise_uncaught_exception(exc)
  File "C:\django-mongo\django-mongo\venv\lib\site-packages\rest_framework\views.py", line 480, in raise_uncaught_exception
    raise exc
  File "C:\django-mongo\django-mongo\venv\lib\site-packages\rest_framework\views.py", line 506, in dispatch
    response = handler(request, *args, **kwargs)
  File "C:\django-mongo\django-mongo\EmployeeApp\views.py", line 46, in get
    total_count = len(data)
TypeError: object of type 'ListSerializer' has no len()
INFO:root:Finished request: GET /employees with status 500
INFO:django.utils.autoreload:C:\django-mongo\django-mongo\EmployeeApp\views.py changed, reloading.
INFO:root:Started request: GET /employees
ERROR:django.request:Internal Server Error: /employees
Traceback (most recent call last):
  File "C:\django-mongo\django-mongo\venv\lib\site-packages\django\core\handlers\exception.py", line 47, in inner
    response = get_response(request)
  File "C:\django-mongo\django-mongo\venv\lib\site-packages\django\core\handlers\base.py", line 204, in _get_response
    response = response.render()
  File "C:\django-mongo\django-mongo\venv\lib\site-packages\django\template\response.py", line 105, in render
    self.content = self.rendered_content
  File "C:\django-mongo\django-mongo\venv\lib\site-packages\rest_framework\response.py", line 70, in rendered_content
    ret = renderer.render(self.data, accepted_media_type, context)
  File "C:\django-mongo\django-mongo\venv\lib\site-packages\djangorestframework_camel_case\render.py", line 12, in render
    camelize(data, **self.json_underscoreize), *args, **kwargs
  File "C:\django-mongo\django-mongo\venv\lib\site-packages\rest_framework\renderers.py", line 102, in render
    allow_nan=not self.strict, separators=separators
  File "C:\django-mongo\django-mongo\venv\lib\site-packages\rest_framework\utils\json.py", line 25, in dumps
    return json.dumps(*args, **kwargs)
  File "C:\Program Files\WindowsApps\PythonSoftwareFoundation.Python.3.7_3.7.2544.0_x64__qbz5n2kfra8p0\lib\json\__init__.py", line 238, in dumps
    **kw).encode(obj)
  File "C:\Program Files\WindowsApps\PythonSoftwareFoundation.Python.3.7_3.7.2544.0_x64__qbz5n2kfra8p0\lib\json\encoder.py", line 199, in encode
    chunks = self.iterencode(o, _one_shot=True)
  File "C:\Program Files\WindowsApps\PythonSoftwareFoundation.Python.3.7_3.7.2544.0_x64__qbz5n2kfra8p0\lib\json\encoder.py", line 257, in iterencode
    return _iterencode(o, 0)
  File "C:\django-mongo\django-mongo\venv\lib\site-packages\rest_framework\utils\encoders.py", line 67, in default
    return super().default(obj)
  File "C:\Program Files\WindowsApps\PythonSoftwareFoundation.Python.3.7_3.7.2544.0_x64__qbz5n2kfra8p0\lib\json\encoder.py", line 179, in default
    raise TypeError(f'Object of type {o.__class__.__name__} '
TypeError: Object of type ListSerializer is not JSON serializable
INFO:root:Finished request: GET /employees with status 500
INFO:django.utils.autoreload:C:\django-mongo\django-mongo\EmployeeApp\views.py changed, reloading.
INFO:root:Started request: GET /employees
ERROR:django.request:Internal Server Error: /employees
Traceback (most recent call last):
  File "C:\django-mongo\django-mongo\venv\lib\site-packages\django\core\handlers\exception.py", line 47, in inner
    response = get_response(request)
  File "C:\django-mongo\django-mongo\venv\lib\site-packages\django\core\handlers\base.py", line 204, in _get_response
    response = response.render()
  File "C:\django-mongo\django-mongo\venv\lib\site-packages\django\template\response.py", line 105, in render
    self.content = self.rendered_content
  File "C:\django-mongo\django-mongo\venv\lib\site-packages\rest_framework\response.py", line 70, in rendered_content
    ret = renderer.render(self.data, accepted_media_type, context)
  File "C:\django-mongo\django-mongo\venv\lib\site-packages\djangorestframework_camel_case\render.py", line 12, in render
    camelize(data, **self.json_underscoreize), *args, **kwargs
  File "C:\django-mongo\django-mongo\venv\lib\site-packages\rest_framework\renderers.py", line 102, in render
    allow_nan=not self.strict, separators=separators
  File "C:\django-mongo\django-mongo\venv\lib\site-packages\rest_framework\utils\json.py", line 25, in dumps
    return json.dumps(*args, **kwargs)
  File "C:\Program Files\WindowsApps\PythonSoftwareFoundation.Python.3.7_3.7.2544.0_x64__qbz5n2kfra8p0\lib\json\__init__.py", line 238, in dumps
    **kw).encode(obj)
  File "C:\Program Files\WindowsApps\PythonSoftwareFoundation.Python.3.7_3.7.2544.0_x64__qbz5n2kfra8p0\lib\json\encoder.py", line 199, in encode
    chunks = self.iterencode(o, _one_shot=True)
  File "C:\Program Files\WindowsApps\PythonSoftwareFoundation.Python.3.7_3.7.2544.0_x64__qbz5n2kfra8p0\lib\json\encoder.py", line 257, in iterencode
    return _iterencode(o, 0)
  File "C:\django-mongo\django-mongo\venv\lib\site-packages\rest_framework\utils\encoders.py", line 67, in default
    return super().default(obj)
  File "C:\Program Files\WindowsApps\PythonSoftwareFoundation.Python.3.7_3.7.2544.0_x64__qbz5n2kfra8p0\lib\json\encoder.py", line 179, in default
    raise TypeError(f'Object of type {o.__class__.__name__} '
TypeError: Object of type ListSerializer is not JSON serializable
INFO:root:Finished request: GET /employees with status 500
INFO:django.utils.autoreload:C:\django-mongo\django-mongo\EmployeeApp\views.py changed, reloading.
INFO:django.utils.autoreload:C:\django-mongo\django-mongo\EmployeeApp\views.py changed, reloading.
INFO:django.utils.autoreload:C:\django-mongo\django-mongo\EmployeeApp\views.py changed, reloading.
INFO:django.utils.autoreload:C:\django-mongo\django-mongo\EmployeeApp\views.py changed, reloading.
INFO:root:Started request: GET /employees
ERROR:django.request:Internal Server Error: /employees
Traceback (most recent call last):
  File "C:\django-mongo\django-mongo\venv\lib\site-packages\django\core\handlers\exception.py", line 47, in inner
    response = get_response(request)
  File "C:\django-mongo\django-mongo\venv\lib\site-packages\django\core\handlers\base.py", line 181, in _get_response
    response = wrapped_callback(request, *callback_args, **callback_kwargs)
  File "C:\django-mongo\django-mongo\venv\lib\site-packages\django\views\decorators\csrf.py", line 54, in wrapped_view
    return view_func(*args, **kwargs)
  File "C:\django-mongo\django-mongo\venv\lib\site-packages\django\views\generic\base.py", line 70, in view
    return self.dispatch(request, *args, **kwargs)
  File "C:\django-mongo\django-mongo\venv\lib\site-packages\rest_framework\views.py", line 509, in dispatch
    response = self.handle_exception(exc)
  File "C:\django-mongo\django-mongo\venv\lib\site-packages\rest_framework\views.py", line 469, in handle_exception
    self.raise_uncaught_exception(exc)
  File "C:\django-mongo\django-mongo\venv\lib\site-packages\rest_framework\views.py", line 480, in raise_uncaught_exception
    raise exc
  File "C:\django-mongo\django-mongo\venv\lib\site-packages\rest_framework\views.py", line 506, in dispatch
    response = handler(request, *args, **kwargs)
  File "C:\django-mongo\django-mongo\EmployeeApp\views.py", line 43, in get
    employee_data=Employee.objects.paginate(page=page,per_page=page_size)
AttributeError: 'QuerySet' object has no attribute 'paginate'
INFO:root:Finished request: GET /employees with status 500
INFO:django.utils.autoreload:C:\django-mongo\django-mongo\EmployeeApp\views.py changed, reloading.
INFO:root:Started request: GET /employees
ERROR:django.request:Internal Server Error: /employees
Traceback (most recent call last):
  File "C:\django-mongo\django-mongo\venv\lib\site-packages\django\core\handlers\exception.py", line 47, in inner
    response = get_response(request)
  File "C:\django-mongo\django-mongo\venv\lib\site-packages\django\core\handlers\base.py", line 204, in _get_response
    response = response.render()
  File "C:\django-mongo\django-mongo\venv\lib\site-packages\django\template\response.py", line 105, in render
    self.content = self.rendered_content
  File "C:\django-mongo\django-mongo\venv\lib\site-packages\rest_framework\response.py", line 70, in rendered_content
    ret = renderer.render(self.data, accepted_media_type, context)
  File "C:\django-mongo\django-mongo\venv\lib\site-packages\djangorestframework_camel_case\render.py", line 12, in render
    camelize(data, **self.json_underscoreize), *args, **kwargs
  File "C:\django-mongo\django-mongo\venv\lib\site-packages\rest_framework\renderers.py", line 102, in render
    allow_nan=not self.strict, separators=separators
  File "C:\django-mongo\django-mongo\venv\lib\site-packages\rest_framework\utils\json.py", line 25, in dumps
    return json.dumps(*args, **kwargs)
  File "C:\Program Files\WindowsApps\PythonSoftwareFoundation.Python.3.7_3.7.2544.0_x64__qbz5n2kfra8p0\lib\json\__init__.py", line 238, in dumps
    **kw).encode(obj)
  File "C:\Program Files\WindowsApps\PythonSoftwareFoundation.Python.3.7_3.7.2544.0_x64__qbz5n2kfra8p0\lib\json\encoder.py", line 199, in encode
    chunks = self.iterencode(o, _one_shot=True)
  File "C:\Program Files\WindowsApps\PythonSoftwareFoundation.Python.3.7_3.7.2544.0_x64__qbz5n2kfra8p0\lib\json\encoder.py", line 257, in iterencode
    return _iterencode(o, 0)
  File "C:\django-mongo\django-mongo\venv\lib\site-packages\rest_framework\utils\encoders.py", line 67, in default
    return super().default(obj)
  File "C:\Program Files\WindowsApps\PythonSoftwareFoundation.Python.3.7_3.7.2544.0_x64__qbz5n2kfra8p0\lib\json\encoder.py", line 179, in default
    raise TypeError(f'Object of type {o.__class__.__name__} '
TypeError: Object of type ListSerializer is not JSON serializable
INFO:root:Finished request: GET /employees with status 500
INFO:django.utils.autoreload:C:\django-mongo\django-mongo\EmployeeApp\views.py changed, reloading.
INFO:root:Started request: GET /employees
INFO:root:Finished request: GET /employees with status 200
INFO:root:Started request: GET /employees
INFO:root:Finished request: GET /employees with status 200
INFO:root:Started request: GET /employees
INFO:root:Finished request: GET /employees with status 200
INFO:django.utils.autoreload:C:\django-mongo\django-mongo\EmployeeApp\views.py changed, reloading.
INFO:root:Started request: GET /employees
INFO:root:Finished request: GET /employees with status 200
INFO:django.utils.autoreload:C:\django-mongo\django-mongo\EmployeeApp\views.py changed, reloading.
INFO:django.utils.autoreload:C:\django-mongo\django-mongo\EmployeeApp\views.py changed, reloading.
INFO:django.utils.autoreload:C:\django-mongo\django-mongo\EmployeeApp\views.py changed, reloading.
INFO:django.utils.autoreload:C:\django-mongo\django-mongo\EmployeeApp\views.py changed, reloading.
INFO:django.utils.autoreload:C:\django-mongo\django-mongo\EmployeeApp\views.py changed, reloading.
INFO:django.utils.autoreload:C:\django-mongo\django-mongo\EmployeeApp\views.py changed, reloading.
INFO:django.utils.autoreload:C:\django-mongo\django-mongo\EmployeeApp\views.py changed, reloading.
INFO:root:Started request: GET /employees
INFO:root:Finished request: GET /employees with status 200
INFO:django.utils.autoreload:C:\django-mongo\django-mongo\EmployeeApp\views.py changed, reloading.
INFO:django.utils.autoreload:C:\django-mongo\django-mongo\EmployeeApp\views.py changed, reloading.
INFO:django.utils.autoreload:C:\django-mongo\django-mongo\EmployeeApp\views.py changed, reloading.
INFO:root:Started request: GET /employees
INFO:root:Finished request: GET /employees with status 200
INFO:django.utils.autoreload:C:\django-mongo\django-mongo\EmployeeApp\views.py changed, reloading.
INFO:root:Started request: GET /employees
INFO:root:Finished request: GET /employees with status 200
INFO:django.utils.autoreload:C:\django-mongo\django-mongo\EmployeeApp\views.py changed, reloading.
INFO:root:Started request: GET /employees
INFO:root:Finished request: GET /employees with status 200
INFO:django.utils.autoreload:C:\django-mongo\django-mongo\EmployeeApp\views.py changed, reloading.
INFO:django.utils.autoreload:C:\django-mongo\django-mongo\EmployeeApp\views.py changed, reloading.
INFO:root:Started request: GET /employees
INFO:root:Finished request: GET /employees with status 200
INFO:django.utils.autoreload:C:\django-mongo\django-mongo\EmployeeApp\views.py changed, reloading.
INFO:root:Started request: GET /employees
INFO:root:Finished request: GET /employees with status 200
INFO:root:Started request: GET /employees
INFO:root:Finished request: GET /employees with status 200
INFO:django.utils.autoreload:C:\django-mongo\django-mongo\EmployeeApp\views.py changed, reloading.
INFO:django.utils.autoreload:C:\django-mongo\django-mongo\EmployeeApp\views.py changed, reloading.
INFO:root:Started request: GET /employees
INFO:root:Finished request: GET /employees with status 200
INFO:root:Started request: GET /employees
INFO:root:Finished request: GET /employees with status 200
INFO:root:Started request: GET /employees
ERROR:django.request:Internal Server Error: /employees
Traceback (most recent call last):
  File "C:\django-mongo\django-mongo\venv\lib\site-packages\django\core\handlers\exception.py", line 47, in inner
    response = get_response(request)
  File "C:\django-mongo\django-mongo\venv\lib\site-packages\django\core\handlers\base.py", line 181, in _get_response
    response = wrapped_callback(request, *callback_args, **callback_kwargs)
  File "C:\django-mongo\django-mongo\venv\lib\site-packages\django\views\decorators\csrf.py", line 54, in wrapped_view
    return view_func(*args, **kwargs)
  File "C:\django-mongo\django-mongo\venv\lib\site-packages\django\views\generic\base.py", line 70, in view
    return self.dispatch(request, *args, **kwargs)
  File "C:\django-mongo\django-mongo\venv\lib\site-packages\rest_framework\views.py", line 509, in dispatch
    response = self.handle_exception(exc)
  File "C:\django-mongo\django-mongo\venv\lib\site-packages\rest_framework\views.py", line 469, in handle_exception
    self.raise_uncaught_exception(exc)
  File "C:\django-mongo\django-mongo\venv\lib\site-packages\rest_framework\views.py", line 480, in raise_uncaught_exception
    raise exc
  File "C:\django-mongo\django-mongo\venv\lib\site-packages\rest_framework\views.py", line 506, in dispatch
    response = handler(request, *args, **kwargs)
  File "C:\django-mongo\django-mongo\EmployeeApp\views.py", line 53, in get
    "payload": {"data": employees.data, "totalCount": total_count},
UnboundLocalError: local variable 'employees' referenced before assignment
INFO:root:Finished request: GET /employees with status 500
INFO:django.utils.autoreload:C:\django-mongo\django-mongo\EmployeeApp\views.py changed, reloading.
INFO:django.utils.autoreload:C:\django-mongo\django-mongo\EmployeeApp\views.py changed, reloading.
INFO:root:Started request: GET /employees
ERROR:django.request:Internal Server Error: /employees
Traceback (most recent call last):
  File "C:\django-mongo\django-mongo\venv\lib\site-packages\django\core\handlers\exception.py", line 47, in inner
    response = get_response(request)
  File "C:\django-mongo\django-mongo\venv\lib\site-packages\django\core\handlers\base.py", line 181, in _get_response
    response = wrapped_callback(request, *callback_args, **callback_kwargs)
  File "C:\django-mongo\django-mongo\venv\lib\site-packages\django\views\decorators\csrf.py", line 54, in wrapped_view
    return view_func(*args, **kwargs)
  File "C:\django-mongo\django-mongo\venv\lib\site-packages\django\views\generic\base.py", line 70, in view
    return self.dispatch(request, *args, **kwargs)
  File "C:\django-mongo\django-mongo\venv\lib\site-packages\rest_framework\views.py", line 509, in dispatch
    response = self.handle_exception(exc)
  File "C:\django-mongo\django-mongo\venv\lib\site-packages\rest_framework\views.py", line 469, in handle_exception
    self.raise_uncaught_exception(exc)
  File "C:\django-mongo\django-mongo\venv\lib\site-packages\rest_framework\views.py", line 480, in raise_uncaught_exception
    raise exc
  File "C:\django-mongo\django-mongo\venv\lib\site-packages\rest_framework\views.py", line 506, in dispatch
    response = handler(request, *args, **kwargs)
  File "C:\django-mongo\django-mongo\EmployeeApp\views.py", line 37, in get
    queryset = Employee.objects.all()
  File "C:\django-mongo\django-mongo\venv\lib\site-packages\mongoengine\queryset\manager.py", line 38, in __get__
    queryset = queryset_class(owner, owner._get_collection())
  File "C:\django-mongo\django-mongo\venv\lib\site-packages\mongoengine\document.py", line 232, in _get_collection
    cls.ensure_indexes()
  File "C:\django-mongo\django-mongo\venv\lib\site-packages\mongoengine\document.py", line 916, in ensure_indexes
    collection.create_index(fields, background=background, **opts)
  File "C:\django-mongo\django-mongo\venv\lib\site-packages\pymongo\collection.py", line 2055, in create_index
    return self.__create_indexes([index], session, **cmd_options)[0]
  File "C:\django-mongo\django-mongo\venv\lib\site-packages\pymongo\_csot.py", line 105, in csot_wrapper
    return func(self, *args, **kwargs)
  File "C:\django-mongo\django-mongo\venv\lib\site-packages\pymongo\collection.py", line 1938, in __create_indexes
    session=session,
  File "C:\django-mongo\django-mongo\venv\lib\site-packages\pymongo\collection.py", line 306, in _command
    user_fields=user_fields,
  File "C:\django-mongo\django-mongo\venv\lib\site-packages\pymongo\pool.py", line 789, in command
    write_concern=write_concern,
  File "C:\django-mongo\django-mongo\venv\lib\site-packages\pymongo\network.py", line 170, in command
    parse_write_concern_error=parse_write_concern_error,
  File "C:\django-mongo\django-mongo\venv\lib\site-packages\pymongo\helpers.py", line 175, in _check_command_response
    raise DuplicateKeyError(errmsg, code, response, max_wire_version)
pymongo.errors.DuplicateKeyError: Index build failed: 7cbdc349-f213-4828-a818-dbcef814bbe9: Collection new-django.employee ( 4568febe-b7eb-410e-a944-3c0efbf23982 ) :: caused by :: E11000 duplicate key error collection: new-django.employee index: email_1 dup key: { email: null }, full error: {'ok': 0.0, 'errmsg': 'Index build failed: 7cbdc349-f213-4828-a818-dbcef814bbe9: Collection new-django.employee ( 4568febe-b7eb-410e-a944-3c0efbf23982 ) :: caused by :: E11000 duplicate key error collection: new-django.employee index: email_1 dup key: { email: null }', 'code': 11000, 'codeName': 'DuplicateKey', 'keyPattern': {'email': 1}, 'keyValue': {'email': None}}
INFO:root:Finished request: GET /employees with status 500
INFO:root:Started request: GET /employees
INFO:root:Finished request: GET /employees with status 200
INFO:django.utils.autoreload:C:\django-mongo\django-mongo\EmployeeApp\views.py changed, reloading.
INFO:root:Started request: GET /employees
ERROR:django.request:Internal Server Error: /employees
Traceback (most recent call last):
  File "C:\django-mongo\django-mongo\venv\lib\site-packages\django\core\handlers\exception.py", line 47, in inner
    response = get_response(request)
  File "C:\django-mongo\django-mongo\venv\lib\site-packages\django\core\handlers\base.py", line 181, in _get_response
    response = wrapped_callback(request, *callback_args, **callback_kwargs)
  File "C:\django-mongo\django-mongo\venv\lib\site-packages\django\views\decorators\csrf.py", line 54, in wrapped_view
    return view_func(*args, **kwargs)
  File "C:\django-mongo\django-mongo\venv\lib\site-packages\django\views\generic\base.py", line 70, in view
    return self.dispatch(request, *args, **kwargs)
  File "C:\django-mongo\django-mongo\venv\lib\site-packages\rest_framework\views.py", line 509, in dispatch
    response = self.handle_exception(exc)
  File "C:\django-mongo\django-mongo\venv\lib\site-packages\rest_framework\views.py", line 469, in handle_exception
    self.raise_uncaught_exception(exc)
  File "C:\django-mongo\django-mongo\venv\lib\site-packages\rest_framework\views.py", line 480, in raise_uncaught_exception
    raise exc
  File "C:\django-mongo\django-mongo\venv\lib\site-packages\rest_framework\views.py", line 506, in dispatch
    response = handler(request, *args, **kwargs)
  File "C:\django-mongo\django-mongo\EmployeeApp\views.py", line 37, in get
    queryset = Employee.objects.all()
  File "C:\django-mongo\django-mongo\venv\lib\site-packages\mongoengine\queryset\manager.py", line 38, in __get__
    queryset = queryset_class(owner, owner._get_collection())
  File "C:\django-mongo\django-mongo\venv\lib\site-packages\mongoengine\document.py", line 232, in _get_collection
    cls.ensure_indexes()
  File "C:\django-mongo\django-mongo\venv\lib\site-packages\mongoengine\document.py", line 916, in ensure_indexes
    collection.create_index(fields, background=background, **opts)
  File "C:\django-mongo\django-mongo\venv\lib\site-packages\pymongo\collection.py", line 2055, in create_index
    return self.__create_indexes([index], session, **cmd_options)[0]
  File "C:\django-mongo\django-mongo\venv\lib\site-packages\pymongo\_csot.py", line 105, in csot_wrapper
    return func(self, *args, **kwargs)
  File "C:\django-mongo\django-mongo\venv\lib\site-packages\pymongo\collection.py", line 1938, in __create_indexes
    session=session,
  File "C:\django-mongo\django-mongo\venv\lib\site-packages\pymongo\collection.py", line 306, in _command
    user_fields=user_fields,
  File "C:\django-mongo\django-mongo\venv\lib\site-packages\pymongo\pool.py", line 789, in command
    write_concern=write_concern,
  File "C:\django-mongo\django-mongo\venv\lib\site-packages\pymongo\network.py", line 170, in command
    parse_write_concern_error=parse_write_concern_error,
  File "C:\django-mongo\django-mongo\venv\lib\site-packages\pymongo\helpers.py", line 175, in _check_command_response
    raise DuplicateKeyError(errmsg, code, response, max_wire_version)
pymongo.errors.DuplicateKeyError: Index build failed: d457826d-14fc-4825-a413-143be7101868: Collection new-django.employee ( 4568febe-b7eb-410e-a944-3c0efbf23982 ) :: caused by :: E11000 duplicate key error collection: new-django.employee index: email_1 dup key: { email: null }, full error: {'ok': 0.0, 'errmsg': 'Index build failed: d457826d-14fc-4825-a413-143be7101868: Collection new-django.employee ( 4568febe-b7eb-410e-a944-3c0efbf23982 ) :: caused by :: E11000 duplicate key error collection: new-django.employee index: email_1 dup key: { email: null }', 'code': 11000, 'codeName': 'DuplicateKey', 'keyPattern': {'email': 1}, 'keyValue': {'email': None}}
INFO:root:Finished request: GET /employees with status 500
INFO:django.utils.autoreload:C:\django-mongo\django-mongo\EmployeeApp\views.py changed, reloading.
INFO:root:Started request: GET /employees
ERROR:django.request:Internal Server Error: /employees
Traceback (most recent call last):
  File "C:\django-mongo\django-mongo\venv\lib\site-packages\django\core\handlers\exception.py", line 47, in inner
    response = get_response(request)
  File "C:\django-mongo\django-mongo\venv\lib\site-packages\django\core\handlers\base.py", line 181, in _get_response
    response = wrapped_callback(request, *callback_args, **callback_kwargs)
  File "C:\django-mongo\django-mongo\venv\lib\site-packages\django\views\decorators\csrf.py", line 54, in wrapped_view
    return view_func(*args, **kwargs)
  File "C:\django-mongo\django-mongo\venv\lib\site-packages\django\views\generic\base.py", line 70, in view
    return self.dispatch(request, *args, **kwargs)
  File "C:\django-mongo\django-mongo\venv\lib\site-packages\rest_framework\views.py", line 509, in dispatch
    response = self.handle_exception(exc)
  File "C:\django-mongo\django-mongo\venv\lib\site-packages\rest_framework\views.py", line 469, in handle_exception
    self.raise_uncaught_exception(exc)
  File "C:\django-mongo\django-mongo\venv\lib\site-packages\rest_framework\views.py", line 480, in raise_uncaught_exception
    raise exc
  File "C:\django-mongo\django-mongo\venv\lib\site-packages\rest_framework\views.py", line 506, in dispatch
    response = handler(request, *args, **kwargs)
  File "C:\django-mongo\django-mongo\EmployeeApp\views.py", line 37, in get
    queryset = Employee.objects.all()
  File "C:\django-mongo\django-mongo\venv\lib\site-packages\mongoengine\queryset\manager.py", line 38, in __get__
    queryset = queryset_class(owner, owner._get_collection())
  File "C:\django-mongo\django-mongo\venv\lib\site-packages\mongoengine\document.py", line 232, in _get_collection
    cls.ensure_indexes()
  File "C:\django-mongo\django-mongo\venv\lib\site-packages\mongoengine\document.py", line 916, in ensure_indexes
    collection.create_index(fields, background=background, **opts)
  File "C:\django-mongo\django-mongo\venv\lib\site-packages\pymongo\collection.py", line 2055, in create_index
    return self.__create_indexes([index], session, **cmd_options)[0]
  File "C:\django-mongo\django-mongo\venv\lib\site-packages\pymongo\_csot.py", line 105, in csot_wrapper
    return func(self, *args, **kwargs)
  File "C:\django-mongo\django-mongo\venv\lib\site-packages\pymongo\collection.py", line 1938, in __create_indexes
    session=session,
  File "C:\django-mongo\django-mongo\venv\lib\site-packages\pymongo\collection.py", line 306, in _command
    user_fields=user_fields,
  File "C:\django-mongo\django-mongo\venv\lib\site-packages\pymongo\pool.py", line 789, in command
    write_concern=write_concern,
  File "C:\django-mongo\django-mongo\venv\lib\site-packages\pymongo\network.py", line 170, in command
    parse_write_concern_error=parse_write_concern_error,
  File "C:\django-mongo\django-mongo\venv\lib\site-packages\pymongo\helpers.py", line 175, in _check_command_response
    raise DuplicateKeyError(errmsg, code, response, max_wire_version)
pymongo.errors.DuplicateKeyError: Index build failed: e400031f-763c-4a54-a312-8de4effe9dc4: Collection new-django.employee ( 4568febe-b7eb-410e-a944-3c0efbf23982 ) :: caused by :: E11000 duplicate key error collection: new-django.employee index: email_1 dup key: { email: null }, full error: {'ok': 0.0, 'errmsg': 'Index build failed: e400031f-763c-4a54-a312-8de4effe9dc4: Collection new-django.employee ( 4568febe-b7eb-410e-a944-3c0efbf23982 ) :: caused by :: E11000 duplicate key error collection: new-django.employee index: email_1 dup key: { email: null }', 'code': 11000, 'codeName': 'DuplicateKey', 'keyPattern': {'email': 1}, 'keyValue': {'email': None}}
INFO:root:Finished request: GET /employees with status 500
INFO:django.utils.autoreload:C:\django-mongo\django-mongo\EmployeeApp\views.py changed, reloading.
INFO:django.utils.autoreload:C:\django-mongo\django-mongo\EmployeeApp\views.py changed, reloading.
INFO:django.utils.autoreload:C:\django-mongo\django-mongo\EmployeeApp\views.py changed, reloading.
INFO:root:Started request: GET /employees
ERROR:django.request:Internal Server Error: /employees
Traceback (most recent call last):
  File "C:\django-mongo\django-mongo\venv\lib\site-packages\django\core\handlers\exception.py", line 47, in inner
    response = get_response(request)
  File "C:\django-mongo\django-mongo\venv\lib\site-packages\django\core\handlers\base.py", line 181, in _get_response
    response = wrapped_callback(request, *callback_args, **callback_kwargs)
  File "C:\django-mongo\django-mongo\venv\lib\site-packages\django\views\decorators\csrf.py", line 54, in wrapped_view
    return view_func(*args, **kwargs)
  File "C:\django-mongo\django-mongo\venv\lib\site-packages\django\views\generic\base.py", line 70, in view
    return self.dispatch(request, *args, **kwargs)
  File "C:\django-mongo\django-mongo\venv\lib\site-packages\rest_framework\views.py", line 509, in dispatch
    response = self.handle_exception(exc)
  File "C:\django-mongo\django-mongo\venv\lib\site-packages\rest_framework\views.py", line 469, in handle_exception
    self.raise_uncaught_exception(exc)
  File "C:\django-mongo\django-mongo\venv\lib\site-packages\rest_framework\views.py", line 480, in raise_uncaught_exception
    raise exc
  File "C:\django-mongo\django-mongo\venv\lib\site-packages\rest_framework\views.py", line 506, in dispatch
    response = handler(request, *args, **kwargs)
  File "C:\django-mongo\django-mongo\EmployeeApp\views.py", line 37, in get
    employees = Employee.objects.all()
  File "C:\django-mongo\django-mongo\venv\lib\site-packages\mongoengine\queryset\manager.py", line 38, in __get__
    queryset = queryset_class(owner, owner._get_collection())
  File "C:\django-mongo\django-mongo\venv\lib\site-packages\mongoengine\document.py", line 232, in _get_collection
    cls.ensure_indexes()
  File "C:\django-mongo\django-mongo\venv\lib\site-packages\mongoengine\document.py", line 916, in ensure_indexes
    collection.create_index(fields, background=background, **opts)
  File "C:\django-mongo\django-mongo\venv\lib\site-packages\pymongo\collection.py", line 2055, in create_index
    return self.__create_indexes([index], session, **cmd_options)[0]
  File "C:\django-mongo\django-mongo\venv\lib\site-packages\pymongo\_csot.py", line 105, in csot_wrapper
    return func(self, *args, **kwargs)
  File "C:\django-mongo\django-mongo\venv\lib\site-packages\pymongo\collection.py", line 1938, in __create_indexes
    session=session,
  File "C:\django-mongo\django-mongo\venv\lib\site-packages\pymongo\collection.py", line 306, in _command
    user_fields=user_fields,
  File "C:\django-mongo\django-mongo\venv\lib\site-packages\pymongo\pool.py", line 789, in command
    write_concern=write_concern,
  File "C:\django-mongo\django-mongo\venv\lib\site-packages\pymongo\network.py", line 170, in command
    parse_write_concern_error=parse_write_concern_error,
  File "C:\django-mongo\django-mongo\venv\lib\site-packages\pymongo\helpers.py", line 175, in _check_command_response
    raise DuplicateKeyError(errmsg, code, response, max_wire_version)
pymongo.errors.DuplicateKeyError: Index build failed: 0ec347b4-bafe-49f9-b844-322b49867dc5: Collection new-django.employee ( 4568febe-b7eb-410e-a944-3c0efbf23982 ) :: caused by :: E11000 duplicate key error collection: new-django.employee index: email_1 dup key: { email: null }, full error: {'ok': 0.0, 'errmsg': 'Index build failed: 0ec347b4-bafe-49f9-b844-322b49867dc5: Collection new-django.employee ( 4568febe-b7eb-410e-a944-3c0efbf23982 ) :: caused by :: E11000 duplicate key error collection: new-django.employee index: email_1 dup key: { email: null }', 'code': 11000, 'codeName': 'DuplicateKey', 'keyPattern': {'email': 1}, 'keyValue': {'email': None}}
INFO:root:Finished request: GET /employees with status 500
INFO:django.utils.autoreload:C:\django-mongo\django-mongo\EmployeeApp\views.py changed, reloading.
INFO:django.utils.autoreload:C:\django-mongo\django-mongo\EmployeeApp\views.py changed, reloading.
INFO:django.utils.autoreload:C:\django-mongo\django-mongo\EmployeeApp\views.py changed, reloading.
INFO:django.utils.autoreload:C:\django-mongo\django-mongo\EmployeeApp\views.py changed, reloading.
INFO:django.utils.autoreload:C:\django-mongo\django-mongo\EmployeeApp\views.py changed, reloading.
INFO:django.utils.autoreload:C:\django-mongo\django-mongo\EmployeeApp\views.py changed, reloading.
INFO:django.utils.autoreload:C:\django-mongo\django-mongo\EmployeeApp\views.py changed, reloading.
INFO:django.utils.autoreload:C:\django-mongo\django-mongo\EmployeeApp\views.py changed, reloading.
INFO:root:Started request: GET /employees
ERROR:django.request:Internal Server Error: /employees
Traceback (most recent call last):
  File "C:\django-mongo\django-mongo\venv\lib\site-packages\django\core\handlers\exception.py", line 47, in inner
    response = get_response(request)
  File "C:\django-mongo\django-mongo\venv\lib\site-packages\django\core\handlers\base.py", line 181, in _get_response
    response = wrapped_callback(request, *callback_args, **callback_kwargs)
  File "C:\django-mongo\django-mongo\venv\lib\site-packages\django\views\decorators\csrf.py", line 54, in wrapped_view
    return view_func(*args, **kwargs)
  File "C:\django-mongo\django-mongo\venv\lib\site-packages\django\views\generic\base.py", line 70, in view
    return self.dispatch(request, *args, **kwargs)
  File "C:\django-mongo\django-mongo\venv\lib\site-packages\rest_framework\views.py", line 509, in dispatch
    response = self.handle_exception(exc)
  File "C:\django-mongo\django-mongo\venv\lib\site-packages\rest_framework\views.py", line 469, in handle_exception
    self.raise_uncaught_exception(exc)
  File "C:\django-mongo\django-mongo\venv\lib\site-packages\rest_framework\views.py", line 480, in raise_uncaught_exception
    raise exc
  File "C:\django-mongo\django-mongo\venv\lib\site-packages\rest_framework\views.py", line 506, in dispatch
    response = handler(request, *args, **kwargs)
  File "C:\django-mongo\django-mongo\EmployeeApp\views.py", line 37, in get
    data = Employee.objects.all()
  File "C:\django-mongo\django-mongo\venv\lib\site-packages\mongoengine\queryset\manager.py", line 38, in __get__
    queryset = queryset_class(owner, owner._get_collection())
  File "C:\django-mongo\django-mongo\venv\lib\site-packages\mongoengine\document.py", line 232, in _get_collection
    cls.ensure_indexes()
  File "C:\django-mongo\django-mongo\venv\lib\site-packages\mongoengine\document.py", line 916, in ensure_indexes
    collection.create_index(fields, background=background, **opts)
  File "C:\django-mongo\django-mongo\venv\lib\site-packages\pymongo\collection.py", line 2055, in create_index
    return self.__create_indexes([index], session, **cmd_options)[0]
  File "C:\django-mongo\django-mongo\venv\lib\site-packages\pymongo\_csot.py", line 105, in csot_wrapper
    return func(self, *args, **kwargs)
  File "C:\django-mongo\django-mongo\venv\lib\site-packages\pymongo\collection.py", line 1938, in __create_indexes
    session=session,
  File "C:\django-mongo\django-mongo\venv\lib\site-packages\pymongo\collection.py", line 306, in _command
    user_fields=user_fields,
  File "C:\django-mongo\django-mongo\venv\lib\site-packages\pymongo\pool.py", line 789, in command
    write_concern=write_concern,
  File "C:\django-mongo\django-mongo\venv\lib\site-packages\pymongo\network.py", line 170, in command
    parse_write_concern_error=parse_write_concern_error,
  File "C:\django-mongo\django-mongo\venv\lib\site-packages\pymongo\helpers.py", line 175, in _check_command_response
    raise DuplicateKeyError(errmsg, code, response, max_wire_version)
pymongo.errors.DuplicateKeyError: Index build failed: b273c5ce-f441-4c1c-9edf-baab7d01d152: Collection new-django.employee ( 4568febe-b7eb-410e-a944-3c0efbf23982 ) :: caused by :: E11000 duplicate key error collection: new-django.employee index: email_1 dup key: { email: null }, full error: {'ok': 0.0, 'errmsg': 'Index build failed: b273c5ce-f441-4c1c-9edf-baab7d01d152: Collection new-django.employee ( 4568febe-b7eb-410e-a944-3c0efbf23982 ) :: caused by :: E11000 duplicate key error collection: new-django.employee index: email_1 dup key: { email: null }', 'code': 11000, 'codeName': 'DuplicateKey', 'keyPattern': {'email': 1}, 'keyValue': {'email': None}}
INFO:root:Finished request: GET /employees with status 500
INFO:django.utils.autoreload:C:\django-mongo\django-mongo\EmployeeApp\views.py changed, reloading.
INFO:root:Started request: GET /employees
ERROR:django.request:Internal Server Error: /employees
Traceback (most recent call last):
  File "C:\django-mongo\django-mongo\venv\lib\site-packages\django\core\handlers\exception.py", line 47, in inner
    response = get_response(request)
  File "C:\django-mongo\django-mongo\venv\lib\site-packages\django\core\handlers\base.py", line 181, in _get_response
    response = wrapped_callback(request, *callback_args, **callback_kwargs)
  File "C:\django-mongo\django-mongo\venv\lib\site-packages\django\views\decorators\csrf.py", line 54, in wrapped_view
    return view_func(*args, **kwargs)
  File "C:\django-mongo\django-mongo\venv\lib\site-packages\django\views\generic\base.py", line 70, in view
    return self.dispatch(request, *args, **kwargs)
  File "C:\django-mongo\django-mongo\venv\lib\site-packages\rest_framework\views.py", line 509, in dispatch
    response = self.handle_exception(exc)
  File "C:\django-mongo\django-mongo\venv\lib\site-packages\rest_framework\views.py", line 469, in handle_exception
    self.raise_uncaught_exception(exc)
  File "C:\django-mongo\django-mongo\venv\lib\site-packages\rest_framework\views.py", line 480, in raise_uncaught_exception
    raise exc
  File "C:\django-mongo\django-mongo\venv\lib\site-packages\rest_framework\views.py", line 506, in dispatch
    response = handler(request, *args, **kwargs)
  File "C:\django-mongo\django-mongo\EmployeeApp\views.py", line 37, in get
    data = Employee.objects.all()
  File "C:\django-mongo\django-mongo\venv\lib\site-packages\mongoengine\queryset\manager.py", line 38, in __get__
    queryset = queryset_class(owner, owner._get_collection())
  File "C:\django-mongo\django-mongo\venv\lib\site-packages\mongoengine\document.py", line 232, in _get_collection
    cls.ensure_indexes()
  File "C:\django-mongo\django-mongo\venv\lib\site-packages\mongoengine\document.py", line 916, in ensure_indexes
    collection.create_index(fields, background=background, **opts)
  File "C:\django-mongo\django-mongo\venv\lib\site-packages\pymongo\collection.py", line 2055, in create_index
    return self.__create_indexes([index], session, **cmd_options)[0]
  File "C:\django-mongo\django-mongo\venv\lib\site-packages\pymongo\_csot.py", line 105, in csot_wrapper
    return func(self, *args, **kwargs)
  File "C:\django-mongo\django-mongo\venv\lib\site-packages\pymongo\collection.py", line 1938, in __create_indexes
    session=session,
  File "C:\django-mongo\django-mongo\venv\lib\site-packages\pymongo\collection.py", line 306, in _command
    user_fields=user_fields,
  File "C:\django-mongo\django-mongo\venv\lib\site-packages\pymongo\pool.py", line 789, in command
    write_concern=write_concern,
  File "C:\django-mongo\django-mongo\venv\lib\site-packages\pymongo\network.py", line 170, in command
    parse_write_concern_error=parse_write_concern_error,
  File "C:\django-mongo\django-mongo\venv\lib\site-packages\pymongo\helpers.py", line 175, in _check_command_response
    raise DuplicateKeyError(errmsg, code, response, max_wire_version)
pymongo.errors.DuplicateKeyError: Index build failed: 7ac0ffe6-3053-4f1a-aaff-d5c877e6abd9: Collection new-django.employee ( 4568febe-b7eb-410e-a944-3c0efbf23982 ) :: caused by :: E11000 duplicate key error collection: new-django.employee index: email_1 dup key: { email: null }, full error: {'ok': 0.0, 'errmsg': 'Index build failed: 7ac0ffe6-3053-4f1a-aaff-d5c877e6abd9: Collection new-django.employee ( 4568febe-b7eb-410e-a944-3c0efbf23982 ) :: caused by :: E11000 duplicate key error collection: new-django.employee index: email_1 dup key: { email: null }', 'code': 11000, 'codeName': 'DuplicateKey', 'keyPattern': {'email': 1}, 'keyValue': {'email': None}}
INFO:root:Finished request: GET /employees with status 500
INFO:django.utils.autoreload:C:\django-mongo\django-mongo\EmployeeApp\views.py changed, reloading.
INFO:django.utils.autoreload:C:\django-mongo\django-mongo\EmployeeApp\views.py changed, reloading.
INFO:root:Started request: GET /employees
ERROR:django.request:Internal Server Error: /employees
Traceback (most recent call last):
  File "C:\django-mongo\django-mongo\venv\lib\site-packages\django\core\handlers\exception.py", line 47, in inner
    response = get_response(request)
  File "C:\django-mongo\django-mongo\venv\lib\site-packages\django\core\handlers\base.py", line 181, in _get_response
    response = wrapped_callback(request, *callback_args, **callback_kwargs)
  File "C:\django-mongo\django-mongo\venv\lib\site-packages\django\views\decorators\csrf.py", line 54, in wrapped_view
    return view_func(*args, **kwargs)
  File "C:\django-mongo\django-mongo\venv\lib\site-packages\django\views\generic\base.py", line 70, in view
    return self.dispatch(request, *args, **kwargs)
  File "C:\django-mongo\django-mongo\venv\lib\site-packages\rest_framework\views.py", line 509, in dispatch
    response = self.handle_exception(exc)
  File "C:\django-mongo\django-mongo\venv\lib\site-packages\rest_framework\views.py", line 469, in handle_exception
    self.raise_uncaught_exception(exc)
  File "C:\django-mongo\django-mongo\venv\lib\site-packages\rest_framework\views.py", line 480, in raise_uncaught_exception
    raise exc
  File "C:\django-mongo\django-mongo\venv\lib\site-packages\rest_framework\views.py", line 506, in dispatch
    response = handler(request, *args, **kwargs)
  File "C:\django-mongo\django-mongo\EmployeeApp\views.py", line 38, in get
    data = Employee.objects.all()
  File "C:\django-mongo\django-mongo\venv\lib\site-packages\mongoengine\queryset\manager.py", line 38, in __get__
    queryset = queryset_class(owner, owner._get_collection())
  File "C:\django-mongo\django-mongo\venv\lib\site-packages\mongoengine\document.py", line 232, in _get_collection
    cls.ensure_indexes()
  File "C:\django-mongo\django-mongo\venv\lib\site-packages\mongoengine\document.py", line 916, in ensure_indexes
    collection.create_index(fields, background=background, **opts)
  File "C:\django-mongo\django-mongo\venv\lib\site-packages\pymongo\collection.py", line 2055, in create_index
    return self.__create_indexes([index], session, **cmd_options)[0]
  File "C:\django-mongo\django-mongo\venv\lib\site-packages\pymongo\_csot.py", line 105, in csot_wrapper
    return func(self, *args, **kwargs)
  File "C:\django-mongo\django-mongo\venv\lib\site-packages\pymongo\collection.py", line 1938, in __create_indexes
    session=session,
  File "C:\django-mongo\django-mongo\venv\lib\site-packages\pymongo\collection.py", line 306, in _command
    user_fields=user_fields,
  File "C:\django-mongo\django-mongo\venv\lib\site-packages\pymongo\pool.py", line 789, in command
    write_concern=write_concern,
  File "C:\django-mongo\django-mongo\venv\lib\site-packages\pymongo\network.py", line 170, in command
    parse_write_concern_error=parse_write_concern_error,
  File "C:\django-mongo\django-mongo\venv\lib\site-packages\pymongo\helpers.py", line 175, in _check_command_response
    raise DuplicateKeyError(errmsg, code, response, max_wire_version)
pymongo.errors.DuplicateKeyError: Index build failed: e2bdee46-5578-4f46-896d-9b72dfd23858: Collection new-django.employee ( 4568febe-b7eb-410e-a944-3c0efbf23982 ) :: caused by :: E11000 duplicate key error collection: new-django.employee index: email_1 dup key: { email: null }, full error: {'ok': 0.0, 'errmsg': 'Index build failed: e2bdee46-5578-4f46-896d-9b72dfd23858: Collection new-django.employee ( 4568febe-b7eb-410e-a944-3c0efbf23982 ) :: caused by :: E11000 duplicate key error collection: new-django.employee index: email_1 dup key: { email: null }', 'code': 11000, 'codeName': 'DuplicateKey', 'keyPattern': {'email': 1}, 'keyValue': {'email': None}}
INFO:root:Finished request: GET /employees with status 500
INFO:django.utils.autoreload:C:\django-mongo\django-mongo\EmployeeApp\views.py changed, reloading.
INFO:root:Started request: GET /employees
ERROR:django.request:Internal Server Error: /employees
Traceback (most recent call last):
  File "C:\django-mongo\django-mongo\venv\lib\site-packages\django\core\handlers\exception.py", line 47, in inner
    response = get_response(request)
  File "C:\django-mongo\django-mongo\venv\lib\site-packages\django\core\handlers\base.py", line 181, in _get_response
    response = wrapped_callback(request, *callback_args, **callback_kwargs)
  File "C:\django-mongo\django-mongo\venv\lib\site-packages\django\views\decorators\csrf.py", line 54, in wrapped_view
    return view_func(*args, **kwargs)
  File "C:\django-mongo\django-mongo\venv\lib\site-packages\django\views\generic\base.py", line 70, in view
    return self.dispatch(request, *args, **kwargs)
  File "C:\django-mongo\django-mongo\venv\lib\site-packages\rest_framework\views.py", line 509, in dispatch
    response = self.handle_exception(exc)
  File "C:\django-mongo\django-mongo\venv\lib\site-packages\rest_framework\views.py", line 469, in handle_exception
    self.raise_uncaught_exception(exc)
  File "C:\django-mongo\django-mongo\venv\lib\site-packages\rest_framework\views.py", line 480, in raise_uncaught_exception
    raise exc
  File "C:\django-mongo\django-mongo\venv\lib\site-packages\rest_framework\views.py", line 506, in dispatch
    response = handler(request, *args, **kwargs)
  File "C:\django-mongo\django-mongo\EmployeeApp\views.py", line 39, in get
    data = Employee.objects.all()
  File "C:\django-mongo\django-mongo\venv\lib\site-packages\mongoengine\queryset\manager.py", line 38, in __get__
    queryset = queryset_class(owner, owner._get_collection())
  File "C:\django-mongo\django-mongo\venv\lib\site-packages\mongoengine\document.py", line 232, in _get_collection
    cls.ensure_indexes()
  File "C:\django-mongo\django-mongo\venv\lib\site-packages\mongoengine\document.py", line 916, in ensure_indexes
    collection.create_index(fields, background=background, **opts)
  File "C:\django-mongo\django-mongo\venv\lib\site-packages\pymongo\collection.py", line 2055, in create_index
    return self.__create_indexes([index], session, **cmd_options)[0]
  File "C:\django-mongo\django-mongo\venv\lib\site-packages\pymongo\_csot.py", line 105, in csot_wrapper
    return func(self, *args, **kwargs)
  File "C:\django-mongo\django-mongo\venv\lib\site-packages\pymongo\collection.py", line 1938, in __create_indexes
    session=session,
  File "C:\django-mongo\django-mongo\venv\lib\site-packages\pymongo\collection.py", line 306, in _command
    user_fields=user_fields,
  File "C:\django-mongo\django-mongo\venv\lib\site-packages\pymongo\pool.py", line 789, in command
    write_concern=write_concern,
  File "C:\django-mongo\django-mongo\venv\lib\site-packages\pymongo\network.py", line 170, in command
    parse_write_concern_error=parse_write_concern_error,
  File "C:\django-mongo\django-mongo\venv\lib\site-packages\pymongo\helpers.py", line 175, in _check_command_response
    raise DuplicateKeyError(errmsg, code, response, max_wire_version)
pymongo.errors.DuplicateKeyError: Index build failed: 64c46bc6-9c98-4e31-ae34-b1629a7ab011: Collection new-django.employee ( 4568febe-b7eb-410e-a944-3c0efbf23982 ) :: caused by :: E11000 duplicate key error collection: new-django.employee index: email_1 dup key: { email: null }, full error: {'ok': 0.0, 'errmsg': 'Index build failed: 64c46bc6-9c98-4e31-ae34-b1629a7ab011: Collection new-django.employee ( 4568febe-b7eb-410e-a944-3c0efbf23982 ) :: caused by :: E11000 duplicate key error collection: new-django.employee index: email_1 dup key: { email: null }', 'code': 11000, 'codeName': 'DuplicateKey', 'keyPattern': {'email': 1}, 'keyValue': {'email': None}}
INFO:root:Finished request: GET /employees with status 500
INFO:django.utils.autoreload:C:\django-mongo\django-mongo\EmployeeApp\views.py changed, reloading.
INFO:root:Started request: GET /employees
ERROR:django.request:Internal Server Error: /employees
Traceback (most recent call last):
  File "C:\django-mongo\django-mongo\venv\lib\site-packages\django\core\handlers\exception.py", line 47, in inner
    response = get_response(request)
  File "C:\django-mongo\django-mongo\venv\lib\site-packages\django\core\handlers\base.py", line 181, in _get_response
    response = wrapped_callback(request, *callback_args, **callback_kwargs)
  File "C:\django-mongo\django-mongo\venv\lib\site-packages\django\views\decorators\csrf.py", line 54, in wrapped_view
    return view_func(*args, **kwargs)
  File "C:\django-mongo\django-mongo\venv\lib\site-packages\django\views\generic\base.py", line 70, in view
    return self.dispatch(request, *args, **kwargs)
  File "C:\django-mongo\django-mongo\venv\lib\site-packages\rest_framework\views.py", line 509, in dispatch
    response = self.handle_exception(exc)
  File "C:\django-mongo\django-mongo\venv\lib\site-packages\rest_framework\views.py", line 469, in handle_exception
    self.raise_uncaught_exception(exc)
  File "C:\django-mongo\django-mongo\venv\lib\site-packages\rest_framework\views.py", line 480, in raise_uncaught_exception
    raise exc
  File "C:\django-mongo\django-mongo\venv\lib\site-packages\rest_framework\views.py", line 506, in dispatch
    response = handler(request, *args, **kwargs)
  File "C:\django-mongo\django-mongo\EmployeeApp\views.py", line 38, in get
    data = Employee.objects.all()
  File "C:\django-mongo\django-mongo\venv\lib\site-packages\mongoengine\queryset\manager.py", line 38, in __get__
    queryset = queryset_class(owner, owner._get_collection())
  File "C:\django-mongo\django-mongo\venv\lib\site-packages\mongoengine\document.py", line 232, in _get_collection
    cls.ensure_indexes()
  File "C:\django-mongo\django-mongo\venv\lib\site-packages\mongoengine\document.py", line 916, in ensure_indexes
    collection.create_index(fields, background=background, **opts)
  File "C:\django-mongo\django-mongo\venv\lib\site-packages\pymongo\collection.py", line 2055, in create_index
    return self.__create_indexes([index], session, **cmd_options)[0]
  File "C:\django-mongo\django-mongo\venv\lib\site-packages\pymongo\_csot.py", line 105, in csot_wrapper
    return func(self, *args, **kwargs)
  File "C:\django-mongo\django-mongo\venv\lib\site-packages\pymongo\collection.py", line 1938, in __create_indexes
    session=session,
  File "C:\django-mongo\django-mongo\venv\lib\site-packages\pymongo\collection.py", line 306, in _command
    user_fields=user_fields,
  File "C:\django-mongo\django-mongo\venv\lib\site-packages\pymongo\pool.py", line 789, in command
    write_concern=write_concern,
  File "C:\django-mongo\django-mongo\venv\lib\site-packages\pymongo\network.py", line 170, in command
    parse_write_concern_error=parse_write_concern_error,
  File "C:\django-mongo\django-mongo\venv\lib\site-packages\pymongo\helpers.py", line 175, in _check_command_response
    raise DuplicateKeyError(errmsg, code, response, max_wire_version)
pymongo.errors.DuplicateKeyError: Index build failed: 0293222d-4138-4b35-95ae-f1e7f9852563: Collection new-django.employee ( 4568febe-b7eb-410e-a944-3c0efbf23982 ) :: caused by :: E11000 duplicate key error collection: new-django.employee index: email_1 dup key: { email: null }, full error: {'ok': 0.0, 'errmsg': 'Index build failed: 0293222d-4138-4b35-95ae-f1e7f9852563: Collection new-django.employee ( 4568febe-b7eb-410e-a944-3c0efbf23982 ) :: caused by :: E11000 duplicate key error collection: new-django.employee index: email_1 dup key: { email: null }', 'code': 11000, 'codeName': 'DuplicateKey', 'keyPattern': {'email': 1}, 'keyValue': {'email': None}}
INFO:root:Finished request: GET /employees with status 500
INFO:django.utils.autoreload:C:\django-mongo\django-mongo\EmployeeApp\views.py changed, reloading.
INFO:root:Started request: GET /employees
ERROR:django.request:Internal Server Error: /employees
Traceback (most recent call last):
  File "C:\django-mongo\django-mongo\venv\lib\site-packages\django\core\handlers\exception.py", line 47, in inner
    response = get_response(request)
  File "C:\django-mongo\django-mongo\venv\lib\site-packages\django\core\handlers\base.py", line 181, in _get_response
    response = wrapped_callback(request, *callback_args, **callback_kwargs)
  File "C:\django-mongo\django-mongo\venv\lib\site-packages\django\views\decorators\csrf.py", line 54, in wrapped_view
    return view_func(*args, **kwargs)
  File "C:\django-mongo\django-mongo\venv\lib\site-packages\django\views\generic\base.py", line 70, in view
    return self.dispatch(request, *args, **kwargs)
  File "C:\django-mongo\django-mongo\venv\lib\site-packages\rest_framework\views.py", line 509, in dispatch
    response = self.handle_exception(exc)
  File "C:\django-mongo\django-mongo\venv\lib\site-packages\rest_framework\views.py", line 469, in handle_exception
    self.raise_uncaught_exception(exc)
  File "C:\django-mongo\django-mongo\venv\lib\site-packages\rest_framework\views.py", line 480, in raise_uncaught_exception
    raise exc
  File "C:\django-mongo\django-mongo\venv\lib\site-packages\rest_framework\views.py", line 506, in dispatch
    response = handler(request, *args, **kwargs)
  File "C:\django-mongo\django-mongo\EmployeeApp\views.py", line 56, in get
    "payload": {"data": employees.data, "totalCount": total_count},
UnboundLocalError: local variable 'employees' referenced before assignment
INFO:root:Finished request: GET /employees with status 500
INFO:django.utils.autoreload:C:\django-mongo\django-mongo\EmployeeApp\views.py changed, reloading.
INFO:django.utils.autoreload:C:\django-mongo\django-mongo\EmployeeApp\views.py changed, reloading.
INFO:django.utils.autoreload:C:\django-mongo\django-mongo\EmployeeApp\views.py changed, reloading.
INFO:django.utils.autoreload:C:\django-mongo\django-mongo\EmployeeApp\views.py changed, reloading.
INFO:django.utils.autoreload:C:\django-mongo\django-mongo\EmployeeApp\views.py changed, reloading.
INFO:django.utils.autoreload:C:\django-mongo\django-mongo\EmployeeApp\views.py changed, reloading.
INFO:root:Started request: GET /employees
ERROR:django.request:Internal Server Error: /employees
Traceback (most recent call last):
  File "C:\django-mongo\django-mongo\venv\lib\site-packages\django\core\handlers\exception.py", line 47, in inner
    response = get_response(request)
  File "C:\django-mongo\django-mongo\venv\lib\site-packages\django\core\handlers\base.py", line 181, in _get_response
    response = wrapped_callback(request, *callback_args, **callback_kwargs)
  File "C:\django-mongo\django-mongo\venv\lib\site-packages\django\views\decorators\csrf.py", line 54, in wrapped_view
    return view_func(*args, **kwargs)
  File "C:\django-mongo\django-mongo\venv\lib\site-packages\django\views\generic\base.py", line 70, in view
    return self.dispatch(request, *args, **kwargs)
  File "C:\django-mongo\django-mongo\venv\lib\site-packages\rest_framework\views.py", line 509, in dispatch
    response = self.handle_exception(exc)
  File "C:\django-mongo\django-mongo\venv\lib\site-packages\rest_framework\views.py", line 469, in handle_exception
    self.raise_uncaught_exception(exc)
  File "C:\django-mongo\django-mongo\venv\lib\site-packages\rest_framework\views.py", line 480, in raise_uncaught_exception
    raise exc
  File "C:\django-mongo\django-mongo\venv\lib\site-packages\rest_framework\views.py", line 506, in dispatch
    response = handler(request, *args, **kwargs)
  File "C:\django-mongo\django-mongo\EmployeeApp\views.py", line 50, in get
    total_count = self.total_count
AttributeError: 'EmployeeAll' object has no attribute 'total_count'
INFO:root:Finished request: GET /employees with status 500
INFO:django.utils.autoreload:C:\django-mongo\django-mongo\EmployeeApp\views.py changed, reloading.
INFO:root:Started request: GET /employees
INFO:root:Finished request: GET /employees with status 200
INFO:django.utils.autoreload:C:\django-mongo\django-mongo\EmployeeApp\views.py changed, reloading.
INFO:django.utils.autoreload:C:\django-mongo\django-mongo\EmployeeApp\views.py changed, reloading.
INFO:root:Started request: GET /employees
INFO:root:Finished request: GET /employees with status 200
INFO:root:Started request: GET /employees
INFO:root:Finished request: GET /employees with status 200
INFO:root:Started request: GET /employees
INFO:root:Finished request: GET /employees with status 200
INFO:root:Started request: GET /employees
INFO:root:Finished request: GET /employees with status 200
INFO:root:Started request: GET /employees
INFO:root:Finished request: GET /employees with status 200
INFO:root:Started request: GET /employees
ERROR:django.request:Internal Server Error: /employees
Traceback (most recent call last):
  File "C:\django-mongo\django-mongo\venv\lib\site-packages\django\core\handlers\exception.py", line 47, in inner
    response = get_response(request)
  File "C:\django-mongo\django-mongo\venv\lib\site-packages\django\core\handlers\base.py", line 181, in _get_response
    response = wrapped_callback(request, *callback_args, **callback_kwargs)
  File "C:\django-mongo\django-mongo\venv\lib\site-packages\django\views\decorators\csrf.py", line 54, in wrapped_view
    return view_func(*args, **kwargs)
  File "C:\django-mongo\django-mongo\venv\lib\site-packages\django\views\generic\base.py", line 70, in view
    return self.dispatch(request, *args, **kwargs)
  File "C:\django-mongo\django-mongo\venv\lib\site-packages\rest_framework\views.py", line 509, in dispatch
    response = self.handle_exception(exc)
  File "C:\django-mongo\django-mongo\venv\lib\site-packages\rest_framework\views.py", line 469, in handle_exception
    self.raise_uncaught_exception(exc)
  File "C:\django-mongo\django-mongo\venv\lib\site-packages\rest_framework\views.py", line 480, in raise_uncaught_exception
    raise exc
  File "C:\django-mongo\django-mongo\venv\lib\site-packages\rest_framework\views.py", line 506, in dispatch
    response = handler(request, *args, **kwargs)
  File "C:\django-mongo\django-mongo\EmployeeApp\views.py", line 61, in get
    "payload": {"data": employees.data, "totalCount": self.total_count},
UnboundLocalError: local variable 'employees' referenced before assignment
INFO:root:Finished request: GET /employees with status 500
INFO:django.utils.autoreload:C:\django-mongo\django-mongo\EmployeeApp\views.py changed, reloading.
INFO:root:Started request: GET /employees
ERROR:django.request:Internal Server Error: /employees
Traceback (most recent call last):
  File "C:\django-mongo\django-mongo\venv\lib\site-packages\django\core\handlers\exception.py", line 47, in inner
    response = get_response(request)
  File "C:\django-mongo\django-mongo\venv\lib\site-packages\django\core\handlers\base.py", line 181, in _get_response
    response = wrapped_callback(request, *callback_args, **callback_kwargs)
  File "C:\django-mongo\django-mongo\venv\lib\site-packages\django\views\decorators\csrf.py", line 54, in wrapped_view
    return view_func(*args, **kwargs)
  File "C:\django-mongo\django-mongo\venv\lib\site-packages\django\views\generic\base.py", line 70, in view
    return self.dispatch(request, *args, **kwargs)
  File "C:\django-mongo\django-mongo\venv\lib\site-packages\rest_framework\views.py", line 509, in dispatch
    response = self.handle_exception(exc)
  File "C:\django-mongo\django-mongo\venv\lib\site-packages\rest_framework\views.py", line 469, in handle_exception
    self.raise_uncaught_exception(exc)
  File "C:\django-mongo\django-mongo\venv\lib\site-packages\rest_framework\views.py", line 480, in raise_uncaught_exception
    raise exc
  File "C:\django-mongo\django-mongo\venv\lib\site-packages\rest_framework\views.py", line 506, in dispatch
    response = handler(request, *args, **kwargs)
  File "C:\django-mongo\django-mongo\EmployeeApp\views.py", line 62, in get
    "payload": {"data": employees.data, "totalCount": self.total_count},
UnboundLocalError: local variable 'employees' referenced before assignment
INFO:root:Finished request: GET /employees with status 500
INFO:django.utils.autoreload:C:\django-mongo\django-mongo\EmployeeApp\views.py changed, reloading.
INFO:root:Started request: GET /employees
INFO:root:Finished request: GET /employees with status 200
INFO:django.utils.autoreload:C:\django-mongo\django-mongo\EmployeeApp\views.py changed, reloading.
INFO:root:Started request: GET /employees
INFO:root:Finished request: GET /employees with status 200
INFO:django.utils.autoreload:C:\django-mongo\django-mongo\EmployeeApp\views.py changed, reloading.
INFO:root:Started request: GET /employees
ERROR:django.request:Internal Server Error: /employees
Traceback (most recent call last):
  File "C:\django-mongo\django-mongo\venv\lib\site-packages\django\core\handlers\exception.py", line 47, in inner
    response = get_response(request)
  File "C:\django-mongo\django-mongo\venv\lib\site-packages\django\core\handlers\base.py", line 181, in _get_response
    response = wrapped_callback(request, *callback_args, **callback_kwargs)
  File "C:\django-mongo\django-mongo\venv\lib\site-packages\django\views\decorators\csrf.py", line 54, in wrapped_view
    return view_func(*args, **kwargs)
  File "C:\django-mongo\django-mongo\venv\lib\site-packages\django\views\generic\base.py", line 70, in view
    return self.dispatch(request, *args, **kwargs)
  File "C:\django-mongo\django-mongo\venv\lib\site-packages\rest_framework\views.py", line 509, in dispatch
    response = self.handle_exception(exc)
  File "C:\django-mongo\django-mongo\venv\lib\site-packages\rest_framework\views.py", line 469, in handle_exception
    self.raise_uncaught_exception(exc)
  File "C:\django-mongo\django-mongo\venv\lib\site-packages\rest_framework\views.py", line 480, in raise_uncaught_exception
    raise exc
  File "C:\django-mongo\django-mongo\venv\lib\site-packages\rest_framework\views.py", line 506, in dispatch
    response = handler(request, *args, **kwargs)
  File "C:\django-mongo\django-mongo\EmployeeApp\views.py", line 40, in get
    print(request.GET.get() is None)
TypeError: get() missing 1 required positional argument: 'key'
INFO:root:Finished request: GET /employees with status 500
INFO:django.utils.autoreload:C:\django-mongo\django-mongo\EmployeeApp\views.py changed, reloading.
INFO:root:Started request: GET /employees
INFO:root:Finished request: GET /employees with status 200
INFO:django.utils.autoreload:C:\django-mongo\django-mongo\EmployeeApp\views.py changed, reloading.
INFO:django.utils.autoreload:C:\django-mongo\django-mongo\EmployeeApp\views.py changed, reloading.
INFO:root:Started request: GET /employees
ERROR:django.request:Internal Server Error: /employees
Traceback (most recent call last):
  File "C:\django-mongo\django-mongo\venv\lib\site-packages\django\core\handlers\exception.py", line 47, in inner
    response = get_response(request)
  File "C:\django-mongo\django-mongo\venv\lib\site-packages\django\core\handlers\base.py", line 181, in _get_response
    response = wrapped_callback(request, *callback_args, **callback_kwargs)
  File "C:\django-mongo\django-mongo\venv\lib\site-packages\django\views\decorators\csrf.py", line 54, in wrapped_view
    return view_func(*args, **kwargs)
  File "C:\django-mongo\django-mongo\venv\lib\site-packages\django\views\generic\base.py", line 70, in view
    return self.dispatch(request, *args, **kwargs)
  File "C:\django-mongo\django-mongo\venv\lib\site-packages\rest_framework\views.py", line 509, in dispatch
    response = self.handle_exception(exc)
  File "C:\django-mongo\django-mongo\venv\lib\site-packages\rest_framework\views.py", line 469, in handle_exception
    self.raise_uncaught_exception(exc)
  File "C:\django-mongo\django-mongo\venv\lib\site-packages\rest_framework\views.py", line 480, in raise_uncaught_exception
    raise exc
  File "C:\django-mongo\django-mongo\venv\lib\site-packages\rest_framework\views.py", line 506, in dispatch
    response = handler(request, *args, **kwargs)
  File "C:\django-mongo\django-mongo\EmployeeApp\views.py", line 62, in get
    "payload": {"data": employees.data, "totalCount": self.total_count},
UnboundLocalError: local variable 'employees' referenced before assignment
INFO:root:Finished request: GET /employees with status 500
INFO:django.utils.autoreload:C:\django-mongo\django-mongo\EmployeeApp\views.py changed, reloading.
INFO:root:Started request: GET /employees
INFO:root:Finished request: GET /employees with status 200
INFO:django.utils.autoreload:C:\django-mongo\django-mongo\EmployeeApp\views.py changed, reloading.
INFO:root:Started request: GET /employees
ERROR:django.request:Internal Server Error: /employees
Traceback (most recent call last):
  File "C:\django-mongo\django-mongo\venv\lib\site-packages\django\core\handlers\exception.py", line 47, in inner
    response = get_response(request)
  File "C:\django-mongo\django-mongo\venv\lib\site-packages\django\core\handlers\base.py", line 181, in _get_response
    response = wrapped_callback(request, *callback_args, **callback_kwargs)
  File "C:\django-mongo\django-mongo\venv\lib\site-packages\django\views\decorators\csrf.py", line 54, in wrapped_view
    return view_func(*args, **kwargs)
  File "C:\django-mongo\django-mongo\venv\lib\site-packages\django\views\generic\base.py", line 70, in view
    return self.dispatch(request, *args, **kwargs)
  File "C:\django-mongo\django-mongo\venv\lib\site-packages\rest_framework\views.py", line 509, in dispatch
    response = self.handle_exception(exc)
  File "C:\django-mongo\django-mongo\venv\lib\site-packages\rest_framework\views.py", line 469, in handle_exception
    self.raise_uncaught_exception(exc)
  File "C:\django-mongo\django-mongo\venv\lib\site-packages\rest_framework\views.py", line 480, in raise_uncaught_exception
    raise exc
  File "C:\django-mongo\django-mongo\venv\lib\site-packages\rest_framework\views.py", line 506, in dispatch
    response = handler(request, *args, **kwargs)
  File "C:\django-mongo\django-mongo\EmployeeApp\views.py", line 40, in get
    print(request.GET.QueryDict)
AttributeError: 'QueryDict' object has no attribute 'QueryDict'
INFO:root:Finished request: GET /employees with status 500
INFO:django.utils.autoreload:C:\django-mongo\django-mongo\EmployeeApp\views.py changed, reloading.
INFO:root:Started request: GET /employees
INFO:root:Finished request: GET /employees with status 200
INFO:django.utils.autoreload:C:\django-mongo\django-mongo\EmployeeApp\views.py changed, reloading.
INFO:django.utils.autoreload:C:\django-mongo\django-mongo\EmployeeApp\views.py changed, reloading.
INFO:root:Started request: GET /employees
INFO:root:Finished request: GET /employees with status 200
